File: Specimen_RawData_3_SN19Z010748.csv
Time,Extension,Load
(s),(mm),(N)
"0.00000","0.00000","2.47667"
"0.01800","-0.00003","2.46998"
"0.03600","-0.00055","2.34955"
"0.05400","-0.00269","2.24921"
"0.07200","-0.00575","2.20769"
"0.09000","-0.00891","2.17444"
"0.10800","-0.01285","2.15139"
"0.12600","-0.01781","2.16038"
"0.14400","-0.02328","2.18696"
"0.16200","-0.02866","2.20196"
"0.18000","-0.03379","2.19557"
"0.19800","-0.03871","2.18284"
"0.21600","-0.04345","2.16824"
"0.23400","-0.04804","2.15395"
"0.25200","-0.05260","2.14342"
"0.27000","-0.05717","2.13789"
"0.28800","-0.06175","2.13674"
"0.30600","-0.06626","2.13485"
"0.32400","-0.07078","2.13364"
"0.34200","-0.07538","2.13342"
"0.36000","-0.08002","2.13504"
"0.37800","-0.08461","2.14014"
"0.39600","-0.08917","2.14138"
"0.41400","-0.09374","2.13836"
"0.43200","-0.09832","2.13156"
"0.45000","-0.10284","2.12543"
"0.46800","-0.10733","2.12413"
"0.48600","-0.11188","2.12698"
"0.50400","-0.11651","2.12987"
"0.52200","-0.12112","2.12723"
"0.54000","-0.12570","2.13136"
"0.55800","-0.13030","2.14016"
"0.57600","-0.13496","2.14853"
"0.59400","-0.13959","2.15466"
"0.61200","-0.14411","2.15556"
"0.63000","-0.14862","2.15910"
"0.64800","-0.15319","2.16276"
"0.66600","-0.15776","2.16377"
"0.68400","-0.16228","2.16126"
"0.70200","-0.16685","2.15386"
"0.72000","-0.17148","2.15201"
"0.73800","-0.17612","2.15534"
"0.75600","-0.18070","2.16794"
"0.77400","-0.18523","2.18470"
"0.79200","-0.18977","2.19627"
"0.81000","-0.19431","2.20502"
"0.82800","-0.19882","2.20521"
"0.84600","-0.20331","2.19884"
"0.86400","-0.20788","2.19444"
"0.88200","-0.21252","2.19624"
"0.90000","-0.21718","2.20369"
"0.91800","-0.22177","2.20629"
"0.93600","-0.22635","2.20470"
"0.95400","-0.23096","2.19893"
"0.97200","-0.23555","2.20527"
"0.99000","-0.24011","2.21712"
"1.00800","-0.24465","2.22568"
"1.02600","-0.24920","2.23623"
"1.04400","-0.25380","2.24122"
"1.06200","-0.25839","2.24770"
"1.08000","-0.26297","2.25462"
"1.09800","-0.26757","2.26002"
"1.11600","-0.27216","2.25911"
"1.13400","-0.27670","2.25354"
"1.15200","-0.28121","2.25155"
"1.17000","-0.28573","2.25222"
"1.18800","-0.29028","2.25743"
"1.20600","-0.29481","2.26696"
"1.22400","-0.29936","2.27591"
"1.24200","-0.30396","2.28510"
"1.26000","-0.30857","2.29013"
"1.27800","-0.31316","2.29066"
"1.29600","-0.31773","2.29114"
"1.31400","-0.32230","2.29335"
"1.33200","-0.32689","2.29317"
"1.35000","-0.33144","2.28811"
"1.36800","-0.33596","2.28589"
"1.38600","-0.34054","2.28605"
"1.40400","-0.34518","2.28944"
"1.42200","-0.34984","2.29928"
"1.44000","-0.35444","2.30761"
"1.45800","-0.35902","2.31474"
"1.47600","-0.36360","2.31770"
"1.49400","-0.36816","2.32272"
"1.51200","-0.37265","2.32857"
"1.53000","-0.37716","2.33823"
"1.54800","-0.38172","2.34538"
"1.56600","-0.38631","2.34261"
"1.58400","-0.39088","2.34018"
"1.60200","-0.39545","2.34178"
"1.62000","-0.40006","2.34941"
"1.63800","-0.40467","2.36146"
"1.65600","-0.40920","2.37156"
"1.67400","-0.41370","2.37674"
"1.69200","-0.41826","2.37643"
"1.71000","-0.42287","2.37675"
"1.72800","-0.42744","2.37752"
"1.74600","-0.43199","2.38047"
"1.76400","-0.43661","2.38471"
"1.78200","-0.44129","2.38521"
"1.80000","-0.44591","2.38115"
"1.81800","-0.45047","2.37454"
"1.83600","-0.45502","2.37308"
"1.85400","-0.45957","2.38281"
"1.87200","-0.46412","2.39700"
"1.89000","-0.46861","2.41025"
"1.90800","-0.47314","2.42011"
"1.92600","-0.47775","2.42442"
"1.94400","-0.48241","2.42540"
"1.96200","-0.48700","2.42582"
"1.98000","-0.49156","2.42779"
"1.99800","-0.49614","2.43203"
"2.01600","-0.50071","2.43343"
"2.03400","-0.50521","2.43554"
"2.05200","-0.50968","2.44003"
"2.07000","-0.51422","2.44751"
"2.08800","-0.51884","2.45857"
"2.10600","-0.52346","2.46817"
"2.12400","-0.52805","2.46919"
"2.14200","-0.53267","2.46923"
"2.16000","-0.53732","2.46807"
"2.17800","-0.54194","2.46871"
"2.19600","-0.54647","2.47114"
"2.21400","-0.55099","2.47096"
"2.23200","-0.55554","2.46936"
"2.25000","-0.56010","2.46636"
"2.26800","-0.56463","2.46201"
"2.28600","-0.56921","2.46315"
"2.30400","-0.57386","2.47020"
"2.32200","-0.57851","2.48174"
"2.34000","-0.58307","2.49621"
"2.35800","-0.58759","2.51352"
"2.37600","-0.59213","2.51958"
"2.39400","-0.59667","2.52193"
"2.41200","-0.60117","2.52804"
"2.43000","-0.60564","2.53195"
"2.44800","-0.61020","2.53203"
"2.46600","-0.61486","2.52344"
"2.48400","-0.61952","2.52383"
"2.50200","-0.62412","2.53173"
"2.52000","-0.62871","2.54319"
"2.53800","-0.63330","2.55898"
"2.55600","-0.63785","2.56935"
"2.57400","-0.64237","2.57655"
"2.59200","-0.64690","2.58726"
"2.61000","-0.65147","2.59062"
"2.62800","-0.65608","2.58649"
"2.64600","-0.66067","2.57665"
"2.66400","-0.66528","2.57002"
"2.68200","-0.66990","2.56846"
"2.70000","-0.67450","2.56956"
"2.71800","-0.67903","2.57382"
"2.73600","-0.68353","2.58339"
"2.75400","-0.68805","2.60068"
"2.77200","-0.69259","2.61969"
"2.79000","-0.69711","2.63900"
"2.80800","-0.70166","2.64995"
"2.82600","-0.70627","2.65274"
"2.84400","-0.71090","2.65792"
"2.86200","-0.71551","2.65944"
"2.88000","-0.72008","2.66569"
"2.89800","-0.72466","2.66412"
"2.91600","-0.72923","2.65566"
"2.93400","-0.73376","2.65238"
"2.95200","-0.73828","2.65607"
"2.97000","-0.74287","2.66748"
"2.98800","-0.74753","2.67858"
"3.00600","-0.75218","2.68148"
"3.02400","-0.75677","2.68216"
"3.04200","-0.76135","2.68002"
"3.06000","-0.76595","2.67332"
"3.07800","-0.77051","2.66043"
"3.09600","-0.77499","2.64939"
"3.11400","-0.77950","2.64778"
"3.13200","-0.78406","2.64880"
"3.15000","-0.78865","2.65355"
"3.16800","-0.79322","2.66284"
"3.18600","-0.79778","2.67508"
"3.20400","-0.80237","2.68613"
"3.22200","-0.80697","2.69841"
"3.24000","-0.81151","2.70996"
"3.25800","-0.81602","2.71808"
"3.27600","-0.82060","2.73057"
"3.29400","-0.82522","2.74125"
"3.31200","-0.82978","2.74776"
"3.33000","-0.83432","2.74353"
"3.34800","-0.83894","2.73358"
"3.36600","-0.84361","2.73126"
"3.38400","-0.84824","2.73534"
"3.40200","-0.85280","2.74798"
"3.42000","-0.85736","2.75709"
"3.43800","-0.86191","2.76450"
"3.45600","-0.86645","2.77353"
"3.47400","-0.87095","2.77736"
"3.49200","-0.87550","2.77865"
"3.51000","-0.88011","2.77601"
"3.52800","-0.88474","2.76944"
"3.54600","-0.88931","2.76419"
"3.56400","-0.89387","2.76147"
"3.58200","-0.89845","2.76213"
"3.60000","-0.90303","2.76671"
"3.61800","-0.90754","2.78151"
"3.63600","-0.91202","2.79793"
"3.65400","-0.91658","2.81240"
"3.67200","-0.92121","2.82492"
"3.69000","-0.92580","2.83143"
"3.70800","-0.93037","2.83760"
"3.72600","-0.93499","2.84380"
"3.74400","-0.93966","2.84975"
"3.76200","-0.94427","2.85664"
"3.78000","-0.94879","2.86042"
"3.79800","-0.95332","2.86217"
"3.81600","-0.95788","2.85944"
"3.83400","-0.96242","2.86520"
"3.85200","-0.96694","2.87325"
"3.87000","-0.97152","2.87915"
"3.88800","-0.97616","2.88390"
"3.90600","-0.98081","2.88781"
"3.92400","-0.98538","2.89308"
"3.94200","-0.98992","2.89542"
"3.96000","-0.99448","2.89195"
"3.97800","-0.99902","2.88015"
"3.99600","-1.00351","2.86665"
"4.01400","-1.00801","2.85733"
"4.03200","-1.01259","2.85418"
"4.05000","-1.01724","2.86616"
"4.06800","-1.02186","2.88472"
"4.08600","-1.02643","2.90022"
"4.10400","-1.03102","2.91751"
"4.12200","-1.03562","2.93444"
"4.14000","-1.04017","2.94961"
"4.15800","-1.04470","2.95973"
"4.17600","-1.04924","2.96748"
"4.19400","-1.05384","2.97385"
"4.21200","-1.05844","2.98001"
"4.23000","-1.06302","2.99065"
"4.24800","-1.06762","2.99375"
"4.26600","-1.07222","2.99360"
"4.28400","-1.07682","2.99342"
"4.30200","-1.08135","2.99323"
"4.32000","-1.08586","2.99590"
"4.33800","-1.09040","3.00131"
"4.35600","-1.09496","3.00918"
"4.37400","-1.09949","3.00958"
"4.39200","-1.10405","3.00822"
"4.41000","-1.10864","3.00546"
"4.42800","-1.11325","2.99951"
"4.44600","-1.11784","2.98871"
"4.46400","-1.12242","2.97587"
"4.48200","-1.12698","2.97725"
"4.50000","-1.13154","2.99161"
"4.51800","-1.13604","3.00903"
"4.53600","-1.14055","3.02914"
"4.55400","-1.14514","3.04681"
"4.57200","-1.14980","3.06374"
"4.59000","-1.15446","3.07698"
"4.60800","-1.15907","3.08547"
"4.62600","-1.16367","3.09270"
"4.64400","-1.16829","3.09786"
"4.66200","-1.17284","3.10469"
"4.68000","-1.17732","3.10552"
"4.69800","-1.18184","3.10343"
"4.71600","-1.18639","3.10273"
"4.73400","-1.19097","3.10531"
"4.75200","-1.19552","3.10893"
"4.77000","-1.20010","3.10999"
"4.78800","-1.20472","3.11336"
"4.80600","-1.20934","3.11098"
"4.82400","-1.21387","3.10444"
"4.84200","-1.21837","3.09388"
"4.86000","-1.22293","3.08674"
"4.87800","-1.22753","3.08825"
"4.89600","-1.23210","3.08875"
"4.91400","-1.23666","3.09495"
"4.93200","-1.24129","3.10959"
"4.95000","-1.24596","3.13339"
"4.96800","-1.25057","3.15430"
"4.98600","-1.25511","3.17275"
"5.00400","-1.25966","3.19033"
"5.02200","-1.26423","3.20399"
"5.04000","-1.26877","3.21801"
"5.05800","-1.27327","3.22793"
"5.07600","-1.27781","3.23431"
"5.09400","-1.28243","3.23598"
"5.11200","-1.28707","3.23065"
"5.13000","-1.29165","3.22124"
"5.14800","-1.29622","3.21887"
"5.16600","-1.30081","3.22636"
"5.18400","-1.30538","3.23882"
"5.20200","-1.30987","3.24893"
"5.22000","-1.31436","3.25866"
"5.23800","-1.31891","3.25861"
"5.25600","-1.32352","3.25567"
"5.27400","-1.32812","3.25187"
"5.29200","-1.33273","3.24226"
"5.31000","-1.33738","3.22693"
"5.32800","-1.34204","3.21411"
"5.34600","-1.34663","3.21599"
"5.36400","-1.35111","3.23072"
"5.38200","-1.35563","3.25274"
"5.40000","-1.36020","3.27977"
"5.41800","-1.36476","3.30543"
"5.43600","-1.36930","3.33035"
"5.45400","-1.37391","3.34726"
"5.47200","-1.37856","3.35877"
"5.49000","-1.38319","3.36733"
"5.50800","-1.38772","3.36726"
"5.52600","-1.39223","3.36377"
"5.54400","-1.39676","3.35813"
"5.56200","-1.40129","3.35421"
"5.58000","-1.40579","3.35284"
"5.59800","-1.41033","3.35796"
"5.61600","-1.41494","3.36926"
"5.63400","-1.41960","3.38306"
"5.65200","-1.42423","3.39565"
"5.67000","-1.42881","3.40334"
"5.68800","-1.43341","3.40648"
"5.70600","-1.43799","3.40552"
"5.72400","-1.44253","3.38730"
"5.74200","-1.44704","3.36565"
"5.76000","-1.45158","3.34726"
"5.77800","-1.45617","3.34464"
"5.79600","-1.46078","3.36157"
"5.81400","-1.46538","3.38777"
"5.83200","-1.46997","3.41790"
"5.85000","-1.47456","3.44060"
"5.86800","-1.47913","3.46646"
"5.88600","-1.48365","3.48951"
"5.90400","-1.48817","3.51204"
"5.92200","-1.49272","3.53678"
"5.94000","-1.49728","3.55934"
"5.95800","-1.50182","3.57266"
"5.97600","-1.50639","3.57301"
"5.99400","-1.51099","3.56547"
"6.01200","-1.51561","3.55675"
"6.03000","-1.52020","3.55489"
"6.04800","-1.52478","3.55994"
"6.06600","-1.52935","3.55597"
"6.08400","-1.53392","3.55723"
"6.10200","-1.53846","3.56361"
"6.12000","-1.54300","3.56748"
"6.13800","-1.54760","3.56937"
"6.15600","-1.55226","3.56369"
"6.17400","-1.55688","3.55113"
"6.19200","-1.56145","3.53101"
"6.21000","-1.56603","3.51543"
"6.22800","-1.57062","3.51254"
"6.24600","-1.57516","3.52702"
"6.26400","-1.57965","3.55482"
"6.28200","-1.58418","3.57948"
"6.30000","-1.58874","3.60934"
"6.31800","-1.59332","3.63704"
"6.33600","-1.59788","3.66155"
"6.35400","-1.60246","3.68150"
"6.37200","-1.60707","3.69702"
"6.39000","-1.61166","3.71084"
"6.40800","-1.61618","3.71223"
"6.42600","-1.62070","3.70448"
"6.44400","-1.62528","3.69993"
"6.46200","-1.62988","3.69804"
"6.48000","-1.63444","3.69911"
"6.49800","-1.63901","3.69932"
"6.51600","-1.64366","3.71375"
"6.53400","-1.64832","3.73183"
"6.55200","-1.65292","3.73897"
"6.57000","-1.65746","3.74075"
"6.58800","-1.66202","3.73209"
"6.60600","-1.66659","3.71853"
"6.62400","-1.67112","3.70145"
"6.64200","-1.67561","3.68542"
"6.66000","-1.68014","3.67923"
"6.67800","-1.68476","3.69019"
"6.69600","-1.68938","3.71790"
"6.71400","-1.69395","3.74632"
"6.73200","-1.69851","3.77501"
"6.75000","-1.70310","3.80528"
"6.76800","-1.70766","3.83151"
"6.78600","-1.71215","3.85465"
"6.80400","-1.71667","3.87521"
"6.82200","-1.72127","3.89635"
"6.84000","-1.72591","3.90615"
"6.85800","-1.73050","3.90416"
"6.87600","-1.73507","3.89198"
"6.89400","-1.73969","3.87651"
"6.91200","-1.74433","3.86955"
"6.93000","-1.74891","3.86346"
"6.94800","-1.75342","3.86191"
"6.96600","-1.75797","3.86748"
"6.98400","-1.76254","3.87095"
"7.00200","-1.76709","3.87560"
"7.02000","-1.77161","3.86824"
"7.03800","-1.77621","3.85354"
"7.05600","-1.78086","3.84479"
"7.07400","-1.78547","3.84224"
"7.09200","-1.78999","3.84591"
"7.11000","-1.79451","3.85900"
"7.12800","-1.79905","3.88726"
"7.14600","-1.80360","3.91557"
"7.16400","-1.80810","3.94156"
"7.18200","-1.81263","3.96845"
"7.20000","-1.81723","3.99364"
"7.21800","-1.82190","4.01780"
"7.23600","-1.82652","4.03710"
"7.25400","-1.83111","4.04819"
"7.27200","-1.83571","4.04768"
"7.29000","-1.84031","4.03509"
"7.30800","-1.84485","4.02510"
"7.32600","-1.84938","4.01539"
"7.34400","-1.85394","4.01384"
"7.36200","-1.85853","4.01809"
"7.38000","-1.86313","4.02377"
"7.39800","-1.86772","4.04099"
"7.41600","-1.87231","4.05694"
"7.43400","-1.87690","4.07195"
"7.45200","-1.88145","4.06832"
"7.47000","-1.88595","4.04994"
"7.48800","-1.89045","4.03229"
"7.50600","-1.89500","4.02253"
"7.52400","-1.89957","4.02264"
"7.54200","-1.90412","4.03205"
"7.56000","-1.90870","4.05368"
"7.57800","-1.91332","4.08340"
"7.59600","-1.91794","4.11380"
"7.61400","-1.92252","4.14786"
"7.63200","-1.92709","4.18124"
"7.65000","-1.93167","4.21409"
"7.66800","-1.93622","4.24098"
"7.68600","-1.94076","4.26397"
"7.70400","-1.94530","4.28189"
"7.72200","-1.94991","4.28524"
"7.74000","-1.95459","4.26979"
"7.75800","-1.95924","4.24409"
"7.77600","-1.96382","4.23129"
"7.79400","-1.96839","4.23034"
"7.81200","-1.97297","4.23586"
"7.83000","-1.97748","4.25126"
"7.84800","-1.98194","4.26813"
"7.86600","-1.98647","4.28556"
"7.88400","-1.99107","4.29610"
"7.90200","-1.99566","4.29951"
"7.92000","-2.00023","4.29168"
"7.93800","-2.00483","4.26948"
"7.95600","-2.00945","4.25656"
"7.97400","-2.01403","4.25062"
"7.99200","-2.01853","4.26476"
"8.01000","-2.02303","4.29251"
"8.02800","-2.02760","4.32327"
"8.04600","-2.03220","4.35666"
"8.06400","-2.03676","4.38707"
"8.08200","-2.04133","4.41939"
"8.10000","-2.04599","4.44007"
"8.11800","-2.05066","4.46234"
"8.13600","-2.05524","4.47960"
"8.15400","-2.05979","4.48230"
"8.17200","-2.06434","4.48200"
"8.19000","-2.06890","4.47398"
"8.20800","-2.07341","4.46653"
"8.22600","-2.07791","4.46516"
"8.24400","-2.08249","4.46890"
"8.26200","-2.08714","4.48345"
"8.28000","-2.09177","4.49967"
"8.29800","-2.09633","4.51555"
"8.31600","-2.10089","4.52656"
"8.33400","-2.10547","4.53262"
"8.35200","-2.11001","4.52706"
"8.37000","-2.11447","4.50965"
"8.38800","-2.11899","4.48912"
"8.40600","-2.12359","4.47334"
"8.42400","-2.12823","4.47516"
"8.44200","-2.13283","4.49098"
"8.46000","-2.13744","4.51845"
"8.47800","-2.14208","4.54787"
"8.49600","-2.14673","4.57714"
"8.51400","-2.15128","4.61381"
"8.53200","-2.15575","4.64191"
"8.55000","-2.16026","4.67023"
"8.56800","-2.16483","4.69829"
"8.58600","-2.16938","4.71359"
"8.60400","-2.17392","4.71535"
"8.62200","-2.17855","4.70035"
"8.64000","-2.18323","4.68809"
"8.65800","-2.18784","4.68635"
"8.67600","-2.19237","4.69438"
"8.69400","-2.19689","4.71036"
"8.71200","-2.20141","4.73003"
"8.73000","-2.20593","4.74590"
"8.74800","-2.21043","4.75322"
"8.76600","-2.21496","4.75798"
"8.78400","-2.21959","4.75132"
"8.80200","-2.22428","4.72518"
"8.82000","-2.22893","4.70057"
"8.83800","-2.23352","4.68608"
"8.85600","-2.23811","4.68745"
"8.87400","-2.24266","4.70644"
"8.89200","-2.24717","4.73744"
"8.91000","-2.25169","4.77875"
"8.92800","-2.25624","4.81384"
"8.94600","-2.26085","4.85082"
"8.96400","-2.26547","4.87645"
"8.98200","-2.27007","4.89973"
"9.00000","-2.27467","4.92671"
"9.01800","-2.27925","4.95424"
"9.03600","-2.28381","4.97046"
"9.05400","-2.28832","4.96814"
"9.07200","-2.29283","4.96203"
"9.09000","-2.29738","4.95413"
"9.10800","-2.30192","4.98091"
"9.12600","-2.30646","5.01564"
"9.14400","-2.31105","5.03098"
"9.16200","-2.31568","5.04884"
"9.18000","-2.32030","5.06340"
"9.19800","-2.32486","5.06692"
"9.21600","-2.32942","5.05658"
"9.23400","-2.33398","5.02957"
"9.25200","-2.33853","5.00916"
"9.27000","-2.34305","4.99583"
"9.28800","-2.34759","4.99776"
"9.30600","-2.35221","5.01773"
"9.32400","-2.35689","5.05349"
"9.34200","-2.36153","5.09474"
"9.36000","-2.36613","5.12635"
"9.37800","-2.37072","5.15779"
"9.39600","-2.37529","5.18468"
"9.41400","-2.37979","5.21041"
"9.43200","-2.38426","5.23566"
"9.45000","-2.38880","5.25614"
"9.46800","-2.39340","5.27750"
"9.48600","-2.39799","5.28685"
"9.50400","-2.40255","5.27984"
"9.52200","-2.40714","5.26768"
"9.54000","-2.41176","5.26602"
"9.55800","-2.41634","5.26518"
"9.57600","-2.42085","5.26455"
"9.59400","-2.42538","5.28371"
"9.61200","-2.42996","5.30371"
"9.63000","-2.43455","5.31880"
"9.64800","-2.43908","5.32088"
"9.66600","-2.44366","5.30446"
"9.68400","-2.44833","5.28142"
"9.70200","-2.45300","5.25388"
"9.72000","-2.45759","5.24310"
"9.73800","-2.46213","5.25538"
"9.75600","-2.46667","5.28535"
"9.77400","-2.47121","5.32365"
"9.79200","-2.47573","5.36047"
"9.81000","-2.48026","5.40216"
"9.82800","-2.48485","5.43318"
"9.84600","-2.48952","5.46149"
"9.86400","-2.49415","5.49622"
"9.88200","-2.49870","5.52767"
"9.90000","-2.50324","5.55597"
"9.91800","-2.50779","5.57386"
"9.93600","-2.51230","5.58168"
"9.95400","-2.51677","5.57414"
"9.97200","-2.52131","5.56135"
"9.99000","-2.52592","5.55647"
"10.00800","-2.53056","5.55704"
"10.02600","-2.53517","5.56910"
"10.04400","-2.53978","5.58883"
"10.06200","-2.54442","5.60515"
"10.08000","-2.54906","5.61770"
"10.09800","-2.55359","5.61914"
"10.11600","-2.55808","5.60321"
"10.13400","-2.56262","5.58019"
"10.15200","-2.56721","5.56514"
"10.17000","-2.57176","5.56487"
"10.18800","-2.57632","5.58339"
"10.20600","-2.58094","5.61712"
"10.22400","-2.58561","5.65391"
"10.24200","-2.59020","5.69162"
"10.26000","-2.59472","5.72281"
"10.27800","-2.59923","5.75398"
"10.29600","-2.60375","5.78698"
"10.31400","-2.60826","5.80864"
"10.33200","-2.61275","5.82641"
"10.35000","-2.61729","5.83242"
"10.36800","-2.62194","5.82751"
"10.38600","-2.62663","5.82168"
"10.40400","-2.63125","5.82441"
"10.42200","-2.63584","5.83122"
"10.44000","-2.64043","5.83620"
"10.45800","-2.64501","5.85016"
"10.47600","-2.64952","5.86263"
"10.49400","-2.65404","5.87481"
"10.51200","-2.65859","5.89018"
"10.53000","-2.66320","5.89875"
"10.54800","-2.66780","5.89112"
"10.56600","-2.67240","5.86952"
"10.58400","-2.67700","5.85280"
"10.60200","-2.68160","5.85755"
"10.62000","-2.68614","5.87409"
"10.63800","-2.69064","5.90091"
"10.65600","-2.69515","5.92837"
"10.67400","-2.69970","5.96253"
"10.69200","-2.70427","6.00341"
"10.71000","-2.70883","6.03664"
"10.72800","-2.71342","6.07149"
"10.74600","-2.71803","6.09497"
"10.76400","-2.72262","6.12327"
"10.78200","-2.72718","6.14690"
"10.80000","-2.73175","6.15378"
"10.81800","-2.73633","6.15371"
"10.83600","-2.74088","6.14772"
"10.85400","-2.74540","6.15536"
"10.87200","-2.74996","6.16338"
"10.89000","-2.75459","6.16796"
"10.90800","-2.75925","6.17666"
"10.92600","-2.76387","6.19300"
"10.94400","-2.76845","6.21485"
"10.96200","-2.77303","6.22689"
"10.98000","-2.77761","6.22381"
"10.99800","-2.78212","6.20180"
"11.01600","-2.78660","6.17917"
"11.03400","-2.79115","6.17199"
"11.05200","-2.79574","6.18208"
"11.07000","-2.80032","6.21265"
"11.08800","-2.80489","6.24978"
"11.10600","-2.80950","6.29139"
"11.12400","-2.81412","6.33044"
"11.14200","-2.81869","6.36866"
"11.16000","-2.82319","6.40627"
"11.17800","-2.82772","6.43658"
"11.19600","-2.83231","6.47440"
"11.21400","-2.83690","6.50502"
"11.23200","-2.84145","6.52180"
"11.25000","-2.84603","6.51908"
"11.26800","-2.85070","6.50224"
"11.28600","-2.85535","6.50025"
"11.30400","-2.85993","6.49777"
"11.32200","-2.86447","6.49934"
"11.34000","-2.86902","6.51409"
"11.35800","-2.87357","6.53258"
"11.37600","-2.87809","6.55040"
"11.39400","-2.88260","6.56137"
"11.41200","-2.88719","6.56463"
"11.43000","-2.89183","6.55790"
"11.44800","-2.89644","6.54553"
"11.46600","-2.90098","6.53488"
"11.48400","-2.90554","6.53839"
"11.50200","-2.91012","6.56622"
"11.52000","-2.91466","6.60299"
"11.53800","-2.91913","6.64232"
"11.55600","-2.92367","6.68473"
"11.57400","-2.92828","6.72446"
"11.59200","-2.93291","6.76417"
"11.61000","-2.93751","6.79351"
"11.62800","-2.94212","6.82609"
"11.64600","-2.94676","6.85816"
"11.66400","-2.95139","6.87176"
"11.68200","-2.95593","6.86903"
"11.70000","-2.96044","6.85569"
"11.71800","-2.96498","6.85277"
"11.73600","-2.96956","6.86022"
"11.75400","-2.97408","6.87363"
"11.77200","-2.97864","6.89307"
"11.79000","-2.98327","6.91098"
"11.80800","-2.98792","6.93328"
"11.82600","-2.99249","6.94640"
"11.84400","-2.99700","6.94450"
"11.86200","-3.00151","6.92612"
"11.88000","-3.00603","6.90509"
"11.89800","-3.01055","6.89914"
"11.91600","-3.01506","6.90286"
"11.93400","-3.01963","6.92465"
"11.95200","-3.02429","6.95981"
"11.97000","-3.02897","6.99959"
"11.98800","-3.03359","7.04190"
"12.00600","-3.03817","7.08576"
"12.02400","-3.04276","7.13043"
"12.04200","-3.04732","7.16772"
"12.06000","-3.05183","7.20040"
"12.07800","-3.05636","7.22422"
"12.09600","-3.06093","7.23960"
"12.11400","-3.06554","7.25239"
"12.13200","-3.07014","7.25474"
"12.15000","-3.07473","7.25691"
"12.16800","-3.07933","7.26061"
"12.18600","-3.08393","7.27047"
"12.20400","-3.08847","7.28964"
"12.22200","-3.09299","7.30937"
"12.24000","-3.09750","7.33614"
"12.25800","-3.10206","7.35217"
"12.27600","-3.10660","7.36637"
"12.29400","-3.11114","7.36385"
"12.31200","-3.11574","7.35342"
"12.33000","-3.12036","7.34324"
"12.34800","-3.12495","7.33572"
"12.36600","-3.12952","7.34462"
"12.38400","-3.13408","7.36383"
"12.40200","-3.13864","7.40267"
"12.42000","-3.14319","7.44838"
"12.43800","-3.14771","7.48869"
"12.45600","-3.15228","7.53328"
"12.47400","-3.15693","7.57344"
"12.49200","-3.16161","7.61120"
"12.51000","-3.16622","7.64915"
"12.52800","-3.17080","7.67906"
"12.54600","-3.17539","7.70311"
"12.56400","-3.17995","7.70833"
"12.58200","-3.18445","7.70612"
"12.60000","-3.18895","7.70370"
"12.61800","-3.19351","7.70629"
"12.63600","-3.19810","7.71456"
"12.65400","-3.20267","7.72783"
"12.67200","-3.20723","7.75121"
"12.69000","-3.21182","7.77075"
"12.70800","-3.21642","7.79292"
"12.72600","-3.22097","7.79428"
"12.74400","-3.22547","7.78594"
"12.76200","-3.23001","7.78459"
"12.78000","-3.23462","7.77787"
"12.79800","-3.23921","7.77853"
"12.81600","-3.24377","7.79313"
"12.83400","-3.24838","7.82784"
"12.85200","-3.25305","7.87872"
"12.87000","-3.25769","7.92933"
"12.88800","-3.26224","7.97420"
"12.90600","-3.26679","8.00885"
"12.92400","-3.27135","8.04329"
"12.94200","-3.27590","8.06858"
"12.96000","-3.28040","8.08872"
"12.97800","-3.28490","8.10402"
"12.99600","-3.28950","8.11242"
"13.01400","-3.29417","8.12323"
"13.03200","-3.29878","8.13149"
"13.05000","-3.30333","8.14623"
"13.06800","-3.30790","8.16766"
"13.08600","-3.31248","8.18863"
"13.10400","-3.31700","8.21061"
"13.12200","-3.32147","8.22848"
"13.14000","-3.32601","8.24507"
"13.15800","-3.33063","8.25672"
"13.17600","-3.33525","8.25692"
"13.19400","-3.33985","8.25420"
"13.21200","-3.34446","8.24435"
"13.23000","-3.34910","8.25126"
"13.24800","-3.35373","8.26351"
"13.26600","-3.35827","8.28561"
"13.28400","-3.36278","8.31980"
"13.30200","-3.36734","8.36130"
"13.32000","-3.37190","8.41090"
"13.33800","-3.37644","8.45575"
"13.35600","-3.38100","8.49723"
"13.37400","-3.38563","8.54175"
"13.39200","-3.39027","8.58719"
"13.41000","-3.39484","8.62964"
"13.42800","-3.39936","8.64710"
"13.44600","-3.40388","8.64733"
"13.46400","-3.40843","8.64445"
"13.48200","-3.41295","8.64676"
"13.50000","-3.41745","8.66326"
"13.51800","-3.42200","8.68107"
"13.53600","-3.42664","8.70505"
"13.55400","-3.43130","8.72518"
"13.57200","-3.43590","8.73959"
"13.59000","-3.44049","8.74814"
"13.60800","-3.44508","8.74764"
"13.62600","-3.44965","8.74849"
"13.64400","-3.45417","8.74704"
"13.66200","-3.45871","8.75433"
"13.68000","-3.46328","8.76751"
"13.69800","-3.46789","8.79539"
"13.71600","-3.47249","8.83672"
"13.73400","-3.47708","8.87516"
"13.75200","-3.48168","8.92513"
"13.77000","-3.48627","8.97109"
"13.78800","-3.49081","9.01857"
"13.80600","-3.49532","9.05863"
"13.82400","-3.49985","9.08720"
"13.84200","-3.50440","9.12473"
"13.86000","-3.50892","9.15185"
"13.87800","-3.51344","9.16056"
"13.89600","-3.51803","9.16248"
"13.91400","-3.52264","9.16274"
"13.93200","-3.52723","9.17174"
"13.95000","-3.53180","9.18302"
"13.96800","-3.53640","9.20035"
"13.98600","-3.54098","9.22545"
"14.00400","-3.54553","9.25406"
"14.02200","-3.55005","9.28236"
"14.04000","-3.55461","9.29445"
"14.05800","-3.55924","9.30289"
"14.07600","-3.56391","9.29265"
"14.09400","-3.56852","9.28826"
"14.11200","-3.57310","9.29831"
"14.13000","-3.57771","9.31699"
"14.14800","-3.58229","9.35180"
"14.16600","-3.58678","9.38838"
"14.18400","-3.59129","9.43223"
"14.20200","-3.59584","9.47508"
"14.22000","-3.60043","9.52023"
"14.23800","-3.60499","9.56081"
"14.25600","-3.60954","9.59943"
"14.27400","-3.61414","9.63767"
"14.29200","-3.61875","9.65658"
"14.31000","-3.62330","9.67466"
"14.32800","-3.62782","9.69899"
"14.34600","-3.63236","9.71764"
"14.36400","-3.63696","9.74591"
"14.38200","-3.64154","9.77351"
"14.40000","-3.64609","9.80210"
"14.41800","-3.65071","9.82842"
"14.43600","-3.65539","9.85445"
"14.45400","-3.66003","9.88371"
"14.47200","-3.66459","9.90164"
"14.49000","-3.66914","9.92125"
"14.50800","-3.67370","9.93068"
"14.52600","-3.67826","9.93940"
"14.54400","-3.68275","9.94795"
"14.56200","-3.68726","9.96208"
"14.58000","-3.69185","9.99445"
"14.59800","-3.69650","10.03235"
"14.61600","-3.70109","10.07415"
"14.63400","-3.70566","10.10863"
"14.65200","-3.71024","10.14517"
"14.67000","-3.71482","10.18253"
"14.68800","-3.71933","10.21722"
"14.70600","-3.72380","10.25780"
"14.72400","-3.72835","10.28755"
"14.74200","-3.73297","10.30856"
"14.76000","-3.73758","10.33335"
"14.77800","-3.74217","10.36272"
"14.79600","-3.74678","10.39839"
"14.81400","-3.75144","10.43173"
"14.83200","-3.75606","10.46875"
"14.85000","-3.76058","10.49723"
"14.86800","-3.76510","10.52311"
"14.88600","-3.76966","10.55628"
"14.90400","-3.77422","10.57334"
"14.92200","-3.77874","10.58874"
"14.94000","-3.78332","10.60114"
"14.95800","-3.78797","10.60870"
"14.97600","-3.79261","10.61683"
"14.99400","-3.79717","10.62519"
"15.01200","-3.80169","10.65242"
"15.03000","-3.80624","10.68870"
"15.04800","-3.81079","10.73959"
"15.06600","-3.81529","10.78839"
"15.08400","-3.81978","10.83063"
"15.10200","-3.82433","10.87174"
"15.12000","-3.82898","10.90452"
"15.13800","-3.83365","10.94528"
"15.15600","-3.83824","10.97628"
"15.17400","-3.84283","11.00782"
"15.19200","-3.84743","11.03751"
"15.21000","-3.85199","11.06654"
"15.22800","-3.85651","11.11375"
"15.24600","-3.86105","11.15811"
"15.26400","-3.86562","11.19049"
"15.28200","-3.87022","11.21574"
"15.30000","-3.87481","11.24012"
"15.31800","-3.87939","11.28029"
"15.33600","-3.88399","11.30529"
"15.35400","-3.88859","11.32211"
"15.37200","-3.89314","11.33264"
"15.39000","-3.89766","11.34848"
"15.40800","-3.90219","11.37880"
"15.42600","-3.90674","11.39531"
"15.44400","-3.91126","11.41879"
"15.46200","-3.91581","11.44804"
"15.48000","-3.92042","11.49711"
"15.49800","-3.92506","11.55171"
"15.51600","-3.92966","11.60236"
"15.53400","-3.93423","11.65882"
"15.55200","-3.93881","11.70486"
"15.57000","-3.94339","11.74948"
"15.58800","-3.94792","11.78835"
"15.60600","-3.95244","11.82357"
"15.62400","-3.95700","11.84657"
"15.64200","-3.96163","11.86616"
"15.66000","-3.96628","11.89530"
"15.67800","-3.97088","11.91973"
"15.69600","-3.97547","11.95635"
"15.71400","-3.98007","11.99351"
"15.73200","-3.98463","12.02680"
"15.75000","-3.98911","12.07324"
"15.76800","-3.99362","12.11277"
"15.78600","-3.99818","12.13852"
"15.80400","-4.00277","12.15595"
"15.82200","-4.00734","12.16601"
"15.84000","-4.01192","12.18591"
"15.85800","-4.01652","12.21025"
"15.87600","-4.02114","12.23269"
"15.89400","-4.02568","12.26332"
"15.91200","-4.03019","12.31071"
"15.93000","-4.03473","12.35856"
"15.94800","-4.03931","12.39952"
"15.96600","-4.04386","12.45593"
"15.98400","-4.04840","12.50759"
"16.00200","-4.05304","12.57135"
"16.02000","-4.05773","12.62020"
"16.03800","-4.06235","12.66037"
"16.05600","-4.06690","12.69320"
"16.07400","-4.07145","12.70790"
"16.09200","-4.07603","12.73223"
"16.11000","-4.08058","12.75967"
"16.12800","-4.08507","12.80027"
"16.14600","-4.08959","12.85087"
"16.16400","-4.09419","12.90415"
"16.18200","-4.09883","12.95897"
"16.20000","-4.10340","13.00195"
"16.21800","-4.10795","13.04706"
"16.23600","-4.11253","13.07843"
"16.25400","-4.11712","13.09970"
"16.27200","-4.12163","13.12279"
"16.29000","-4.12613","13.13161"
"16.30800","-4.13070","13.15723"
"16.32600","-4.13532","13.19345"
"16.34400","-4.13992","13.24060"
"16.36200","-4.14451","13.30363"
"16.38000","-4.14913","13.36043"
"16.39800","-4.15380","13.42364"
"16.41600","-4.15841","13.47444"
"16.43400","-4.16293","13.51953"
"16.45200","-4.16744","13.56708"
"16.47000","-4.17198","13.61769"
"16.48800","-4.17652","13.65853"
"16.50600","-4.18104","13.67718"
"16.52400","-4.18563","13.70446"
"16.54200","-4.19028","13.74022"
"16.56000","-4.19493","13.79724"
"16.57800","-4.19948","13.84901"
"16.59600","-4.20402","13.88410"
"16.61400","-4.20856","13.92423"
"16.63200","-4.21310","13.96310"
"16.65000","-4.21760","14.00121"
"16.66800","-4.22210","14.04139"
"16.68600","-4.22669","14.07172"
"16.70400","-4.23135","14.10263"
"16.72200","-4.23600","14.12729"
"16.74000","-4.24058","14.15956"
"16.75800","-4.24516","14.19907"
"16.77600","-4.24976","14.25508"
"16.79400","-4.25433","14.31555"
"16.81200","-4.25886","14.37179"
"16.83000","-4.26340","14.43715"
"16.84800","-4.26796","14.49533"
"16.86600","-4.27255","14.56162"
"16.88400","-4.27714","14.62601"
"16.90200","-4.28175","14.67235"
"16.92000","-4.28637","14.70946"
"16.93800","-4.29096","14.72744"
"16.95600","-4.29549","14.76048"
"16.97400","-4.30000","14.80749"
"16.99200","-4.30453","14.85906"
"17.01000","-4.30907","14.91506"
"17.02800","-4.31358","14.96158"
"17.04600","-4.31813","15.01229"
"17.06400","-4.32274","15.05494"
"17.08200","-4.32737","15.10092"
"17.10000","-4.33197","15.14118"
"17.11800","-4.33655","15.17696"
"17.13600","-4.34114","15.22446"
"17.15400","-4.34572","15.26448"
"17.17200","-4.35025","15.29562"
"17.19000","-4.35476","15.33602"
"17.20800","-4.35934","15.38745"
"17.22600","-4.36398","15.46075"
"17.24400","-4.36862","15.53676"
"17.26200","-4.37321","15.60953"
"17.28000","-4.37780","15.66282"
"17.29800","-4.38241","15.71144"
"17.31600","-4.38698","15.76721"
"17.33400","-4.39148","15.81921"
"17.35200","-4.39598","15.87385"
"17.37000","-4.40053","15.90187"
"17.38800","-4.40509","15.94119"
"17.40600","-4.40965","15.98526"
"17.42400","-4.41423","16.04117"
"17.44200","-4.41885","16.10428"
"17.46000","-4.42347","16.16024"
"17.47800","-4.42800","16.23173"
"17.49600","-4.43251","16.28819"
"17.51400","-4.43705","16.34398"
"17.53200","-4.44165","16.39121"
"17.55000","-4.44621","16.41990"
"17.56800","-4.45077","16.46053"
"17.58600","-4.45541","16.50311"
"17.60400","-4.46009","16.55180"
"17.62200","-4.46470","16.59696"
"17.64000","-4.46925","16.65017"
"17.65800","-4.47381","16.71530"
"17.67600","-4.47837","16.78851"
"17.69400","-4.48290","16.87381"
"17.71200","-4.48739","16.94489"
"17.73000","-4.49191","17.00485"
"17.74800","-4.49652","17.06838"
"17.76600","-4.50117","17.12716"
"17.78400","-4.50577","17.19545"
"17.80200","-4.51036","17.24681"
"17.82000","-4.51496","17.29434"
"17.83800","-4.51953","17.33754"
"17.85600","-4.52399","17.37893"
"17.87400","-4.52845","17.43314"
"17.89200","-4.53301","17.48794"
"17.91000","-4.53763","17.55445"
"17.92800","-4.54225","17.61476"
"17.94600","-4.54685","17.67775"
"17.96400","-4.55148","17.74478"
"17.98200","-4.55614","17.79569"
"18.00000","-4.56073","17.85188"
"18.01800","-4.56523","17.90433"
"18.03600","-4.56975","17.95378"
"18.05400","-4.57431","17.99860"
"18.07200","-4.57885","18.06124"
"18.09000","-4.58337","18.13846"
"18.10800","-4.58796","18.21576"
"18.12600","-4.59263","18.30135"
"18.14400","-4.59729","18.38540"
"18.16200","-4.60185","18.46183"
"18.18000","-4.60638","18.54017"
"18.19800","-4.61092","18.60104"
"18.21600","-4.61544","18.65474"
"18.23400","-4.61992","18.70370"
"18.25200","-4.62439","18.75046"
"18.27000","-4.62896","18.80048"
"18.28800","-4.63363","18.86357"
"18.30600","-4.63829","18.95235"
"18.32400","-4.64289","19.03378"
"18.34200","-4.64749","19.11713"
"18.36000","-4.65209","19.17859"
"18.37800","-4.65666","19.23065"
"18.39600","-4.66118","19.29698"
"18.41400","-4.66571","19.36010"
"18.43200","-4.67027","19.40736"
"18.45000","-4.67486","19.45847"
"18.46800","-4.67944","19.52287"
"18.48600","-4.68404","19.57046"
"18.50400","-4.68865","19.62680"
"18.52200","-4.69325","19.72094"
"18.54000","-4.69781","19.80819"
"18.55800","-4.70233","19.90083"
"18.57600","-4.70686","19.99055"
"18.59400","-4.71139","20.07506"
"18.61200","-4.71589","20.16563"
"18.63000","-4.72044","20.24621"
"18.64800","-4.72505","20.32719"
"18.66600","-4.72970","20.39923"
"18.68400","-4.73431","20.47192"
"18.70200","-4.73890","20.53245"
"18.72000","-4.74348","20.58892"
"18.73800","-4.74804","20.66029"
"18.75600","-4.75256","20.72828"
"18.77400","-4.75709","20.81400"
"18.79200","-4.76168","20.89625"
"18.81000","-4.76633","20.97065"
"18.82800","-4.77097","21.04298"
"18.84600","-4.77555","21.09168"
"18.86400","-4.78013","21.15509"
"18.88200","-4.78474","21.21266"
"18.90000","-4.78928","21.27351"
"18.91800","-4.79376","21.33768"
"18.93600","-4.79828","21.41111"
"18.95400","-4.80285","21.50821"
"18.97200","-4.80742","21.59544"
"18.99000","-4.81198","21.69384"
"19.00800","-4.81656","21.80381"
"19.02600","-4.82118","21.90472"
"19.04400","-4.82579","22.00064"
"19.06200","-4.83033","22.08965"
"19.08000","-4.83485","22.18222"
"19.09800","-4.83941","22.26180"
"19.11600","-4.84400","22.32751"
"19.13400","-4.84853","22.37395"
"19.15200","-4.85307","22.42285"
"19.17000","-4.85771","22.50952"
"19.18800","-4.86239","22.59348"
"19.20600","-4.86701","22.69855"
"19.22400","-4.87158","22.79626"
"19.24200","-4.87614","22.88522"
"19.26000","-4.88071","22.97988"
"19.27800","-4.88524","23.04900"
"19.29600","-4.88972","23.12454"
"19.31400","-4.89425","23.18737"
"19.33200","-4.89888","23.25923"
"19.35000","-4.90351","23.33107"
"19.36800","-4.90809","23.40674"
"19.38600","-4.91267","23.51321"
"19.40400","-4.91727","23.61506"
"19.42200","-4.92184","23.72183"
"19.44000","-4.92632","23.83517"
"19.45800","-4.93081","23.93566"
"19.47600","-4.93538","24.03617"
"19.49400","-4.93999","24.12967"
"19.51200","-4.94458","24.22279"
"19.53000","-4.94915","24.30339"
"19.54800","-4.95378","24.37693"
"19.56600","-4.95845","24.45440"
"19.58400","-4.96304","24.52967"
"19.60200","-4.96755","24.62901"
"19.62000","-4.97210","24.74166"
"19.63800","-4.97667","24.85361"
"19.65600","-4.98122","24.94776"
"19.67400","-4.98574","25.04079"
"19.69200","-4.99034","25.14145"
"19.71000","-4.99499","25.21646"
"19.72800","-4.99961","25.29916"
"19.74600","-5.00416","25.37316"
"19.76400","-5.00869","25.44928"
"19.78200","-5.01324","25.53135"
"19.80000","-5.01777","25.62072"
"19.81800","-5.02228","25.73907"
"19.83600","-5.02679","25.84829"
"19.85400","-5.03138","25.96971"
"19.87200","-5.03605","26.08569"
"19.89000","-5.04068","26.20896"
"19.90800","-5.04527","26.34008"
"19.92600","-5.04986","26.44981"
"19.94400","-5.05444","26.56425"
"19.96200","-5.05898","26.66945"
"19.98000","-5.06349","26.74729"
"19.99800","-5.06803","26.82759"
"20.01600","-5.07261","26.90333"
"20.03400","-5.07720","26.99535"
"20.05200","-5.08179","27.09318"
"20.07000","-5.08640","27.21048"
"20.08800","-5.09102","27.32662"
"20.10600","-5.09561","27.43001"
"20.12400","-5.10014","27.54602"
"20.14200","-5.10466","27.62874"
"20.16000","-5.10920","27.72540"
"20.17800","-5.11373","27.80789"
"20.19600","-5.11824","27.88100"
"20.21400","-5.12281","27.97971"
"20.23200","-5.12742","28.08288"
"20.25000","-5.13203","28.20939"
"20.26800","-5.13662","28.33489"
"20.28600","-5.14121","28.47538"
"20.30400","-5.14579","28.60871"
"20.32200","-5.15038","28.73881"
"20.34000","-5.15490","28.87857"
"20.35800","-5.15943","29.00415"
"20.37600","-5.16402","29.12165"
"20.39400","-5.16867","29.21804"
"20.41200","-5.17331","29.30937"
"20.43000","-5.17789","29.41238"
"20.44800","-5.18249","29.51439"
"20.46600","-5.18709","29.62971"
"20.48400","-5.19162","29.73615"
"20.50200","-5.19611","29.84153"
"20.52000","-5.20064","29.94950"
"20.53800","-5.20521","30.05625"
"20.55600","-5.20977","30.18353"
"20.57400","-5.21431","30.28969"
"20.59200","-5.21889","30.39444"
"20.61000","-5.22351","30.48893"
"20.62800","-5.22811","30.58077"
"20.64600","-5.23263","30.69587"
"20.66400","-5.23716","30.80960"
"20.68200","-5.24175","30.93809"
"20.70000","-5.24635","31.07656"
"20.71800","-5.25089","31.24664"
"20.73600","-5.25546","31.44551"
"20.75400","-5.26010","31.51687"
"20.77200","-5.26475","31.48288"
"20.79000","-5.26934","31.45769"
"20.80800","-5.27388","31.47904"
"20.82600","-5.27844","31.55986"
"20.84400","-5.28303","31.67175"
"20.86200","-5.28758","31.78669"
"20.88000","-5.29208","31.88872"
"20.89800","-5.29664","32.03124"
"20.91600","-5.30126","32.21556"
"20.93400","-5.30587","32.40650"
"20.95200","-5.31042","32.51272"
"20.97000","-5.31498","32.51196"
"20.98800","-5.31957","32.54296"
"21.00600","-5.32413","32.63477"
"21.02400","-5.32862","32.77209"
"21.04200","-5.33313","32.92645"
"21.06000","-5.33772","33.06712"
"21.07800","-5.34235","33.18382"
"21.09600","-5.34694","33.29628"
"21.11400","-5.35153","33.44306"
"21.13200","-5.35615","33.60094"
"21.15000","-5.36080","33.75805"
"21.16800","-5.36538","33.89771"
"21.18600","-5.36990","33.98756"
"21.20400","-5.37444","34.07950"
"21.22200","-5.37901","34.16053"
"21.24000","-5.38354","34.25317"
"21.25800","-5.38806","34.36182"
"21.27600","-5.39266","34.47944"
"21.29400","-5.39730","34.60231"
"21.31200","-5.40192","34.71863"
"21.33000","-5.40647","34.86898"
"21.34800","-5.41101","35.04901"
"21.36600","-5.41557","35.22760"
"21.38400","-5.42011","35.37051"
"21.40200","-5.42461","35.43741"
"21.42000","-5.42912","35.49861"
"21.43800","-5.43371","35.58259"
"21.45600","-5.43837","35.68496"
"21.47400","-5.44299","35.79346"
"21.49200","-5.44759","35.88500"
"21.51000","-5.45219","36.00273"
"21.52800","-5.45678","36.11966"
"21.54600","-5.46130","36.25108"
"21.56400","-5.46583","36.37849"
"21.58200","-5.47039","36.51498"
"21.60000","-5.47500","36.65328"
"21.61800","-5.47960","36.77177"
"21.63600","-5.48417","36.87686"
"21.65400","-5.48876","36.98991"
"21.67200","-5.49335","37.11408"
"21.69000","-5.49792","37.20370"
"21.70800","-5.50243","37.29094"
"21.72600","-5.50695","37.39889"
"21.74400","-5.51150","37.53316"
"21.76200","-5.51605","37.69855"
"21.78000","-5.52059","37.89300"
"21.79800","-5.52516","38.07662"
"21.81600","-5.52977","38.22458"
"21.83400","-5.53437","38.30929"
"21.85200","-5.53894","38.40446"
"21.87000","-5.54352","38.52426"
"21.88800","-5.54812","38.66510"
"21.90600","-5.55269","38.77903"
"21.92400","-5.55722","38.85793"
"21.94200","-5.56176","38.93872"
"21.96000","-5.56637","39.03226"
"21.97800","-5.57102","39.17200"
"21.99600","-5.57563","39.31517"
"22.01400","-5.58022","39.46274"
"22.03200","-5.58482","39.60965"
"22.05000","-5.58941","39.70991"
"22.06800","-5.59393","39.80287"
"22.08600","-5.59842","39.89211"
"22.10400","-5.60295","40.01358"
"22.12200","-5.60752","40.15264"
"22.14000","-5.61210","40.27800"
"22.15800","-5.61664","40.40812"
"22.17600","-5.62122","40.53810"
"22.19400","-5.62584","40.69934"
"22.21200","-5.63043","40.88020"
"22.23000","-5.63496","41.03168"
"22.24800","-5.63949","41.15369"
"22.26600","-5.64407","41.23614"
"22.28400","-5.64866","41.33640"
"22.30200","-5.65321","41.47067"
"22.32000","-5.65780","41.61110"
"22.33800","-5.66246","41.72009"
"22.35600","-5.66713","41.80587"
"22.37400","-5.67171","41.89378"
"22.39200","-5.67626","42.01756"
"22.41000","-5.68081","42.19041"
"22.42800","-5.68536","42.35352"
"22.44600","-5.68988","42.48764"
"22.46400","-5.69439","42.61831"
"22.48200","-5.69896","42.72398"
"22.50000","-5.70360","42.83633"
"22.51800","-5.70822","42.92558"
"22.53600","-5.71279","43.01340"
"22.55400","-5.71736","43.10846"
"22.57200","-5.72194","43.21854"
"22.59000","-5.72647","43.33945"
"22.60800","-5.73093","43.45580"
"22.62600","-5.73544","43.61080"
"22.64400","-5.74004","43.81630"
"22.66200","-5.74467","44.01290"
"22.68000","-5.74927","44.12917"
"22.69800","-5.75386","44.17086"
"22.71600","-5.75851","44.24245"
"22.73400","-5.76316","44.35490"
"22.75200","-5.76771","44.47168"
"22.77000","-5.77221","44.54916"
"22.78800","-5.77675","44.62822"
"22.80600","-5.78133","44.77156"
"22.82400","-5.78587","44.92184"
"22.84200","-5.79042","45.06392"
"22.86000","-5.79504","45.20748"
"22.87800","-5.79969","45.35847"
"22.89600","-5.80428","45.53276"
"22.91400","-5.80880","45.68050"
"22.93200","-5.81334","45.82220"
"22.95000","-5.81788","45.93928"
"22.96800","-5.82241","46.04240"
"22.98600","-5.82690","46.13799"
"23.00400","-5.83142","46.24178"
"23.02200","-5.83603","46.38490"
"23.04000","-5.84070","46.53731"
"23.05800","-5.84532","46.70778"
"23.07600","-5.84992","46.86230"
"23.09400","-5.85453","46.98991"
"23.11200","-5.85912","47.05402"
"23.13000","-5.86364","47.10725"
"23.14800","-5.86816","47.19463"
"23.16600","-5.87271","47.28645"
"23.18400","-5.87731","47.36600"
"23.20200","-5.88191","47.43841"
"23.22000","-5.88650","47.49079"
"23.23800","-5.89109","47.60406"
"23.25600","-5.89568","47.74540"
"23.27400","-5.90023","47.93203"
"23.29200","-5.90474","48.12851"
"23.31000","-5.90924","48.30255"
"23.32800","-5.91379","48.44892"
"23.34600","-5.91835","48.56379"
"23.36400","-5.92290","48.70606"
"23.38200","-5.92748","48.84658"
"23.40000","-5.93211","48.98402"
"23.41800","-5.93672","49.13133"
"23.43600","-5.94131","49.25782"
"23.45400","-5.94587","49.39312"
"23.47200","-5.95044","49.49250"
"23.49000","-5.95500","49.60614"
"23.50800","-5.95952","49.76827"
"23.52600","-5.96407","49.94058"
"23.54400","-5.96870","50.01730"
"23.56200","-5.97336","50.06516"
"23.58000","-5.97797","50.15326"
"23.59800","-5.98255","50.24864"
"23.61600","-5.98714","50.30815"
"23.63400","-5.99173","50.33485"
"23.65200","-5.99626","50.36292"
"23.67000","-6.00075","50.39595"
"23.68800","-6.00529","50.52078"
"23.70600","-6.00987","50.66513"
"23.72400","-6.01445","50.82854"
"23.74200","-6.01900","51.02142"
"23.76000","-6.02359","51.19588"
"23.77800","-6.02820","51.32485"
"23.79600","-6.03278","51.41446"
"23.81400","-6.03729","51.47880"
"23.83200","-6.04182","51.62214"
"23.85000","-6.04642","51.80433"
"23.86800","-6.05101","51.91219"
"23.88600","-6.05556","52.02526"
"23.90400","-6.06015","52.15512"
"23.92200","-6.06480","52.32837"
"23.94000","-6.06944","52.53699"
"23.95800","-6.07402","52.73135"
"23.97600","-6.07858","52.88290"
"23.99400","-6.08314","52.92934"
"24.01200","-6.08770","52.98188"
"24.03000","-6.09221","53.09613"
"24.04800","-6.09672","53.20078"
"24.06600","-6.10131","53.27458"
"24.08400","-6.10596","53.31122"
"24.10200","-6.11057","53.33569"
"24.12000","-6.11511","53.41779"
"24.13800","-6.11967","53.54834"
"24.15600","-6.12424","53.74299"
"24.17400","-6.12876","53.94456"
"24.19200","-6.13324","54.08391"
"24.21000","-6.13779","54.19831"
"24.22800","-6.14242","54.30973"
"24.24600","-6.14705","54.42411"
"24.26400","-6.15163","54.53117"
"24.28200","-6.15622","54.65225"
"24.30000","-6.16086","54.77455"
"24.31800","-6.16550","54.90663"
"24.33600","-6.17004","54.99945"
"24.35400","-6.17455","55.14776"
"24.37200","-6.17910","55.35239"
"24.39000","-6.18367","55.60727"
"24.40800","-6.18820","55.79670"
"24.42600","-6.19276","55.86476"
"24.44400","-6.19740","55.92136"
"24.46200","-6.20205","55.99648"
"24.48000","-6.20664","56.08545"
"24.49800","-6.21116","56.13217"
"24.51600","-6.21568","56.14522"
"24.53400","-6.22021","56.20777"
"24.55200","-6.22471","56.30994"
"24.57000","-6.22922","56.46637"
"24.58800","-6.23378","56.63523"
"24.60600","-6.23842","56.77741"
"24.62400","-6.24309","56.92685"
"24.64200","-6.24770","57.06384"
"24.66000","-6.25228","57.21981"
"24.67800","-6.25686","57.34250"
"24.69600","-6.26141","57.42691"
"24.71400","-6.26592","57.52078"
"24.73200","-6.27045","57.59623"
"24.75000","-6.27504","57.67405"
"24.76800","-6.27967","57.76987"
"24.78600","-6.28428","57.90419"
"24.80400","-6.28887","58.13000"
"24.82200","-6.29347","58.39152"
"24.84000","-6.29807","58.57198"
"24.85800","-6.30261","58.66633"
"24.87600","-6.30712","58.76300"
"24.89400","-6.31164","58.85254"
"24.91200","-6.31619","58.91940"
"24.93000","-6.32073","58.96548"
"24.94800","-6.32526","58.98252"
"24.96600","-6.32984","59.02542"
"24.98400","-6.33446","59.11913"
"25.00200","-6.33905","59.24670"
"25.02000","-6.34362","59.39475"
"25.03800","-6.34820","59.56495"
"25.05600","-6.35280","59.77021"
"25.07400","-6.35736","59.93811"
"25.09200","-6.36186","60.07848"
"25.11000","-6.36641","60.21736"
"25.12800","-6.37104","60.35703"
"25.14600","-6.37571","60.43266"
"25.16400","-6.38034","60.49173"
"25.18200","-6.38493","60.58602"
"25.20000","-6.38952","60.68534"
"25.21800","-6.39408","60.81055"
"25.23600","-6.39858","60.98127"
"25.25400","-6.40306","61.16947"
"25.27200","-6.40760","61.34968"
"25.29000","-6.41219","61.44566"
"25.30800","-6.41677","61.53987"
"25.32600","-6.42133","61.63172"
"25.34400","-6.42594","61.74638"
"25.36200","-6.43056","61.81345"
"25.38000","-6.43513","61.83784"
"25.39800","-6.43962","61.83243"
"25.41600","-6.44414","61.84163"
"25.43400","-6.44873","61.93835"
"25.45200","-6.45332","62.08850"
"25.47000","-6.45786","62.22575"
"25.48800","-6.46246","62.37645"
"25.50600","-6.46712","62.55859"
"25.52400","-6.47177","62.76659"
"25.54200","-6.47635","62.96067"
"25.56000","-6.48090","63.11835"
"25.57800","-6.48547","63.14914"
"25.59600","-6.49001","62.94479"
"25.61400","-6.49453","62.60600"
"25.63200","-6.49905","62.33632"
"25.65000","-6.50365","62.16596"
"25.66800","-6.50829","62.00586"
"25.68600","-6.51288","61.74437"
"25.70400","-6.51743","61.25124"
"25.72200","-6.52200","60.37746"
"25.74000","-6.52658","59.05983"
"25.75800","-6.53110","57.41891"
"25.77600","-6.53556","55.58975"
"25.79400","-6.54010","53.57562"
"25.81200","-6.54472","51.55496"
"25.83000","-6.54935","49.76817"
"25.84800","-6.55394","48.11853"
"25.86600","-6.55856","46.57299"
"25.88400","-6.56322","45.08300"
"25.90200","-6.56785","43.47906"
"25.92000","-6.57237","41.98742"
"25.93800","-6.57687","40.50136"
"25.95600","-6.58141","38.72655"
"25.97400","-6.58596","36.37770"
"25.99200","-6.59049","33.35182"
"26.01000","-6.59507","29.95716"
"26.02800","-6.59971","26.34739"
"26.04600","-6.60438","22.63472"
"26.06400","-6.60896","18.94300"
"26.08200","-6.61347","15.17271"
"26.10000","-6.61798","10.71315"
"26.11800","-6.62250","6.48562"
"26.13600","-6.62702","2.86050"
"26.15400","-6.63154","0.56469"
"26.17200","-6.63612","-0.22901"
"26.19000","-6.64076","-0.26239"
"27.69300","-6.64679","-0.00514"
"29.49300","-6.64679","-0.00534"
"31.29300","-6.64679","-0.00512"
"33.09300","-6.64679","-0.00448"
"34.89300","-6.64679","-0.00402"
"36.26300","-6.63847","0.83081"
"36.29500","-6.63100","7.08349"
"36.31300","-6.62579","12.62308"
"36.33100","-6.62051","18.38068"
"36.34900","-6.61543","23.89242"
"36.36700","-6.61058","29.14714"
"36.38500","-6.60590","34.24035"
"36.40300","-6.60133","39.22887"
"36.42100","-6.59671","44.25234"
"36.43900","-6.59202","49.33401"
"36.45700","-6.58733","54.31960"
"36.47900","-6.58172","59.90768"
"36.51500","-6.57262","67.07564"
"36.99200","-6.45130","67.36659"
"37.65400","-6.28322","62.80162"
"38.30700","-6.11753","58.24474"
"38.97200","-5.94844","53.68140"
"39.61500","-5.78512","49.10194"
"40.26700","-5.61968","44.52679"
"40.91900","-5.45396","39.96576"
"41.57400","-5.28758","35.39072"
"42.28300","-5.10751","30.83480"
"43.04800","-4.91335","26.28682"
"44.02800","-4.66421","21.73557"
"45.27300","-4.34795","17.33854"
"46.93900","-3.92489","13.38847"
"48.73800","-3.46789","10.75436"
"50.53800","-3.01067","8.77863"
"52.33800","-2.55353","7.40221"
"54.12000","-2.10102","5.87668"
"55.85100","-1.66131","4.96424"
"57.47600","-1.24847","4.10005"
"59.11800","-0.83130","3.96160"
"60.85400","-0.39049","3.44067"
"62.18900","-0.05146","4.64461"
"62.39200","0.00008","7.61190"