File: Specimen_RawData_2_SN1A0005640.csv
Time,Extension,Load
(s),(mm),(N)
"0.00000","0.00000","2.57282"
"0.01800","-0.00002","2.56950"
"0.03600","-0.00040","2.46403"
"0.05400","-0.00206","2.34804"
"0.07200","-0.00524","2.31823"
"0.09000","-0.00856","2.32599"
"0.10800","-0.01214","2.32766"
"0.12600","-0.01658","2.31760"
"0.14400","-0.02173","2.29431"
"0.16200","-0.02709","2.26870"
"0.18000","-0.03233","2.24921"
"0.19800","-0.03734","2.23800"
"0.21600","-0.04209","2.24056"
"0.23400","-0.04671","2.24954"
"0.25200","-0.05131","2.25006"
"0.27000","-0.05588","2.24308"
"0.28800","-0.06039","2.23625"
"0.30600","-0.06489","2.23836"
"0.32400","-0.06946","2.25066"
"0.34200","-0.07409","2.27789"
"0.36000","-0.07870","2.30502"
"0.37800","-0.08328","2.32225"
"0.39600","-0.08790","2.32716"
"0.41400","-0.09255","2.32670"
"0.43200","-0.09716","2.33447"
"0.45000","-0.10168","2.33767"
"0.46800","-0.10622","2.33327"
"0.48600","-0.11078","2.33113"
"0.50400","-0.11534","2.33637"
"0.52200","-0.11988","2.35798"
"0.54000","-0.12446","2.38436"
"0.55800","-0.12910","2.40817"
"0.57600","-0.13373","2.41345"
"0.59400","-0.13829","2.40566"
"0.61200","-0.14281","2.39772"
"0.63000","-0.14735","2.40150"
"0.64800","-0.15188","2.40894"
"0.66600","-0.15638","2.40887"
"0.68400","-0.16088","2.40168"
"0.70200","-0.16546","2.40068"
"0.72000","-0.17012","2.40147"
"0.73800","-0.17478","2.39694"
"0.75600","-0.17938","2.38944"
"0.77400","-0.18397","2.38876"
"0.79200","-0.18857","2.40017"
"0.81000","-0.19314","2.41631"
"0.82800","-0.19766","2.43526"
"0.84600","-0.20219","2.44885"
"0.86400","-0.20676","2.44873"
"0.88200","-0.21137","2.44266"
"0.90000","-0.21596","2.42069"
"0.91800","-0.22055","2.40518"
"0.93600","-0.22515","2.39685"
"0.95400","-0.22973","2.39795"
"0.97200","-0.23425","2.41151"
"0.99000","-0.23877","2.43676"
"1.00800","-0.24329","2.46035"
"1.02600","-0.24785","2.48281"
"1.04400","-0.25239","2.50236"
"1.06200","-0.25695","2.51023"
"1.08000","-0.26156","2.51212"
"1.09800","-0.26618","2.50941"
"1.11600","-0.27077","2.50247"
"1.13400","-0.27532","2.50185"
"1.15200","-0.27990","2.49813"
"1.17000","-0.28450","2.49186"
"1.18800","-0.28905","2.48708"
"1.20600","-0.29357","2.49184"
"1.22400","-0.29815","2.50100"
"1.24200","-0.30280","2.50625"
"1.26000","-0.30744","2.51984"
"1.27800","-0.31204","2.53306"
"1.29600","-0.31662","2.53624"
"1.31400","-0.32121","2.53828"
"1.33200","-0.32576","2.54108"
"1.35000","-0.33026","2.54689"
"1.36800","-0.33478","2.55268"
"1.38600","-0.33934","2.56197"
"1.40400","-0.34393","2.57651"
"1.42200","-0.34849","2.58953"
"1.44000","-0.35306","2.60714"
"1.45800","-0.35767","2.62004"
"1.47600","-0.36227","2.62847"
"1.49400","-0.36680","2.62984"
"1.51200","-0.37131","2.62832"
"1.53000","-0.37587","2.62505"
"1.54800","-0.38047","2.61819"
"1.56600","-0.38503","2.60330"
"1.58400","-0.38960","2.57581"
"1.60200","-0.39423","2.55118"
"1.62000","-0.39889","2.54762"
"1.63800","-0.40350","2.56026"
"1.65600","-0.40805","2.58749"
"1.67400","-0.41259","2.62058"
"1.69200","-0.41716","2.64682"
"1.71000","-0.42171","2.65872"
"1.72800","-0.42621","2.66024"
"1.74600","-0.43074","2.66042"
"1.76400","-0.43536","2.66072"
"1.78200","-0.44000","2.65507"
"1.80000","-0.44459","2.64975"
"1.81800","-0.44916","2.64885"
"1.83600","-0.45373","2.65009"
"1.85400","-0.45830","2.65589"
"1.87200","-0.46279","2.66475"
"1.89000","-0.46728","2.66346"
"1.90800","-0.47184","2.66012"
"1.92600","-0.47647","2.65213"
"1.94400","-0.48107","2.64649"
"1.96200","-0.48566","2.63832"
"1.98000","-0.49029","2.63843"
"1.99800","-0.49495","2.64124"
"2.01600","-0.49954","2.63442"
"2.03400","-0.50405","2.62856"
"2.05200","-0.50857","2.62588"
"2.07000","-0.51314","2.63195"
"2.08800","-0.51770","2.65011"
"2.10600","-0.52223","2.67307"
"2.12400","-0.52682","2.69474"
"2.14200","-0.53147","2.71085"
"2.16000","-0.53610","2.71696"
"2.17800","-0.54065","2.71658"
"2.19600","-0.54517","2.71725"
"2.21400","-0.54970","2.71976"
"2.23200","-0.55424","2.71681"
"2.25000","-0.55874","2.71282"
"2.26800","-0.56324","2.70720"
"2.28600","-0.56781","2.70987"
"2.30400","-0.57247","2.72857"
"2.32200","-0.57711","2.74856"
"2.34000","-0.58171","2.76543"
"2.35800","-0.58631","2.77657"
"2.37600","-0.59090","2.77709"
"2.39400","-0.59545","2.77561"
"2.41200","-0.59997","2.77404"
"2.43000","-0.60449","2.77687"
"2.44800","-0.60905","2.77914"
"2.46600","-0.61364","2.78283"
"2.48400","-0.61823","2.78279"
"2.50200","-0.62285","2.77319"
"2.52000","-0.62747","2.77919"
"2.53800","-0.63208","2.78979"
"2.55600","-0.63662","2.80239"
"2.57400","-0.64114","2.81388"
"2.59200","-0.64568","2.82147"
"2.61000","-0.65023","2.82282"
"2.62800","-0.65474","2.82360"
"2.64600","-0.65929","2.83062"
"2.66400","-0.66389","2.83123"
"2.68200","-0.66852","2.83076"
"2.70000","-0.67313","2.83494"
"2.71800","-0.67771","2.85045"
"2.73600","-0.68228","2.87941"
"2.75400","-0.68684","2.90432"
"2.77200","-0.69137","2.92328"
"2.79000","-0.69589","2.93248"
"2.80800","-0.70049","2.93288"
"2.82600","-0.70516","2.93111"
"2.84400","-0.70979","2.92141"
"2.86200","-0.71436","2.91232"
"2.88000","-0.71894","2.90253"
"2.89800","-0.72352","2.89878"
"2.91600","-0.72807","2.89493"
"2.93400","-0.73256","2.88997"
"2.95200","-0.73708","2.89324"
"2.97000","-0.74166","2.91210"
"2.98800","-0.74626","2.93215"
"3.00600","-0.75082","2.94357"
"3.02400","-0.75539","2.95422"
"3.04200","-0.75999","2.96647"
"3.06000","-0.76458","2.97387"
"3.07800","-0.76910","2.98177"
"3.09600","-0.77362","2.98767"
"3.11400","-0.77821","2.98853"
"3.13200","-0.78282","2.98928"
"3.15000","-0.78737","2.99277"
"3.16800","-0.79192","3.00217"
"3.18600","-0.79654","3.01563"
"3.20400","-0.80121","3.02886"
"3.22200","-0.80583","3.04217"
"3.24000","-0.81039","3.04702"
"3.25800","-0.81494","3.05004"
"3.27600","-0.81951","3.05418"
"3.29400","-0.82405","3.05577"
"3.31200","-0.82854","3.05113"
"3.33000","-0.83308","3.04412"
"3.34800","-0.83770","3.03595"
"3.36600","-0.84234","3.02660"
"3.38400","-0.84691","3.02816"
"3.40200","-0.85148","3.03291"
"3.42000","-0.85607","3.04415"
"3.43800","-0.86064","3.06212"
"3.45600","-0.86514","3.07793"
"3.47400","-0.86963","3.08850"
"3.49200","-0.87419","3.09567"
"3.51000","-0.87880","3.10562"
"3.52800","-0.88338","3.11159"
"3.54600","-0.88796","3.11164"
"3.56400","-0.89259","3.11035"
"3.58200","-0.89726","3.11549"
"3.60000","-0.90187","3.12741"
"3.61800","-0.90640","3.13864"
"3.63600","-0.91094","3.14725"
"3.65400","-0.91551","3.15220"
"3.67200","-0.92004","3.15848"
"3.69000","-0.92456","3.16945"
"3.70800","-0.92915","3.17580"
"3.72600","-0.93379","3.17663"
"3.74400","-0.93842","3.16869"
"3.76200","-0.94296","3.15729"
"3.78000","-0.94751","3.14614"
"3.79800","-0.95206","3.13746"
"3.81600","-0.95661","3.13845"
"3.83400","-0.96110","3.14104"
"3.85200","-0.96561","3.15508"
"3.87000","-0.97019","3.17505"
"3.88800","-0.97484","3.19485"
"3.90600","-0.97945","3.20842"
"3.92400","-0.98402","3.21674"
"3.94200","-0.98861","3.22414"
"3.96000","-0.99320","3.22773"
"3.97800","-0.99774","3.22907"
"3.99600","-1.00228","3.22806"
"4.01400","-1.00684","3.22315"
"4.03200","-1.01144","3.22602"
"4.05000","-1.01605","3.23969"
"4.06800","-1.02062","3.25910"
"4.08600","-1.02521","3.27497"
"4.10400","-1.02982","3.28385"
"4.12200","-1.03440","3.29508"
"4.14000","-1.03894","3.30201"
"4.15800","-1.04346","3.30306"
"4.17600","-1.04800","3.29893"
"4.19400","-1.05255","3.28822"
"4.21200","-1.05708","3.27507"
"4.23000","-1.06164","3.26646"
"4.24800","-1.06623","3.26665"
"4.26600","-1.07084","3.27034"
"4.28400","-1.07541","3.28414"
"4.30200","-1.07998","3.30693"
"4.32000","-1.08456","3.33057"
"4.33800","-1.08913","3.34873"
"4.35600","-1.09365","3.35976"
"4.37400","-1.09817","3.36649"
"4.39200","-1.10276","3.36679"
"4.41000","-1.10741","3.36421"
"4.42800","-1.11205","3.35738"
"4.44600","-1.11665","3.34886"
"4.46400","-1.12127","3.34969"
"4.48200","-1.12588","3.35852"
"4.50000","-1.13043","3.37706"
"4.51800","-1.13492","3.39292"
"4.53600","-1.13943","3.40789"
"4.55400","-1.14399","3.42229"
"4.57200","-1.14857","3.43300"
"4.59000","-1.15313","3.44037"
"4.60800","-1.15771","3.43718"
"4.62600","-1.16233","3.42734"
"4.64400","-1.16693","3.41518"
"4.66200","-1.17144","3.40211"
"4.68000","-1.17596","3.39915"
"4.69800","-1.18054","3.40488"
"4.71600","-1.18514","3.41952"
"4.73400","-1.18970","3.43523"
"4.75200","-1.19427","3.44772"
"4.77000","-1.19891","3.46147"
"4.78800","-1.20358","3.46959"
"4.80600","-1.20816","3.47068"
"4.82400","-1.21270","3.47262"
"4.84200","-1.21726","3.48528"
"4.86000","-1.22182","3.49883"
"4.87800","-1.22636","3.50268"
"4.89600","-1.23085","3.50904"
"4.91400","-1.23541","3.51889"
"4.93200","-1.24003","3.52590"
"4.95000","-1.24466","3.53243"
"4.96800","-1.24923","3.54028"
"4.98600","-1.25380","3.54717"
"5.00400","-1.25839","3.55078"
"5.02200","-1.26297","3.55630"
"5.04000","-1.26748","3.55617"
"5.05800","-1.27199","3.55096"
"5.07600","-1.27655","3.54769"
"5.09400","-1.28115","3.54198"
"5.11200","-1.28574","3.53715"
"5.13000","-1.29035","3.52891"
"5.14800","-1.29499","3.53531"
"5.16600","-1.29965","3.55537"
"5.18400","-1.30422","3.57746"
"5.20200","-1.30870","3.60353"
"5.22000","-1.31323","3.62250"
"5.23800","-1.31779","3.64030"
"5.25600","-1.32235","3.65567"
"5.27400","-1.32689","3.65281"
"5.29200","-1.33151","3.63953"
"5.31000","-1.33617","3.62164"
"5.32800","-1.34078","3.61321"
"5.34600","-1.34530","3.61770"
"5.36400","-1.34982","3.63494"
"5.38200","-1.35435","3.65827"
"5.40000","-1.35888","3.67626"
"5.41800","-1.36338","3.69380"
"5.43600","-1.36791","3.70977"
"5.45400","-1.37253","3.71757"
"5.47200","-1.37720","3.72504"
"5.49000","-1.38184","3.73188"
"5.50800","-1.38642","3.74017"
"5.52600","-1.39101","3.73351"
"5.54400","-1.39560","3.72529"
"5.56200","-1.40012","3.72399"
"5.58000","-1.40463","3.73064"
"5.59800","-1.40917","3.73786"
"5.61600","-1.41377","3.74384"
"5.63400","-1.41839","3.75414"
"5.65200","-1.42299","3.76336"
"5.67000","-1.42758","3.77566"
"5.68800","-1.43217","3.78422"
"5.70600","-1.43672","3.78863"
"5.72400","-1.44123","3.79342"
"5.74200","-1.44577","3.79842"
"5.76000","-1.45033","3.80182"
"5.77800","-1.45488","3.80845"
"5.79600","-1.45941","3.82042"
"5.81400","-1.46398","3.83161"
"5.83200","-1.46860","3.83569"
"5.85000","-1.47322","3.83513"
"5.86800","-1.47780","3.83545"
"5.88600","-1.48238","3.84507"
"5.90400","-1.48696","3.85972"
"5.92200","-1.49153","3.86391"
"5.94000","-1.49607","3.85752"
"5.95800","-1.50061","3.84046"
"5.97600","-1.50521","3.82095"
"5.99400","-1.50986","3.80706"
"6.01200","-1.51448","3.80417"
"6.03000","-1.51906","3.81171"
"6.04800","-1.52365","3.82302"
"6.06600","-1.52823","3.84398"
"6.08400","-1.53275","3.86558"
"6.10200","-1.53724","3.88807"
"6.12000","-1.54177","3.90699"
"6.13800","-1.54634","3.91125"
"6.15600","-1.55092","3.90771"
"6.17400","-1.55547","3.90068"
"6.19200","-1.56005","3.89857"
"6.21000","-1.56467","3.89897"
"6.22800","-1.56925","3.90693"
"6.24600","-1.57376","3.92167"
"6.26400","-1.57829","3.93459"
"6.28200","-1.58287","3.95224"
"6.30000","-1.58746","3.96827"
"6.31800","-1.59202","3.98158"
"6.33600","-1.59661","3.99150"
"6.35400","-1.60128","3.99503"
"6.37200","-1.60595","3.99279"
"6.39000","-1.61052","3.98364"
"6.40800","-1.61506","3.97566"
"6.42600","-1.61962","3.97574"
"6.44400","-1.62418","3.98258"
"6.46200","-1.62871","3.99398"
"6.48000","-1.63321","4.00312"
"6.49800","-1.63777","4.01492"
"6.51600","-1.64240","4.03624"
"6.53400","-1.64701","4.05592"
"6.55200","-1.65156","4.07113"
"6.57000","-1.65613","4.08131"
"6.58800","-1.66071","4.09456"
"6.60600","-1.66526","4.10581"
"6.62400","-1.66975","4.11374"
"6.64200","-1.67427","4.11413"
"6.66000","-1.67888","4.11130"
"6.67800","-1.68351","4.12874"
"6.69600","-1.68810","4.14113"
"6.71400","-1.69267","4.14898"
"6.73200","-1.69729","4.15527"
"6.75000","-1.70192","4.16439"
"6.76800","-1.70649","4.17210"
"6.78600","-1.71102","4.17734"
"6.80400","-1.71557","4.17842"
"6.82200","-1.72015","4.17054"
"6.84000","-1.72469","4.16458"
"6.85800","-1.72922","4.16178"
"6.87600","-1.73383","4.16042"
"6.89400","-1.73848","4.16696"
"6.91200","-1.74308","4.17863"
"6.93000","-1.74759","4.19624"
"6.94800","-1.75212","4.21338"
"6.96600","-1.75666","4.23583"
"6.98400","-1.76120","4.25825"
"7.00200","-1.76570","4.26615"
"7.02000","-1.77022","4.27592"
"7.03800","-1.77483","4.28165"
"7.05600","-1.77950","4.29029"
"7.07400","-1.78412","4.29656"
"7.09200","-1.78871","4.30175"
"7.11000","-1.79331","4.31051"
"7.12800","-1.79790","4.32319"
"7.14600","-1.80245","4.34434"
"7.16400","-1.80698","4.36325"
"7.18200","-1.81153","4.38268"
"7.20000","-1.81611","4.39956"
"7.21800","-1.82070","4.41006"
"7.23600","-1.82530","4.41418"
"7.25400","-1.82989","4.40854"
"7.27200","-1.83449","4.40479"
"7.29000","-1.83904","4.39977"
"7.30800","-1.84353","4.39404"
"7.32600","-1.84804","4.39842"
"7.34400","-1.85260","4.40739"
"7.36200","-1.85717","4.41963"
"7.38000","-1.86172","4.43405"
"7.39800","-1.86629","4.45117"
"7.41600","-1.87091","4.46804"
"7.43400","-1.87552","4.47537"
"7.45200","-1.88010","4.47759"
"7.47000","-1.88468","4.47856"
"7.48800","-1.88925","4.48025"
"7.50600","-1.89381","4.48453"
"7.52400","-1.89833","4.49434"
"7.54200","-1.90289","4.51270"
"7.56000","-1.90753","4.52939"
"7.57800","-1.91220","4.54987"
"7.59600","-1.91683","4.56913"
"7.61400","-1.92141","4.58545"
"7.63200","-1.92600","4.60580"
"7.65000","-1.93057","4.61883"
"7.66800","-1.93507","4.62486"
"7.68600","-1.93955","4.62997"
"7.70400","-1.94409","4.63399"
"7.72200","-1.94868","4.62937"
"7.74000","-1.95327","4.61918"
"7.75800","-1.95783","4.61354"
"7.77600","-1.96242","4.61524"
"7.79400","-1.96704","4.62194"
"7.81200","-1.97162","4.63446"
"7.83000","-1.97612","4.65336"
"7.84800","-1.98065","4.67392"
"7.86600","-1.98523","4.69374"
"7.88400","-1.98982","4.70681"
"7.90200","-1.99436","4.71077"
"7.92000","-1.99894","4.71209"
"7.93800","-2.00359","4.71958"
"7.95600","-2.00826","4.72592"
"7.97400","-2.01283","4.73739"
"7.99200","-2.01738","4.75178"
"8.01000","-2.02194","4.76996"
"8.02800","-2.02649","4.78372"
"8.04600","-2.03100","4.79687"
"8.06400","-2.03551","4.82030"
"8.08200","-2.04010","4.83946"
"8.10000","-2.04475","4.85515"
"8.11800","-2.04937","4.86586"
"8.13600","-2.05392","4.87662"
"8.15400","-2.05848","4.87781"
"8.17200","-2.06306","4.90045"
"8.19000","-2.06760","4.91388"
"8.20800","-2.07207","4.91453"
"8.22600","-2.07660","4.91285"
"8.24400","-2.08121","4.92437"
"8.26200","-2.08584","4.94635"
"8.28000","-2.09044","4.97100"
"8.29800","-2.09505","4.99326"
"8.31600","-2.09969","5.01526"
"8.33400","-2.10433","5.02419"
"8.35200","-2.10887","5.02635"
"8.37000","-2.11335","5.02981"
"8.38800","-2.11787","5.03098"
"8.40600","-2.12243","5.03922"
"8.42400","-2.12697","5.05066"
"8.44200","-2.13153","5.06878"
"8.46000","-2.13616","5.08942"
"8.47800","-2.14083","5.10747"
"8.49600","-2.14544","5.13185"
"8.51400","-2.14996","5.14924"
"8.53200","-2.15447","5.16533"
"8.55000","-2.15898","5.16903"
"8.56800","-2.16350","5.16929"
"8.58600","-2.16800","5.16838"
"8.60400","-2.17256","5.16823"
"8.62200","-2.17721","5.17297"
"8.64000","-2.18190","5.17684"
"8.65800","-2.18653","5.18727"
"8.67600","-2.19113","5.20602"
"8.69400","-2.19571","5.22778"
"8.71200","-2.20027","5.24895"
"8.73000","-2.20477","5.26843"
"8.74800","-2.20928","5.28540"
"8.76600","-2.21384","5.29547"
"8.78400","-2.21846","5.30300"
"8.80200","-2.22307","5.31230"
"8.82000","-2.22767","5.31778"
"8.83800","-2.23228","5.32540"
"8.85600","-2.23687","5.33320"
"8.87400","-2.24141","5.34947"
"8.89200","-2.24591","5.36785"
"8.91000","-2.25043","5.38547"
"8.92800","-2.25497","5.40390"
"8.94600","-2.25951","5.41425"
"8.96400","-2.26405","5.42717"
"8.98200","-2.26865","5.43920"
"9.00000","-2.27328","5.44619"
"9.01800","-2.27789","5.44662"
"9.03600","-2.28246","5.43739"
"9.05400","-2.28702","5.43606"
"9.07200","-2.29158","5.43409"
"9.09000","-2.29611","5.44373"
"9.10800","-2.30062","5.46000"
"9.12600","-2.30518","5.47905"
"9.14400","-2.30982","5.50315"
"9.16200","-2.31450","5.52896"
"9.18000","-2.31914","5.55251"
"9.19800","-2.32372","5.56864"
"9.21600","-2.32832","5.57701"
"9.23400","-2.33290","5.58688"
"9.25200","-2.33739","5.59371"
"9.27000","-2.34187","5.60615"
"9.28800","-2.34642","5.61852"
"9.30600","-2.35101","5.63272"
"9.32400","-2.35560","5.65149"
"9.34200","-2.36016","5.67047"
"9.36000","-2.36476","5.69266"
"9.37800","-2.36937","5.70423"
"9.39600","-2.37393","5.70963"
"9.41400","-2.37844","5.71669"
"9.43200","-2.38296","5.72509"
"9.45000","-2.38754","5.73083"
"9.46800","-2.39212","5.73008"
"9.48600","-2.39666","5.73131"
"9.50400","-2.40127","5.73371"
"9.52200","-2.40595","5.73817"
"9.54000","-2.41062","5.74701"
"9.55800","-2.41518","5.76121"
"9.57600","-2.41973","5.78473"
"9.59400","-2.42427","5.80839"
"9.61200","-2.42881","5.83296"
"9.63000","-2.43331","5.85053"
"9.64800","-2.43785","5.86244"
"9.66600","-2.44246","5.86413"
"9.68400","-2.44712","5.85382"
"9.70200","-2.45173","5.85571"
"9.72000","-2.45628","5.86758"
"9.73800","-2.46083","5.88206"
"9.75600","-2.46539","5.90452"
"9.77400","-2.46990","5.93126"
"9.79200","-2.47437","5.95677"
"9.81000","-2.47890","5.97425"
"9.82800","-2.48352","6.00091"
"9.84600","-2.48817","6.02390"
"9.86400","-2.49277","6.03898"
"9.88200","-2.49739","6.05335"
"9.90000","-2.50204","6.05854"
"9.91800","-2.50666","6.06473"
"9.93600","-2.51118","6.06017"
"9.95400","-2.51567","6.05577"
"9.97200","-2.52021","6.05264"
"9.99000","-2.52478","6.05411"
"10.00800","-2.52932","6.06939"
"10.02600","-2.53388","6.09445"
"10.04400","-2.53853","6.13108"
"10.06200","-2.54320","6.16337"
"10.08000","-2.54780","6.18783"
"10.09800","-2.55231","6.20475"
"10.11600","-2.55683","6.21148"
"10.13400","-2.56135","6.21862"
"10.15200","-2.56586","6.22760"
"10.17000","-2.57037","6.23402"
"10.18800","-2.57493","6.24982"
"10.20600","-2.57958","6.27062"
"10.22400","-2.58425","6.29464"
"10.24200","-2.58886","6.31028"
"10.26000","-2.59345","6.32962"
"10.27800","-2.59804","6.34732"
"10.29600","-2.60260","6.35778"
"10.31400","-2.60711","6.36940"
"10.33200","-2.61163","6.37509"
"10.35000","-2.61620","6.37927"
"10.36800","-2.62081","6.38829"
"10.38600","-2.62541","6.39576"
"10.40400","-2.63000","6.40094"
"10.42200","-2.63460","6.41209"
"10.44000","-2.63920","6.43375"
"10.45800","-2.64374","6.45588"
"10.47600","-2.64823","6.47808"
"10.49400","-2.65274","6.50143"
"10.51200","-2.65731","6.52116"
"10.53000","-2.66186","6.53769"
"10.54800","-2.66643","6.54640"
"10.56600","-2.67102","6.55221"
"10.58400","-2.67564","6.55392"
"10.60200","-2.68022","6.56081"
"10.62000","-2.68479","6.58129"
"10.63800","-2.68936","6.59863"
"10.65600","-2.69393","6.61980"
"10.67400","-2.69848","6.64049"
"10.69200","-2.70299","6.66074"
"10.71000","-2.70754","6.67684"
"10.72800","-2.71218","6.68801"
"10.74600","-2.71685","6.70423"
"10.76400","-2.72146","6.71578"
"10.78200","-2.72605","6.72705"
"10.80000","-2.73064","6.73530"
"10.81800","-2.73521","6.73863"
"10.83600","-2.73971","6.74201"
"10.85400","-2.74420","6.74730"
"10.87200","-2.74876","6.76709"
"10.89000","-2.75335","6.78683"
"10.90800","-2.75792","6.81641"
"10.92600","-2.76247","6.84034"
"10.94400","-2.76708","6.85154"
"10.96200","-2.77172","6.86127"
"10.98000","-2.77630","6.87413"
"10.99800","-2.78079","6.89383"
"11.01600","-2.78531","6.90522"
"11.03400","-2.78989","6.91699"
"11.05200","-2.79447","6.93850"
"11.07000","-2.79904","6.95225"
"11.08800","-2.80365","6.96860"
"11.10600","-2.80833","6.99641"
"11.12400","-2.81297","7.02016"
"11.14200","-2.81752","7.03701"
"11.16000","-2.82206","7.04994"
"11.17800","-2.82662","7.06758"
"11.19600","-2.83118","7.07857"
"11.21400","-2.83568","7.08389"
"11.23200","-2.84020","7.08544"
"11.25000","-2.84479","7.08889"
"11.26800","-2.84943","7.09735"
"11.28600","-2.85401","7.10799"
"11.30400","-2.85856","7.12793"
"11.32200","-2.86313","7.14640"
"11.34000","-2.86772","7.16418"
"11.35800","-2.87224","7.18321"
"11.37600","-2.87672","7.20677"
"11.39400","-2.88127","7.23649"
"11.41200","-2.88588","7.25228"
"11.43000","-2.89051","7.26665"
"11.44800","-2.89510","7.27975"
"11.46600","-2.89972","7.29615"
"11.48400","-2.90437","7.31455"
"11.50200","-2.90900","7.32690"
"11.52000","-2.91352","7.35516"
"11.53800","-2.91803","7.38673"
"11.55600","-2.92259","7.40677"
"11.57400","-2.92717","7.42409"
"11.59200","-2.93169","7.44532"
"11.61000","-2.93625","7.46453"
"11.62800","-2.94087","7.47187"
"11.64600","-2.94552","7.48459"
"11.66400","-2.95008","7.49428"
"11.68200","-2.95459","7.50288"
"11.70000","-2.95911","7.51937"
"11.71800","-2.96363","7.53811"
"11.73600","-2.96814","7.56071"
"11.75400","-2.97265","7.57445"
"11.77200","-2.97722","7.59205"
"11.79000","-2.98189","7.61612"
"11.80800","-2.98657","7.64080"
"11.82600","-2.99119","7.66539"
"11.84400","-2.99578","7.68095"
"11.86200","-3.00037","7.69320"
"11.88000","-3.00492","7.70363"
"11.89800","-3.00943","7.70971"
"11.91600","-3.01394","7.72434"
"11.93400","-3.01850","7.74562"
"11.95200","-3.02313","7.77165"
"11.97000","-3.02775","7.79229"
"11.98800","-3.03235","7.81182"
"12.00600","-3.03694","7.83962"
"12.02400","-3.04153","7.87112"
"12.04200","-3.04607","7.90701"
"12.06000","-3.05058","7.93844"
"12.07800","-3.05510","7.95708"
"12.09600","-3.05965","7.95970"
"12.11400","-3.06419","7.95729"
"12.13200","-3.06874","7.96116"
"12.15000","-3.07334","7.96676"
"12.16800","-3.07797","7.97579"
"12.18600","-3.08255","7.99272"
"12.20400","-3.08710","8.01408"
"12.22200","-3.09167","8.03207"
"12.24000","-3.09624","8.04945"
"12.25800","-3.10079","8.07946"
"12.27600","-3.10532","8.10246"
"12.29400","-3.10990","8.11859"
"12.31200","-3.11455","8.13484"
"12.33000","-3.11921","8.14898"
"12.34800","-3.12381","8.17038"
"12.36600","-3.12839","8.19298"
"12.38400","-3.13299","8.22692"
"12.40200","-3.13755","8.25304"
"12.42000","-3.14205","8.27331"
"12.43800","-3.14656","8.29115"
"12.45600","-3.15112","8.30623"
"12.47400","-3.15569","8.33142"
"12.49200","-3.16025","8.36341"
"12.51000","-3.16481","8.38916"
"12.52800","-3.16942","8.40576"
"12.54600","-3.17403","8.41475"
"12.56400","-3.17858","8.42821"
"12.58200","-3.18308","8.44027"
"12.60000","-3.18762","8.45291"
"12.61800","-3.19222","8.46244"
"12.63600","-3.19680","8.47727"
"12.65400","-3.20136","8.50678"
"12.67200","-3.20598","8.53525"
"12.69000","-3.21066","8.56559"
"12.70800","-3.21529","8.58868"
"12.72600","-3.21984","8.61149"
"12.74400","-3.22438","8.63489"
"12.76200","-3.22894","8.65293"
"12.78000","-3.23349","8.67238"
"12.79800","-3.23800","8.69354"
"12.81600","-3.24252","8.71880"
"12.83400","-3.24712","8.74606"
"12.85200","-3.25177","8.77585"
"12.87000","-3.25636","8.80900"
"12.88800","-3.26092","8.82830"
"12.90600","-3.26551","8.85225"
"12.92400","-3.27009","8.87548"
"12.94200","-3.27460","8.89574"
"12.96000","-3.27907","8.91318"
"12.97800","-3.28361","8.92658"
"12.99600","-3.28823","8.94314"
"13.01400","-3.29286","8.94829"
"13.03200","-3.29745","8.96039"
"13.05000","-3.30206","8.98420"
"13.06800","-3.30671","9.00892"
"13.08600","-3.31133","9.03951"
"13.10400","-3.31585","9.06788"
"13.12200","-3.32037","9.10456"
"13.14000","-3.32492","9.13568"
"13.15800","-3.32949","9.16199"
"13.17600","-3.33403","9.18034"
"13.19400","-3.33861","9.18852"
"13.21200","-3.34326","9.20250"
"13.23000","-3.34790","9.21579"
"13.24800","-3.35244","9.23187"
"13.26600","-3.35695","9.24913"
"13.28400","-3.36147","9.26654"
"13.30200","-3.36602","9.28350"
"13.32000","-3.37053","9.29829"
"13.33800","-3.37503","9.32461"
"13.35600","-3.37959","9.34907"
"13.37400","-3.38424","9.37311"
"13.39200","-3.38889","9.40157"
"13.41000","-3.39349","9.43000"
"13.42800","-3.39809","9.45112"
"13.44600","-3.40270","9.46093"
"13.46400","-3.40725","9.47687"
"13.48200","-3.41177","9.50228"
"13.50000","-3.41631","9.52655"
"13.51800","-3.42088","9.55207"
"13.53600","-3.42548","9.57526"
"13.55400","-3.43006","9.60830"
"13.57200","-3.43466","9.64083"
"13.59000","-3.43927","9.66986"
"13.60800","-3.44387","9.69296"
"13.62600","-3.44840","9.70719"
"13.64400","-3.45291","9.72979"
"13.66200","-3.45744","9.75029"
"13.68000","-3.46198","9.77615"
"13.69800","-3.46649","9.80545"
"13.71600","-3.47103","9.83754"
"13.73400","-3.47563","9.87868"
"13.75200","-3.48026","9.91468"
"13.77000","-3.48484","9.94821"
"13.78800","-3.48941","9.97792"
"13.80600","-3.49399","10.00234"
"13.82400","-3.49858","10.02527"
"13.84200","-3.50312","10.04960"
"13.86000","-3.50764","10.07089"
"13.87800","-3.51221","10.08607"
"13.89600","-3.51687","10.10266"
"13.91400","-3.52153","10.12263"
"13.93200","-3.52613","10.14662"
"13.95000","-3.53071","10.17791"
"13.96800","-3.53532","10.21145"
"13.98600","-3.53988","10.24854"
"14.00400","-3.54436","10.27791"
"14.02200","-3.54887","10.30764"
"14.04000","-3.55344","10.33490"
"14.05800","-3.55802","10.35381"
"14.07600","-3.56258","10.38226"
"14.09400","-3.56715","10.41139"
"14.11200","-3.57176","10.44280"
"14.13000","-3.57636","10.47221"
"14.14800","-3.58090","10.50439"
"14.16600","-3.58542","10.54657"
"14.18400","-3.58997","10.58296"
"14.20200","-3.59456","10.62171"
"14.22000","-3.59912","10.65145"
"14.23800","-3.60368","10.67567"
"14.25600","-3.60832","10.70659"
"14.27400","-3.61301","10.72870"
"14.29200","-3.61764","10.74856"
"14.31000","-3.62219","10.76893"
"14.32800","-3.62673","10.79370"
"14.34600","-3.63130","10.82174"
"14.36400","-3.63585","10.84753"
"14.38200","-3.64033","10.88748"
"14.40000","-3.64485","10.92741"
"14.41800","-3.64945","10.95998"
"14.43600","-3.65410","10.99720"
"14.45400","-3.65870","11.03090"
"14.47200","-3.66327","11.06357"
"14.49000","-3.66786","11.08711"
"14.50800","-3.67243","11.11135"
"14.52600","-3.67692","11.13129"
"14.54400","-3.68140","11.15143"
"14.56200","-3.68596","11.19145"
"14.58000","-3.69058","11.23269"
"14.59800","-3.69519","11.27706"
"14.61600","-3.69977","11.31419"
"14.63400","-3.70439","11.35396"
"14.65200","-3.70904","11.38888"
"14.67000","-3.71365","11.42041"
"14.68800","-3.71816","11.45395"
"14.70600","-3.72267","11.48142"
"14.72400","-3.72723","11.50713"
"14.74200","-3.73179","11.52722"
"14.76000","-3.73633","11.54635"
"14.77800","-3.74092","11.56951"
"14.79600","-3.74557","11.59148"
"14.81400","-3.75022","11.62816"
"14.83200","-3.75477","11.66232"
"14.85000","-3.75930","11.70201"
"14.86800","-3.76383","11.75399"
"14.88600","-3.76837","11.79967"
"14.90400","-3.77286","11.83020"
"14.92200","-3.77737","11.85322"
"14.94000","-3.78194","11.88749"
"14.95800","-3.78661","11.91845"
"14.97600","-3.79126","11.95003"
"14.99400","-3.79585","11.98598"
"15.01200","-3.80044","12.01816"
"15.03000","-3.80504","12.05665"
"15.04800","-3.80958","12.09569"
"15.06600","-3.81410","12.13815"
"15.08400","-3.81863","12.17378"
"15.10200","-3.82321","12.21000"
"15.12000","-3.82781","12.24047"
"15.13800","-3.83240","12.25778"
"15.15600","-3.83699","12.29217"
"15.17400","-3.84159","12.33004"
"15.19200","-3.84618","12.35835"
"15.21000","-3.85072","12.38574"
"15.22800","-3.85524","12.41875"
"15.24600","-3.85978","12.46082"
"15.26400","-3.86433","12.49819"
"15.28200","-3.86885","12.54430"
"15.30000","-3.87341","12.59822"
"15.31800","-3.87802","12.64021"
"15.33600","-3.88265","12.68137"
"15.35400","-3.88724","12.71463"
"15.37200","-3.89182","12.74703"
"15.39000","-3.89640","12.77600"
"15.40800","-3.90098","12.80333"
"15.42600","-3.90551","12.83291"
"15.44400","-3.91004","12.85001"
"15.46200","-3.91462","12.88361"
"15.48000","-3.91926","12.93248"
"15.49800","-3.92389","12.98961"
"15.51600","-3.92848","13.04311"
"15.53400","-3.93306","13.08680"
"15.55200","-3.93766","13.12837"
"15.57000","-3.94221","13.15389"
"15.58800","-3.94670","13.18770"
"15.60600","-3.95121","13.23021"
"15.62400","-3.95578","13.26863"
"15.64200","-3.96037","13.30436"
"15.66000","-3.96493","13.33717"
"15.67800","-3.96951","13.37594"
"15.69600","-3.97414","13.41348"
"15.71400","-3.97874","13.46263"
"15.73200","-3.98327","13.50861"
"15.75000","-3.98779","13.53834"
"15.76800","-3.99235","13.57887"
"15.78600","-3.99693","13.62032"
"15.80400","-4.00148","13.66425"
"15.82200","-4.00601","13.70693"
"15.84000","-4.01064","13.74444"
"15.85800","-4.01532","13.78848"
"15.87600","-4.01994","13.82493"
"15.89400","-4.02450","13.87183"
"15.91200","-4.02906","13.92038"
"15.93000","-4.03363","13.96861"
"15.94800","-4.03817","14.02017"
"15.96600","-4.04266","14.06447"
"15.98400","-4.04718","14.10830"
"16.00200","-4.05179","14.14102"
"16.02000","-4.05643","14.18320"
"16.03800","-4.06100","14.22462"
"16.05600","-4.06556","14.25296"
"16.07400","-4.07014","14.28852"
"16.09200","-4.07471","14.33234"
"16.11000","-4.07921","14.38123"
"16.12800","-4.08372","14.42457"
"16.14600","-4.08830","14.46582"
"16.16400","-4.09293","14.50558"
"16.18200","-4.09752","14.54420"
"16.20000","-4.10211","14.59732"
"16.21800","-4.10675","14.64811"
"16.23600","-4.11140","14.69484"
"16.25400","-4.11600","14.74678"
"16.27200","-4.12050","14.79417"
"16.29000","-4.12502","14.84703"
"16.30800","-4.12958","14.88324"
"16.32600","-4.13412","14.92776"
"16.34400","-4.13864","14.97754"
"16.36200","-4.14324","15.02519"
"16.38000","-4.14791","15.08484"
"16.39800","-4.15255","15.13880"
"16.41600","-4.15709","15.19653"
"16.43400","-4.16161","15.24590"
"16.45200","-4.16616","15.29888"
"16.47000","-4.17070","15.34317"
"16.48800","-4.17519","15.37436"
"16.50600","-4.17970","15.41048"
"16.52400","-4.18428","15.43901"
"16.54200","-4.18894","15.47551"
"16.56000","-4.19358","15.52481"
"16.57800","-4.19818","15.58235"
"16.59600","-4.20277","15.64091"
"16.61400","-4.20737","15.69591"
"16.63200","-4.21193","15.75313"
"16.65000","-4.21645","15.80332"
"16.66800","-4.22099","15.85273"
"16.68600","-4.22555","15.90582"
"16.70400","-4.23014","15.95269"
"16.72200","-4.23472","16.00314"
"16.74000","-4.23933","16.05553"
"16.75800","-4.24394","16.12272"
"16.77600","-4.24855","16.18616"
"16.79400","-4.25309","16.23356"
"16.81200","-4.25760","16.28694"
"16.83000","-4.26213","16.33092"
"16.84800","-4.26666","16.38110"
"16.86600","-4.27118","16.42933"
"16.88400","-4.27574","16.48190"
"16.90200","-4.28035","16.52944"
"16.92000","-4.28499","16.57438"
"16.93800","-4.28958","16.63340"
"16.95600","-4.29416","16.68270"
"16.97400","-4.29875","16.73389"
"16.99200","-4.30333","16.78496"
"17.01000","-4.30784","16.83634"
"17.02800","-4.31236","16.88972"
"17.04600","-4.31694","16.95122"
"17.06400","-4.32159","17.02598"
"17.08200","-4.32623","17.08862"
"17.10000","-4.33082","17.13830"
"17.11800","-4.33542","17.19221"
"17.13600","-4.34002","17.23652"
"17.15400","-4.34457","17.28885"
"17.17200","-4.34906","17.34550"
"17.19000","-4.35357","17.41183"
"17.20800","-4.35812","17.47544"
"17.22600","-4.36269","17.53231"
"17.24400","-4.36724","17.59561"
"17.26200","-4.37183","17.64243"
"17.28000","-4.37646","17.70137"
"17.29800","-4.38107","17.76198"
"17.31600","-4.38559","17.81914"
"17.33400","-4.39010","17.88170"
"17.35200","-4.39465","17.94372"
"17.37000","-4.39925","18.01074"
"17.38800","-4.40381","18.06129"
"17.40600","-4.40838","18.10896"
"17.42400","-4.41302","18.16475"
"17.44200","-4.41770","18.22590"
"17.46000","-4.42230","18.29422"
"17.47800","-4.42685","18.36153"
"17.49600","-4.43141","18.43236"
"17.51400","-4.43597","18.49173"
"17.53200","-4.44049","18.56261"
"17.55000","-4.44497","18.63324"
"17.56800","-4.44951","18.67858"
"17.58600","-4.45412","18.73867"
"17.60400","-4.45877","18.80423"
"17.62200","-4.46337","18.86645"
"17.64000","-4.46797","18.93211"
"17.65800","-4.47256","18.99759"
"17.67600","-4.47711","19.06533"
"17.69400","-4.48157","19.12695"
"17.71200","-4.48605","19.19324"
"17.73000","-4.49061","19.25893"
"17.74800","-4.49524","19.32208"
"17.76600","-4.49985","19.39668"
"17.78400","-4.50445","19.46593"
"17.80200","-4.50909","19.54177"
"17.82000","-4.51376","19.60032"
"17.83800","-4.51834","19.66694"
"17.85600","-4.52283","19.73542"
"17.87400","-4.52735","19.79562"
"17.89200","-4.53189","19.86104"
"17.91000","-4.53643","19.93048"
"17.92800","-4.54096","20.00852"
"17.94600","-4.54557","20.08299"
"17.96400","-4.55024","20.16132"
"17.98200","-4.55488","20.23333"
"18.00000","-4.55944","20.28343"
"18.01800","-4.56398","20.34047"
"18.03600","-4.56851","20.40819"
"18.05400","-4.57302","20.48225"
"18.07200","-4.57750","20.56590"
"18.09000","-4.58200","20.64500"
"18.10800","-4.58659","20.73082"
"18.12600","-4.59125","20.81754"
"18.14400","-4.59589","20.91091"
"18.16200","-4.60049","20.98738"
"18.18000","-4.60509","21.05317"
"18.19800","-4.60970","21.12111"
"18.21600","-4.61425","21.17708"
"18.23400","-4.61876","21.24887"
"18.25200","-4.62329","21.31778"
"18.27000","-4.62787","21.38785"
"18.28800","-4.63246","21.45897"
"18.30600","-4.63704","21.52106"
"18.32400","-4.64165","21.60495"
"18.34200","-4.64627","21.68067"
"18.36000","-4.65087","21.74805"
"18.37800","-4.65541","21.81892"
"18.39600","-4.65992","21.90338"
"18.41400","-4.66444","21.99259"
"18.43200","-4.66897","22.07662"
"18.45000","-4.67349","22.16687"
"18.46800","-4.67805","22.25376"
"18.48600","-4.68268","22.33435"
"18.50400","-4.68731","22.42747"
"18.52200","-4.69191","22.51606"
"18.54000","-4.69649","22.60919"
"18.55800","-4.70107","22.67658"
"18.57600","-4.70564","22.74293"
"18.59400","-4.71016","22.81799"
"18.61200","-4.71468","22.90633"
"18.63000","-4.71928","23.00760"
"18.64800","-4.72394","23.08462"
"18.66600","-4.72857","23.15796"
"18.68400","-4.73316","23.21770"
"18.70200","-4.73774","23.29242"
"18.72000","-4.74234","23.37582"
"18.73800","-4.74687","23.45194"
"18.75600","-4.75135","23.54715"
"18.77400","-4.75588","23.64725"
"18.79200","-4.76044","23.74588"
"18.81000","-4.76501","23.84559"
"18.82800","-4.76956","23.93986"
"18.84600","-4.77415","24.02373"
"18.86400","-4.77879","24.10301"
"18.88200","-4.78339","24.18875"
"18.90000","-4.78791","24.27359"
"18.91800","-4.79243","24.36675"
"18.93600","-4.79700","24.47691"
"18.95400","-4.80158","24.56769"
"18.97200","-4.80612","24.64146"
"18.99000","-4.81068","24.72088"
"19.00800","-4.81532","24.83253"
"19.02600","-4.81999","24.93606"
"19.04400","-4.82459","25.02972"
"19.06200","-4.82916","25.12151"
"19.08000","-4.83374","25.20301"
"19.09800","-4.83832","25.29203"
"19.11600","-4.84285","25.38785"
"19.13400","-4.84732","25.48831"
"19.15200","-4.85186","25.58427"
"19.17000","-4.85648","25.66828"
"19.18800","-4.86111","25.76310"
"19.20600","-4.86568","25.84371"
"19.22400","-4.87026","25.94892"
"19.24200","-4.87486","26.06529"
"19.26000","-4.87942","26.17123"
"19.27800","-4.88390","26.24781"
"19.29600","-4.88841","26.34426"
"19.31400","-4.89299","26.46244"
"19.33200","-4.89761","26.56946"
"19.35000","-4.90218","26.67057"
"19.36800","-4.90676","26.77643"
"19.38600","-4.91139","26.86853"
"19.40400","-4.91605","26.96505"
"19.42200","-4.92064","27.06329"
"19.44000","-4.92516","27.17254"
"19.45800","-4.92970","27.26507"
"19.47600","-4.93427","27.34283"
"19.49400","-4.93881","27.43852"
"19.51200","-4.94334","27.53597"
"19.53000","-4.94795","27.64666"
"19.54800","-4.95261","27.76533"
"19.56600","-4.95722","27.86981"
"19.58400","-4.96176","27.97603"
"19.60200","-4.96629","28.08267"
"19.62000","-4.97084","28.20031"
"19.63800","-4.97537","28.30389"
"19.65600","-4.97985","28.40150"
"19.67400","-4.98438","28.50918"
"19.69200","-4.98899","28.62623"
"19.71000","-4.99365","28.74152"
"19.72800","-4.99828","28.84093"
"19.74600","-5.00288","28.95184"
"19.76400","-5.00748","29.05949"
"19.78200","-5.01206","29.16324"
"19.80000","-5.01659","29.26787"
"19.81800","-5.02110","29.36194"
"19.83600","-5.02564","29.47477"
"19.85400","-5.03021","29.60362"
"19.87200","-5.03479","29.72752"
"19.89000","-5.03937","29.85088"
"19.90800","-5.04398","29.96125"
"19.92600","-5.04860","30.06824"
"19.94400","-5.05320","30.16607"
"19.96200","-5.05773","30.27985"
"19.98000","-5.06225","30.39612"
"19.99800","-5.06680","30.48939"
"20.01600","-5.07133","30.58304"
"20.03400","-5.07585","30.67703"
"20.05200","-5.08041","30.79074"
"20.07000","-5.08501","30.91324"
"20.08800","-5.08963","31.04834"
"20.10600","-5.09421","31.16313"
"20.12400","-5.09881","31.24403"
"20.14200","-5.10342","31.35107"
"20.16000","-5.10799","31.46463"
"20.17800","-5.11251","31.59133"
"20.19600","-5.11704","31.71707"
"20.21400","-5.12165","31.84042"
"20.23200","-5.12629","31.95303"
"20.25000","-5.13090","32.05183"
"20.26800","-5.13548","32.16512"
"20.28600","-5.14008","32.27491"
"20.30400","-5.14468","32.38717"
"20.32200","-5.14921","32.50374"
"20.34000","-5.15371","32.60677"
"20.35800","-5.15825","32.71135"
"20.37600","-5.16282","32.80640"
"20.39400","-5.16737","32.92270"
"20.41200","-5.17190","33.04231"
"20.43000","-5.17649","33.14949"
"20.44800","-5.18111","33.27309"
"20.46600","-5.18571","33.37849"
"20.48400","-5.19023","33.48561"
"20.50200","-5.19477","33.59588"
"20.52000","-5.19936","33.72603"
"20.53800","-5.20396","33.87158"
"20.55600","-5.20849","33.99824"
"20.57400","-5.21306","34.12153"
"20.59200","-5.21770","34.22972"
"20.61000","-5.22236","34.33522"
"20.62800","-5.22693","34.43683"
"20.64600","-5.23148","34.52900"
"20.66400","-5.23605","34.63810"
"20.68200","-5.24063","34.75026"
"20.70000","-5.24516","34.89724"
"20.71800","-5.24966","35.03903"
"20.73600","-5.25424","35.17139"
"20.75400","-5.25887","35.30322"
"20.77200","-5.26347","35.41791"
"20.79000","-5.26802","35.53444"
"20.80800","-5.27258","35.64536"
"20.82600","-5.27716","35.77044"
"20.84400","-5.28171","35.88384"
"20.86200","-5.28619","35.98658"
"20.88000","-5.29072","36.10171"
"20.89800","-5.29533","36.22512"
"20.91600","-5.29997","36.34501"
"20.93400","-5.30455","36.45469"
"20.95200","-5.30914","36.56701"
"20.97000","-5.31376","36.69951"
"20.98800","-5.31841","36.83747"
"21.00600","-5.32297","36.98050"
"21.02400","-5.32748","37.10479"
"21.04200","-5.33204","37.23604"
"21.06000","-5.33661","37.37850"
"21.07800","-5.34115","37.50339"
"21.09600","-5.34568","37.60671"
"21.11400","-5.35028","37.71003"
"21.13200","-5.35492","37.84913"
"21.15000","-5.35952","37.98196"
"21.16800","-5.36406","38.12467"
"21.18600","-5.36861","38.28138"
"21.20400","-5.37316","38.40520"
"21.22200","-5.37770","38.51887"
"21.24000","-5.38219","38.62125"
"21.25800","-5.38672","38.71600"
"21.27600","-5.39133","38.81650"
"21.29400","-5.39599","38.93354"
"21.31200","-5.40061","39.06034"
"21.33000","-5.40519","39.17258"
"21.34800","-5.40980","39.30370"
"21.36600","-5.41437","39.44963"
"21.38400","-5.41890","39.60344"
"21.40200","-5.42343","39.75489"
"21.42000","-5.42798","39.86501"
"21.43800","-5.43258","39.98925"
"21.45600","-5.43717","40.11467"
"21.47400","-5.44176","40.25284"
"21.49200","-5.44636","40.39946"
"21.51000","-5.45095","40.52631"
"21.52800","-5.45551","40.64803"
"21.54600","-5.46005","40.75996"
"21.56400","-5.46456","40.89653"
"21.58200","-5.46911","41.02480"
"21.60000","-5.47365","41.14189"
"21.61800","-5.47818","41.27068"
"21.63600","-5.48275","41.39044"
"21.65400","-5.48736","41.53025"
"21.67200","-5.49197","41.65616"
"21.69000","-5.49654","41.77728"
"21.70800","-5.50113","41.89452"
"21.72600","-5.50573","42.02591"
"21.74400","-5.51029","42.15120"
"21.76200","-5.51480","42.24722"
"21.78000","-5.51936","42.37780"
"21.79800","-5.52398","42.52924"
"21.81600","-5.52863","42.66936"
"21.83400","-5.53323","42.81155"
"21.85200","-5.53781","42.95314"
"21.87000","-5.54242","43.10126"
"21.88800","-5.54701","43.24442"
"21.90600","-5.55152","43.37162"
"21.92400","-5.55601","43.48565"
"21.94200","-5.56055","43.58818"
"21.96000","-5.56514","43.71067"
"21.97800","-5.56970","43.82404"
"21.99600","-5.57425","43.92512"
"22.01400","-5.57883","44.05120"
"22.03200","-5.58345","44.19971"
"22.05000","-5.58803","44.32478"
"22.06800","-5.59254","44.40660"
"22.08600","-5.59709","44.51467"
"22.10400","-5.60168","44.65119"
"22.12200","-5.60626","44.78000"
"22.14000","-5.61081","44.89300"
"22.15800","-5.61540","45.01359"
"22.17600","-5.62007","45.15433"
"22.19400","-5.62474","45.30075"
"22.21200","-5.62931","45.45446"
"22.23000","-5.63387","45.60741"
"22.24800","-5.63842","45.75286"
"22.26600","-5.64297","45.88514"
"22.28400","-5.64747","45.98755"
"22.30200","-5.65198","46.09065"
"22.32000","-5.65655","46.20018"
"22.33800","-5.66119","46.33334"
"22.35600","-5.66581","46.45576"
"22.37400","-5.67038","46.53119"
"22.39200","-5.67496","46.62520"
"22.41000","-5.67954","46.72230"
"22.42800","-5.68407","46.84914"
"22.44600","-5.68853","46.99719"
"22.46400","-5.69305","47.15960"
"22.48200","-5.69765","47.31585"
"22.50000","-5.70227","47.45738"
"22.51800","-5.70686","47.61663"
"22.53600","-5.71146","47.76196"
"22.55400","-5.71611","47.90106"
"22.57200","-5.72076","48.04544"
"22.59000","-5.72530","48.16448"
"22.60800","-5.72982","48.26621"
"22.62600","-5.73436","48.36724"
"22.64400","-5.73893","48.47495"
"22.66200","-5.74346","48.59092"
"22.68000","-5.74802","48.71248"
"22.69800","-5.75263","48.81847"
"22.71600","-5.75729","48.90404"
"22.73400","-5.76187","49.01213"
"22.75200","-5.76640","49.15314"
"22.77000","-5.77095","49.31485"
"22.78800","-5.77549","49.46000"
"22.80600","-5.78001","49.58898"
"22.82400","-5.78449","49.72078"
"22.84200","-5.78903","49.84852"
"22.86000","-5.79365","49.99116"
"22.87800","-5.79831","50.15055"
"22.89600","-5.80293","50.28171"
"22.91400","-5.80753","50.41467"
"22.93200","-5.81214","50.53329"
"22.95000","-5.81671","50.64505"
"22.96800","-5.82123","50.72694"
"22.98600","-5.82575","50.80856"
"23.00400","-5.83030","50.91607"
"23.02200","-5.83492","51.00785"
"23.04000","-5.83951","51.14478"
"23.05800","-5.84409","51.25583"
"23.07600","-5.84868","51.36744"
"23.09400","-5.85327","51.50615"
"23.11200","-5.85781","51.65644"
"23.13000","-5.86232","51.80943"
"23.14800","-5.86683","51.93815"
"23.16600","-5.87139","52.07636"
"23.18400","-5.87594","52.20969"
"23.20200","-5.88049","52.34099"
"23.22000","-5.88508","52.48428"
"23.23800","-5.88970","52.60791"
"23.25600","-5.89431","52.72217"
"23.27400","-5.89888","52.82307"
"23.29200","-5.90346","52.93439"
"23.31000","-5.90804","53.04601"
"23.32800","-5.91259","53.15654"
"23.34600","-5.91711","53.26947"
"23.36400","-5.92167","53.37359"
"23.38200","-5.92631","53.48007"
"23.40000","-5.93097","53.56625"
"23.41800","-5.93558","53.66003"
"23.43600","-5.94015","53.76104"
"23.45400","-5.94475","53.86352"
"23.47200","-5.94933","53.99183"
"23.49000","-5.95384","54.12173"
"23.50800","-5.95833","54.26672"
"23.52600","-5.96288","54.43489"
"23.54400","-5.96748","54.61135"
"23.56200","-5.97205","54.76691"
"23.58000","-5.97660","54.87736"
"23.59800","-5.98119","54.98181"
"23.61600","-5.98581","55.08603"
"23.63400","-5.99037","55.19053"
"23.65200","-5.99488","55.31090"
"23.67000","-5.99943","55.42205"
"23.68800","-6.00403","55.51618"
"23.70600","-6.00862","55.56628"
"23.72400","-6.01317","55.64552"
"23.74200","-6.01776","55.78460"
"23.76000","-6.02241","55.92895"
"23.77800","-6.02705","56.05668"
"23.79600","-6.03162","56.15609"
"23.81400","-6.03617","56.28356"
"23.83200","-6.04073","56.44286"
"23.85000","-6.04528","56.61754"
"23.86800","-6.04980","56.76844"
"23.88600","-6.05433","56.87197"
"23.90400","-6.05894","56.96496"
"23.92200","-6.06358","57.04338"
"23.94000","-6.06816","57.15328"
"23.95800","-6.07271","57.28788"
"23.97600","-6.07727","57.42712"
"23.99400","-6.08184","57.56656"
"24.01200","-6.08636","57.67209"
"24.03000","-6.09085","57.75378"
"24.04800","-6.09541","57.82203"
"24.06600","-6.10004","57.91677"
"24.08400","-6.10466","58.04385"
"24.10200","-6.10922","58.15917"
"24.12000","-6.11381","58.28951"
"24.13800","-6.11846","58.46310"
"24.15600","-6.12310","58.66826"
"24.17400","-6.12763","58.84368"
"24.19200","-6.13213","58.97575"
"24.21000","-6.13669","59.10304"
"24.22800","-6.14126","59.22243"
"24.24600","-6.14580","59.32449"
"24.26400","-6.15036","59.41461"
"24.28200","-6.15499","59.47953"
"24.30000","-6.15965","59.58280"
"24.31800","-6.16422","59.70168"
"24.33600","-6.16875","59.79534"
"24.35400","-6.17328","59.82891"
"24.37200","-6.17781","59.88274"
"24.39000","-6.18231","59.98948"
"24.40800","-6.18682","60.09530"
"24.42600","-6.19139","60.20493"
"24.44400","-6.19604","60.35575"
"24.46200","-6.20069","60.57098"
"24.48000","-6.20529","60.79076"
"24.49800","-6.20987","60.97724"
"24.51600","-6.21445","61.14462"
"24.53400","-6.21901","61.28955"
"24.55200","-6.22353","61.41091"
"24.57000","-6.22807","61.50748"
"24.58800","-6.23265","61.58888"
"24.60600","-6.23727","61.65583"
"24.62400","-6.24187","61.76037"
"24.64200","-6.24647","61.88865"
"24.66000","-6.25106","61.95833"
"24.67800","-6.25565","61.99604"
"24.69600","-6.26019","62.03217"
"24.71400","-6.26471","62.04816"
"24.73200","-6.26923","62.10312"
"24.75000","-6.27379","62.20476"
"24.76800","-6.27833","62.35964"
"24.78600","-6.28286","62.56480"
"24.80400","-6.28743","62.78831"
"24.82200","-6.29205","63.01267"
"24.84000","-6.29666","63.22019"
"24.85800","-6.30123","63.39247"
"24.87600","-6.30582","63.52630"
"24.89400","-6.31040","63.65823"
"24.91200","-6.31495","63.73088"
"24.93000","-6.31945","63.74046"
"24.94800","-6.32402","63.77220"
"24.96600","-6.32867","63.80288"
"24.98400","-6.33333","63.85392"
"25.00200","-6.33793","63.90962"
"25.02000","-6.34251","63.94353"
"25.03800","-6.34711","63.95636"
"25.05600","-6.35167","63.94125"
"25.07400","-6.35616","63.94505"
"25.09200","-6.36066","63.89489"
"25.11000","-6.36521","63.66708"
"25.12800","-6.36980","62.99739"
"25.14600","-6.37436","61.70223"
"25.16400","-6.37893","59.98195"
"25.18200","-6.38353","58.23827"
"25.20000","-6.38816","56.64710"
"25.21800","-6.39272","54.99419"
"25.23600","-6.39721","53.44289"
"25.25400","-6.40173","52.05133"
"25.27200","-6.40632","50.60265"
"25.29000","-6.41089","48.91335"
"25.30800","-6.41545","46.92691"
"25.32600","-6.42006","44.42135"
"25.34400","-6.42473","41.24571"
"25.36200","-6.42938","37.83461"
"25.38000","-6.43396","34.42000"
"25.39800","-6.43851","31.03440"
"25.41600","-6.44306","28.03954"
"25.43400","-6.44761","24.99639"
"25.45200","-6.45211","21.21996"
"25.47000","-6.45664","16.98044"
"25.48800","-6.46125","12.98214"
"25.50600","-6.46589","9.33376"
"25.52400","-6.47048","5.99195"
"25.54200","-6.47503","2.85071"
"25.56000","-6.47960","0.63045"
"25.57800","-6.48418","-0.18683"
"26.13600","-6.49230","-0.00718"
"27.93600","-6.49235","-0.00686"
"29.73600","-6.49235","-0.00622"
"31.53600","-6.49235","-0.00564"
"33.33600","-6.49235","-0.00551"
"35.13600","-6.49235","-0.00463"
"35.72200","-6.47495","3.75381"
"35.74300","-6.46874","9.27320"
"35.76100","-6.46345","14.51508"
"35.77900","-6.45843","19.59611"
"35.79700","-6.45364","24.43805"
"35.81500","-6.44897","29.15409"
"35.83300","-6.44440","33.74892"
"35.86200","-6.43706","40.95908"
"35.89800","-6.42777","49.71805"
"35.93400","-6.41857","56.56832"
"35.99400","-6.40329","61.97837"
"36.05700","-6.38742","67.09778"
"36.46900","-6.28273","67.82126"
"37.08300","-6.12678","63.26646"
"37.72900","-5.96270","58.68520"
"38.38300","-5.79656","54.14009"
"39.02300","-5.63405","49.55982"
"39.66400","-5.47115","44.99903"
"40.31000","-5.30709","40.42093"
"40.98100","-5.13673","35.86188"
"41.67500","-4.96052","31.30568"
"42.45900","-4.76123","26.75234"
"43.38900","-4.52503","22.22370"
"44.64800","-4.20528","17.69270"
"46.34700","-3.77365","13.45907"
"48.14700","-3.31650","10.60953"
"49.94700","-2.85944","8.60658"
"51.74700","-2.40208","7.11555"
"53.54700","-1.94489","5.98866"
"55.34700","-1.48763","4.97852"
"57.14700","-1.03062","4.32454"
"58.94700","-0.57327","4.00495"
"60.74700","-0.11602","3.55713"
"61.20500","0.00025","3.66985"