File: Specimen_RawData_4_SN1A1008126.csv
Time,Extension,Load
(s),(mm),(N)
"0.00000","0.00000","3.03456"
"0.01800","-0.00002","3.03299"
"0.03600","-0.00035","2.92251"
"0.05400","-0.00191","2.73715"
"0.07200","-0.00496","2.62307"
"0.09000","-0.00811","2.58795"
"0.10800","-0.01167","2.58651"
"0.12600","-0.01623","2.58577"
"0.14400","-0.02153","2.58558"
"0.16200","-0.02703","2.59020"
"0.18000","-0.03230","2.60154"
"0.19800","-0.03723","2.61475"
"0.21600","-0.04189","2.62418"
"0.23400","-0.04647","2.62575"
"0.25200","-0.05105","2.62549"
"0.27000","-0.05565","2.64144"
"0.28800","-0.06024","2.64719"
"0.30600","-0.06483","2.64831"
"0.32400","-0.06943","2.64777"
"0.34200","-0.07401","2.64678"
"0.36000","-0.07855","2.65912"
"0.37800","-0.08310","2.65878"
"0.39600","-0.08766","2.65169"
"0.41400","-0.09221","2.64617"
"0.43200","-0.09672","2.64387"
"0.45000","-0.10127","2.64493"
"0.46800","-0.10586","2.64965"
"0.48600","-0.11047","2.65695"
"0.50400","-0.11503","2.64951"
"0.52200","-0.11960","2.64428"
"0.54000","-0.12420","2.64652"
"0.55800","-0.12878","2.65435"
"0.57600","-0.13332","2.65897"
"0.59400","-0.13786","2.65632"
"0.61200","-0.14246","2.66479"
"0.63000","-0.14711","2.68591"
"0.64800","-0.15174","2.69116"
"0.66600","-0.15632","2.67985"
"0.68400","-0.16090","2.66986"
"0.70200","-0.16550","2.67410"
"0.72000","-0.17005","2.67622"
"0.73800","-0.17455","2.67109"
"0.75600","-0.17909","2.66546"
"0.77400","-0.18366","2.67151"
"0.79200","-0.18824","2.68901"
"0.81000","-0.19279","2.71026"
"0.82800","-0.19737","2.72600"
"0.84600","-0.20198","2.73632"
"0.86400","-0.20657","2.73919"
"0.88200","-0.21109","2.74541"
"0.90000","-0.21561","2.74980"
"0.91800","-0.22019","2.75832"
"0.93600","-0.22479","2.76005"
"0.95400","-0.22935","2.76635"
"0.97200","-0.23392","2.77031"
"0.99000","-0.23856","2.76550"
"1.00800","-0.24323","2.76792"
"1.02600","-0.24782","2.77472"
"1.04400","-0.25237","2.77892"
"1.06200","-0.25693","2.77360"
"1.08000","-0.26149","2.76904"
"1.09800","-0.26601","2.76943"
"1.11600","-0.27050","2.77398"
"1.13400","-0.27505","2.79025"
"1.15200","-0.27969","2.80693"
"1.17000","-0.28432","2.81400"
"1.18800","-0.28888","2.81620"
"1.20600","-0.29344","2.81649"
"1.22400","-0.29803","2.82856"
"1.24200","-0.30259","2.83727"
"1.26000","-0.30708","2.84800"
"1.27800","-0.31159","2.86287"
"1.29600","-0.31617","2.87638"
"1.31400","-0.32079","2.89242"
"1.33200","-0.32538","2.89835"
"1.35000","-0.32998","2.89799"
"1.36800","-0.33463","2.89593"
"1.38600","-0.33928","2.89692"
"1.40400","-0.34384","2.90276"
"1.42200","-0.34833","2.90331"
"1.44000","-0.35286","2.90577"
"1.45800","-0.35744","2.89550"
"1.47600","-0.36200","2.88692"
"1.49400","-0.36654","2.87723"
"1.51200","-0.37115","2.85509"
"1.53000","-0.37579","2.83544"
"1.54800","-0.38041","2.82808"
"1.56600","-0.38496","2.83134"
"1.58400","-0.38949","2.84743"
"1.60200","-0.39403","2.87450"
"1.62000","-0.39856","2.89864"
"1.63800","-0.40306","2.91057"
"1.65600","-0.40758","2.91349"
"1.67400","-0.41218","2.90391"
"1.69200","-0.41683","2.89900"
"1.71000","-0.42145","2.91119"
"1.72800","-0.42604","2.93415"
"1.74600","-0.43065","2.95831"
"1.76400","-0.43525","2.96240"
"1.78200","-0.43979","2.95540"
"1.80000","-0.44430","2.95804"
"1.81800","-0.44883","2.96470"
"1.83600","-0.45342","2.97877"
"1.85400","-0.45802","2.99375"
"1.87200","-0.46261","3.01080"
"1.89000","-0.46722","3.01790"
"1.90800","-0.47183","3.02196"
"1.92600","-0.47640","3.01764"
"1.94400","-0.48092","3.00512"
"1.96200","-0.48544","2.99770"
"1.98000","-0.48999","3.00289"
"1.99800","-0.49454","3.02009"
"2.01600","-0.49906","3.03746"
"2.03400","-0.50362","3.03989"
"2.05200","-0.50823","3.02365"
"2.07000","-0.51285","2.99364"
"2.08800","-0.51743","2.97429"
"2.10600","-0.52201","2.97771"
"2.12400","-0.52659","2.99626"
"2.14200","-0.53115","3.02255"
"2.16000","-0.53568","3.05007"
"2.17800","-0.54022","3.07974"
"2.19600","-0.54483","3.07545"
"2.21400","-0.54947","3.05145"
"2.23200","-0.55409","3.02692"
"2.25000","-0.55867","3.01549"
"2.26800","-0.56327","3.01775"
"2.28600","-0.56787","3.03259"
"2.30400","-0.57241","3.06347"
"2.32200","-0.57689","3.08154"
"2.34000","-0.58141","3.08915"
"2.35800","-0.58598","3.09678"
"2.37600","-0.59056","3.09988"
"2.39400","-0.59511","3.10887"
"2.41200","-0.59970","3.10739"
"2.43000","-0.60432","3.10863"
"2.44800","-0.60892","3.10818"
"2.46600","-0.61344","3.11018"
"2.48400","-0.61797","3.11143"
"2.50200","-0.62255","3.10689"
"2.52000","-0.62713","3.11446"
"2.53800","-0.63168","3.12654"
"2.55600","-0.63624","3.13368"
"2.57400","-0.64090","3.13685"
"2.59200","-0.64556","3.13156"
"2.61000","-0.65014","3.13147"
"2.62800","-0.65469","3.13037"
"2.64600","-0.65925","3.12966"
"2.66400","-0.66381","3.14042"
"2.68200","-0.66834","3.15348"
"2.70000","-0.67284","3.16578"
"2.71800","-0.67740","3.17106"
"2.73600","-0.68204","3.17698"
"2.75400","-0.68667","3.18250"
"2.77200","-0.69124","3.19099"
"2.79000","-0.69581","3.20669"
"2.80800","-0.70040","3.21947"
"2.82600","-0.70493","3.22996"
"2.84400","-0.70938","3.23831"
"2.86200","-0.71388","3.25187"
"2.88000","-0.71847","3.26217"
"2.89800","-0.72310","3.26966"
"2.91600","-0.72770","3.27327"
"2.93400","-0.73231","3.26786"
"2.95200","-0.73697","3.26307"
"2.97000","-0.74164","3.26182"
"2.98800","-0.74620","3.26030"
"3.00600","-0.75070","3.24948"
"3.02400","-0.75522","3.23551"
"3.04200","-0.75979","3.24056"
"3.06000","-0.76433","3.23706"
"3.07800","-0.76887","3.22293"
"3.09600","-0.77348","3.20675"
"3.11400","-0.77814","3.18927"
"3.13200","-0.78274","3.21807"
"3.15000","-0.78727","3.24153"
"3.16800","-0.79181","3.25260"
"3.18600","-0.79636","3.26204"
"3.20400","-0.80088","3.28200"
"3.22200","-0.80538","3.30783"
"3.24000","-0.80990","3.32265"
"3.25800","-0.81450","3.33921"
"3.27600","-0.81917","3.34269"
"3.29400","-0.82378","3.35239"
"3.31200","-0.82837","3.37343"
"3.33000","-0.83296","3.40188"
"3.34800","-0.83756","3.42719"
"3.36600","-0.84210","3.44265"
"3.38400","-0.84662","3.45473"
"3.40200","-0.85116","3.45401"
"3.42000","-0.85575","3.44832"
"3.43800","-0.86036","3.44349"
"3.45600","-0.86498","3.44374"
"3.47400","-0.86960","3.45663"
"3.49200","-0.87421","3.46152"
"3.51000","-0.87877","3.45906"
"3.52800","-0.88328","3.44896"
"3.54600","-0.88779","3.44451"
"3.56400","-0.89232","3.45746"
"3.58200","-0.89684","3.47342"
"3.60000","-0.90136","3.48062"
"3.61800","-0.90594","3.47639"
"3.63600","-0.91057","3.46767"
"3.65400","-0.91519","3.47432"
"3.67200","-0.91977","3.48153"
"3.69000","-0.92434","3.49556"
"3.70800","-0.92892","3.50870"
"3.72600","-0.93348","3.52206"
"3.74400","-0.93800","3.53209"
"3.76200","-0.94254","3.53732"
"3.78000","-0.94716","3.53427"
"3.79800","-0.95182","3.53414"
"3.81600","-0.95644","3.54809"
"3.83400","-0.96104","3.56588"
"3.85200","-0.96564","3.58781"
"3.87000","-0.97024","3.59974"
"3.88800","-0.97475","3.59203"
"3.90600","-0.97923","3.57654"
"3.92400","-0.98375","3.56479"
"3.94200","-0.98833","3.56430"
"3.96000","-0.99291","3.57129"
"3.97800","-0.99747","3.57278"
"3.99600","-1.00207","3.58568"
"4.01400","-1.00668","3.59311"
"4.03200","-1.01126","3.59350"
"4.05000","-1.01577","3.59229"
"4.06800","-1.02028","3.59715"
"4.08600","-1.02485","3.60149"
"4.10400","-1.02943","3.60017"
"4.12200","-1.03398","3.60087"
"4.14000","-1.03856","3.60537"
"4.15800","-1.04323","3.62045"
"4.17600","-1.04790","3.63173"
"4.19400","-1.05247","3.63488"
"4.21200","-1.05703","3.64572"
"4.23000","-1.06158","3.65187"
"4.24800","-1.06614","3.66455"
"4.26600","-1.07067","3.67582"
"4.28400","-1.07518","3.68890"
"4.30200","-1.07975","3.70301"
"4.32000","-1.08437","3.70999"
"4.33800","-1.08899","3.71635"
"4.35600","-1.09356","3.71935"
"4.37400","-1.09813","3.72490"
"4.39200","-1.10272","3.72905"
"4.41000","-1.10725","3.72487"
"4.42800","-1.11172","3.72385"
"4.44600","-1.11624","3.72920"
"4.46400","-1.12085","3.74697"
"4.48200","-1.12547","3.76343"
"4.50000","-1.13004","3.76779"
"4.51800","-1.13464","3.76472"
"4.53600","-1.13929","3.75428"
"4.55400","-1.14395","3.74398"
"4.57200","-1.14851","3.73804"
"4.59000","-1.15301","3.72563"
"4.60800","-1.15754","3.71251"
"4.62600","-1.16211","3.70937"
"4.64400","-1.16663","3.72467"
"4.66200","-1.17118","3.74279"
"4.68000","-1.17581","3.77134"
"4.69800","-1.18048","3.79412"
"4.71600","-1.18508","3.80933"
"4.73400","-1.18960","3.82786"
"4.75200","-1.19414","3.83372"
"4.77000","-1.19869","3.83824"
"4.78800","-1.20320","3.84138"
"4.80600","-1.20768","3.84490"
"4.82400","-1.21222","3.85268"
"4.84200","-1.21685","3.86449"
"4.86000","-1.22153","3.88564"
"4.87800","-1.22615","3.90583"
"4.89600","-1.23073","3.91944"
"4.91400","-1.23532","3.92819"
"4.93200","-1.23988","3.92031"
"4.95000","-1.24440","3.91921"
"4.96800","-1.24893","3.92436"
"4.98600","-1.25350","3.93872"
"5.00400","-1.25811","3.95039"
"5.02200","-1.26272","3.95832"
"5.04000","-1.26732","3.96119"
"5.05800","-1.27192","3.94162"
"5.07600","-1.27651","3.92078"
"5.09400","-1.28105","3.90779"
"5.11200","-1.28556","3.90943"
"5.13000","-1.29007","3.92200"
"5.14800","-1.29462","3.93779"
"5.16600","-1.29917","3.95353"
"5.18400","-1.30371","3.96082"
"5.20200","-1.30829","3.97640"
"5.22000","-1.31292","3.98368"
"5.23800","-1.31752","3.99374"
"5.25600","-1.32209","3.99819"
"5.27400","-1.32666","4.00599"
"5.29200","-1.33123","4.02826"
"5.31000","-1.33578","4.04468"
"5.32800","-1.34031","4.05295"
"5.34600","-1.34488","4.04727"
"5.36400","-1.34951","4.04466"
"5.38200","-1.35417","4.05034"
"5.40000","-1.35878","4.05249"
"5.41800","-1.36335","4.06645"
"5.43600","-1.36794","4.07877"
"5.45400","-1.37252","4.08093"
"5.47200","-1.37703","4.08354"
"5.49000","-1.38153","4.08657"
"5.50800","-1.38609","4.09043"
"5.52600","-1.39068","4.08711"
"5.54400","-1.39525","4.09745"
"5.56200","-1.39980","4.09984"
"5.58000","-1.40440","4.09559"
"5.59800","-1.40903","4.10451"
"5.61600","-1.41360","4.10259"
"5.63400","-1.41809","4.10465"
"5.65200","-1.42261","4.10904"
"5.67000","-1.42719","4.12522"
"5.68800","-1.43178","4.14234"
"5.70600","-1.43633","4.15180"
"5.72400","-1.44093","4.16556"
"5.74200","-1.44561","4.17697"
"5.76000","-1.45026","4.18599"
"5.77800","-1.45482","4.19119"
"5.79600","-1.45937","4.18696"
"5.81400","-1.46393","4.18964"
"5.83200","-1.46848","4.20184"
"5.85000","-1.47300","4.22747"
"5.86800","-1.47751","4.24800"
"5.88600","-1.48209","4.26034"
"5.90400","-1.48674","4.27349"
"5.92200","-1.49134","4.27217"
"5.94000","-1.49590","4.27534"
"5.95800","-1.50047","4.27771"
"5.97600","-1.50505","4.27445"
"5.99400","-1.50959","4.29116"
"6.01200","-1.51407","4.30157"
"6.03000","-1.51861","4.30701"
"6.04800","-1.52321","4.29882"
"6.06600","-1.52782","4.29336"
"6.08400","-1.53239","4.29640"
"6.10200","-1.53700","4.30277"
"6.12000","-1.54165","4.31681"
"6.13800","-1.54629","4.31999"
"6.15600","-1.55084","4.31427"
"6.17400","-1.55534","4.30996"
"6.19200","-1.55987","4.31733"
"6.21000","-1.56444","4.33033"
"6.22800","-1.56897","4.33788"
"6.24600","-1.57354","4.34858"
"6.26400","-1.57817","4.35884"
"6.28200","-1.58284","4.37156"
"6.30000","-1.58742","4.38387"
"6.31800","-1.59194","4.39453"
"6.33600","-1.59648","4.40682"
"6.35400","-1.60101","4.40671"
"6.37200","-1.60553","4.41894"
"6.39000","-1.61001","4.42952"
"6.40800","-1.61456","4.43449"
"6.42600","-1.61919","4.45217"
"6.44400","-1.62386","4.46961"
"6.46200","-1.62849","4.48973"
"6.48000","-1.63309","4.49762"
"6.49800","-1.63770","4.50446"
"6.51600","-1.64226","4.50624"
"6.53400","-1.64678","4.50191"
"6.55200","-1.65128","4.50369"
"6.57000","-1.65583","4.50918"
"6.58800","-1.66043","4.52659"
"6.60600","-1.66504","4.54240"
"6.62400","-1.66964","4.55904"
"6.64200","-1.67425","4.56592"
"6.66000","-1.67885","4.56090"
"6.67800","-1.68340","4.56031"
"6.69600","-1.68790","4.55876"
"6.71400","-1.69241","4.54859"
"6.73200","-1.69696","4.55378"
"6.75000","-1.70149","4.57252"
"6.76800","-1.70602","4.59678"
"6.78600","-1.71062","4.60576"
"6.80400","-1.71526","4.60901"
"6.82200","-1.71988","4.60364"
"6.84000","-1.72446","4.60035"
"6.85800","-1.72903","4.61157"
"6.87600","-1.73359","4.63193"
"6.89400","-1.73813","4.65630"
"6.91200","-1.74264","4.66976"
"6.93000","-1.74721","4.68224"
"6.94800","-1.75184","4.69521"
"6.96600","-1.75650","4.69903"
"6.98400","-1.76112","4.70479"
"7.00200","-1.76572","4.70225"
"7.02000","-1.77032","4.70186"
"7.03800","-1.77488","4.69986"
"7.05600","-1.77936","4.69656"
"7.07400","-1.78385","4.69725"
"7.09200","-1.78840","4.69946"
"7.11000","-1.79298","4.70906"
"7.12800","-1.79755","4.71128"
"7.14600","-1.80212","4.71223"
"7.16400","-1.80673","4.70648"
"7.18200","-1.81136","4.70198"
"7.20000","-1.81593","4.70591"
"7.21800","-1.82045","4.71380"
"7.23600","-1.82498","4.73520"
"7.25400","-1.82956","4.75810"
"7.27200","-1.83412","4.77485"
"7.29000","-1.83865","4.78967"
"7.30800","-1.84326","4.78890"
"7.32600","-1.84793","4.80125"
"7.34400","-1.85259","4.82179"
"7.36200","-1.85716","4.84037"
"7.38000","-1.86170","4.85162"
"7.39800","-1.86625","4.85797"
"7.41600","-1.87081","4.85847"
"7.43400","-1.87532","4.85143"
"7.45200","-1.87984","4.85963"
"7.47000","-1.88443","4.87071"
"7.48800","-1.88908","4.88371"
"7.50600","-1.89368","4.90918"
"7.52400","-1.89824","4.92204"
"7.54200","-1.90281","4.92255"
"7.56000","-1.90738","4.91954"
"7.57800","-1.91188","4.91459"
"7.59600","-1.91636","4.91198"
"7.61400","-1.92091","4.90710"
"7.63200","-1.92553","4.91510"
"7.65000","-1.93015","4.92962"
"7.66800","-1.93473","4.94976"
"7.68600","-1.93934","4.97282"
"7.70400","-1.94400","4.99531"
"7.72200","-1.94864","5.01457"
"7.74000","-1.95316","5.01433"
"7.75800","-1.95767","5.01208"
"7.77600","-1.96223","5.01547"
"7.79400","-1.96680","5.03207"
"7.81200","-1.97132","5.04875"
"7.83000","-1.97587","5.04927"
"7.84800","-1.98051","5.05520"
"7.86600","-1.98519","5.06508"
"7.88400","-1.98977","5.08282"
"7.90200","-1.99427","5.08934"
"7.92000","-1.99879","5.09462"
"7.93800","-2.00331","5.10377"
"7.95600","-2.00781","5.09883"
"7.97400","-2.01231","5.10549"
"7.99200","-2.01689","5.11163"
"8.01000","-2.02155","5.11762"
"8.02800","-2.02624","5.13159"
"8.04600","-2.03085","5.14027"
"8.06400","-2.03543","5.15242"
"8.08200","-2.04002","5.15749"
"8.10000","-2.04456","5.15964"
"8.11800","-2.04906","5.16694"
"8.13600","-2.05358","5.17010"
"8.15400","-2.05816","5.18413"
"8.17200","-2.06278","5.19529"
"8.19000","-2.06739","5.20275"
"8.20800","-2.07200","5.21008"
"8.22600","-2.07662","5.22182"
"8.24400","-2.08121","5.24542"
"8.26200","-2.08573","5.25989"
"8.28000","-2.09021","5.26869"
"8.29800","-2.09471","5.26727"
"8.31600","-2.09927","5.26875"
"8.33400","-2.10382","5.27362"
"8.35200","-2.10839","5.28571"
"8.37000","-2.11299","5.31334"
"8.38800","-2.11762","5.33854"
"8.40600","-2.12222","5.36521"
"8.42400","-2.12678","5.38188"
"8.44200","-2.13135","5.38779"
"8.46000","-2.13591","5.39467"
"8.47800","-2.14044","5.40668"
"8.49600","-2.14498","5.42951"
"8.51400","-2.14956","5.44244"
"8.53200","-2.15421","5.45207"
"8.55000","-2.15888","5.45922"
"8.56800","-2.16348","5.46160"
"8.58600","-2.16806","5.46894"
"8.60400","-2.17264","5.47393"
"8.62200","-2.17717","5.46755"
"8.64000","-2.18165","5.44848"
"8.65800","-2.18616","5.43130"
"8.67600","-2.19073","5.42815"
"8.69400","-2.19535","5.42927"
"8.71200","-2.19993","5.44721"
"8.73000","-2.20450","5.46982"
"8.74800","-2.20910","5.48756"
"8.76600","-2.21372","5.49742"
"8.78400","-2.21827","5.51487"
"8.80200","-2.22275","5.54123"
"8.82000","-2.22728","5.55481"
"8.83800","-2.23186","5.57746"
"8.85600","-2.23643","5.58642"
"8.87400","-2.24099","5.58640"
"8.89200","-2.24562","5.58239"
"8.91000","-2.25031","5.58035"
"8.92800","-2.25495","5.59365"
"8.94600","-2.25951","5.59854"
"8.96400","-2.26404","5.60186"
"8.98200","-2.26856","5.60767"
"9.00000","-2.27309","5.62036"
"9.01800","-2.27760","5.64325"
"9.03600","-2.28215","5.66307"
"9.05400","-2.28679","5.68125"
"9.07200","-2.29147","5.70037"
"9.09000","-2.29606","5.71685"
"9.10800","-2.30060","5.73637"
"9.12600","-2.30515","5.74577"
"9.14400","-2.30971","5.75037"
"9.16200","-2.31420","5.76445"
"9.18000","-2.31868","5.78344"
"9.19800","-2.32324","5.79947"
"9.21600","-2.32788","5.81546"
"9.23400","-2.33250","5.84122"
"9.25200","-2.33710","5.85616"
"9.27000","-2.34172","5.86766"
"9.28800","-2.34637","5.87641"
"9.30600","-2.35097","5.87787"
"9.32400","-2.35547","5.89512"
"9.34200","-2.35996","5.90712"
"9.36000","-2.36451","5.92681"
"9.37800","-2.36908","5.93878"
"9.39600","-2.37361","5.95454"
"9.41400","-2.37819","5.97629"
"9.43200","-2.38282","5.99466"
"9.45000","-2.38746","6.00980"
"9.46800","-2.39201","6.01439"
"9.48600","-2.39652","6.02044"
"9.50400","-2.40106","6.02229"
"9.52200","-2.40560","6.02463"
"9.54000","-2.41012","6.03650"
"9.55800","-2.41466","6.04288"
"9.57600","-2.41925","6.04786"
"9.59400","-2.42391","6.05822"
"9.61200","-2.42856","6.08211"
"9.63000","-2.43315","6.10983"
"9.64800","-2.43774","6.12107"
"9.66600","-2.44233","6.12849"
"9.68400","-2.44689","6.13108"
"9.70200","-2.45140","6.13152"
"9.72000","-2.45593","6.12424"
"9.73800","-2.46052","6.12457"
"9.75600","-2.46514","6.15156"
"9.77400","-2.46974","6.17733"
"9.79200","-2.47434","6.20222"
"9.81000","-2.47894","6.20090"
"9.82800","-2.48353","6.19617"
"9.84600","-2.48804","6.20494"
"9.86400","-2.49254","6.20955"
"9.88200","-2.49706","6.23082"
"9.90000","-2.50162","6.26139"
"9.91800","-2.50617","6.30204"
"9.93600","-2.51074","6.33384"
"9.95400","-2.51534","6.35122"
"9.97200","-2.51997","6.35831"
"9.99000","-2.52455","6.35137"
"10.00800","-2.52912","6.36109"
"10.02600","-2.53369","6.38132"
"10.04400","-2.53826","6.40390"
"10.06200","-2.54279","6.43536"
"10.08000","-2.54731","6.46281"
"10.09800","-2.55189","6.48126"
"10.11600","-2.55655","6.48131"
"10.13400","-2.56122","6.46560"
"10.15200","-2.56582","6.46292"
"10.17000","-2.57040","6.47106"
"10.18800","-2.57500","6.49907"
"10.20600","-2.57955","6.52790"
"10.22400","-2.58403","6.55124"
"10.24200","-2.58853","6.56709"
"10.26000","-2.59310","6.57825"
"10.27800","-2.59768","6.59053"
"10.29600","-2.60225","6.59233"
"10.31400","-2.60682","6.60785"
"10.33200","-2.61144","6.62237"
"10.35000","-2.61605","6.64526"
"10.36800","-2.62059","6.67046"
"10.38600","-2.62508","6.68748"
"10.40400","-2.62962","6.69770"
"10.42200","-2.63420","6.69305"
"10.44000","-2.63876","6.69243"
"10.45800","-2.64332","6.69949"
"10.47600","-2.64796","6.71133"
"10.49400","-2.65266","6.73883"
"10.51200","-2.65730","6.76518"
"10.53000","-2.66184","6.79965"
"10.54800","-2.66639","6.83120"
"10.56600","-2.67093","6.85038"
"10.58400","-2.67545","6.87118"
"10.60200","-2.67996","6.87618"
"10.62000","-2.68450","6.87996"
"10.63800","-2.68913","6.88479"
"10.65600","-2.69378","6.90428"
"10.67400","-2.69836","6.92439"
"10.69200","-2.70290","6.93576"
"10.71000","-2.70746","6.94932"
"10.72800","-2.71202","6.95545"
"10.74600","-2.71652","6.96879"
"10.76400","-2.72101","6.97828"
"10.78200","-2.72559","6.99473"
"10.80000","-2.73023","7.02171"
"10.81800","-2.73484","7.03995"
"10.83600","-2.73944","7.05212"
"10.85400","-2.74406","7.05201"
"10.87200","-2.74871","7.06385"
"10.89000","-2.75330","7.07286"
"10.90800","-2.75779","7.07561"
"10.92600","-2.76230","7.09033"
"10.94400","-2.76685","7.10612"
"10.96200","-2.77142","7.12620"
"10.98000","-2.77595","7.15093"
"10.99800","-2.78055","7.16364"
"11.01600","-2.78522","7.18627"
"11.03400","-2.78988","7.20296"
"11.05200","-2.79444","7.21592"
"11.07000","-2.79895","7.22578"
"11.08800","-2.80347","7.24368"
"11.10600","-2.80799","7.26819"
"11.12400","-2.81249","7.28761"
"11.14200","-2.81699","7.31440"
"11.16000","-2.82157","7.31756"
"11.17800","-2.82624","7.32317"
"11.19600","-2.83092","7.33116"
"11.21400","-2.83553","7.35201"
"11.23200","-2.84013","7.38460"
"11.25000","-2.84470","7.40473"
"11.26800","-2.84923","7.41965"
"11.28600","-2.85372","7.42214"
"11.30400","-2.85825","7.42128"
"11.32200","-2.86284","7.42725"
"11.34000","-2.86746","7.44244"
"11.35800","-2.87207","7.47592"
"11.37600","-2.87668","7.50883"
"11.39400","-2.88129","7.54526"
"11.41200","-2.88587","7.57293"
"11.43000","-2.89037","7.58350"
"11.44800","-2.89487","7.59398"
"11.46600","-2.89940","7.59562"
"11.48400","-2.90396","7.61245"
"11.50200","-2.90850","7.63120"
"11.52000","-2.91307","7.65140"
"11.53800","-2.91769","7.67969"
"11.55600","-2.92232","7.69653"
"11.57400","-2.92692","7.72130"
"11.59200","-2.93147","7.74241"
"11.61000","-2.93603","7.76399"
"11.62800","-2.94059","7.78160"
"11.64600","-2.94512","7.79454"
"11.66400","-2.94964","7.81414"
"11.68200","-2.95425","7.82417"
"11.70000","-2.95892","7.84391"
"11.71800","-2.96358","7.86541"
"11.73600","-2.96816","7.88599"
"11.75400","-2.97274","7.89502"
"11.77200","-2.97732","7.90107"
"11.79000","-2.98186","7.92955"
"11.80800","-2.98634","7.95237"
"11.82600","-2.99084","7.97340"
"11.84400","-2.99542","7.99415"
"11.86200","-3.00001","8.01236"
"11.88000","-3.00457","8.03134"
"11.89800","-3.00914","8.04434"
"11.91600","-3.01375","8.07560"
"11.93400","-3.01836","8.10549"
"11.95200","-3.02290","8.12881"
"11.97000","-3.02741","8.15042"
"11.98800","-3.03196","8.16495"
"12.00600","-3.03654","8.18779"
"12.02400","-3.04110","8.20406"
"12.04200","-3.04566","8.22790"
"12.06000","-3.05031","8.25043"
"12.07800","-3.05500","8.27310"
"12.09600","-3.05962","8.29560"
"12.11400","-3.06417","8.29936"
"12.13200","-3.06871","8.31227"
"12.15000","-3.07326","8.32577"
"12.16800","-3.07778","8.34433"
"12.18600","-3.08227","8.37408"
"12.20400","-3.08682","8.40337"
"12.22200","-3.09145","8.42455"
"12.24000","-3.09610","8.44171"
"12.25800","-3.10069","8.46682"
"12.27600","-3.10525","8.48606"
"12.29400","-3.10982","8.50096"
"12.31200","-3.11437","8.53255"
"12.33000","-3.11884","8.56371"
"12.34800","-3.12331","8.59612"
"12.36600","-3.12789","8.61853"
"12.38400","-3.13253","8.62264"
"12.40200","-3.13715","8.62577"
"12.42000","-3.14175","8.62334"
"12.43800","-3.14639","8.63853"
"12.45600","-3.15104","8.66503"
"12.47400","-3.15563","8.69996"
"12.49200","-3.16013","8.73368"
"12.51000","-3.16464","8.75389"
"12.52800","-3.16920","8.77448"
"12.54600","-3.17376","8.79256"
"12.56400","-3.17830","8.81411"
"12.58200","-3.18290","8.82825"
"12.60000","-3.18757","8.84314"
"12.61800","-3.19221","8.86517"
"12.63600","-3.19675","8.87691"
"12.65400","-3.20127","8.89752"
"12.67200","-3.20580","8.91065"
"12.69000","-3.21032","8.92098"
"12.70800","-3.21482","8.93592"
"12.72600","-3.21934","8.95215"
"12.74400","-3.22393","8.97517"
"12.76200","-3.22861","8.99504"
"12.78000","-3.23325","9.02181"
"12.79800","-3.23785","9.03569"
"12.81600","-3.24245","9.06772"
"12.83400","-3.24704","9.10688"
"12.85200","-3.25157","9.12481"
"12.87000","-3.25607","9.14119"
"12.88800","-3.26059","9.16028"
"12.90600","-3.26518","9.18852"
"12.92400","-3.26980","9.22838"
"12.94200","-3.27441","9.25862"
"12.96000","-3.27901","9.29183"
"12.97800","-3.28361","9.31351"
"12.99600","-3.28819","9.33784"
"13.01400","-3.29271","9.36036"
"13.03200","-3.29721","9.38088"
"13.05000","-3.30174","9.40865"
"13.06800","-3.30629","9.43266"
"13.08600","-3.31082","9.46975"
"13.10400","-3.31540","9.49514"
"13.12200","-3.32002","9.51258"
"13.14000","-3.32466","9.53143"
"13.15800","-3.32924","9.54527"
"13.17600","-3.33381","9.56580"
"13.19400","-3.33838","9.58003"
"13.21200","-3.34292","9.60717"
"13.23000","-3.34743","9.63786"
"13.24800","-3.35195","9.66209"
"13.26600","-3.35657","9.69014"
"13.28400","-3.36125","9.71105"
"13.30200","-3.36592","9.73785"
"13.32000","-3.37053","9.75511"
"13.33800","-3.37512","9.77013"
"13.35600","-3.37969","9.79674"
"13.37400","-3.38421","9.82154"
"13.39200","-3.38867","9.85448"
"13.41000","-3.39318","9.87442"
"13.42800","-3.39775","9.89956"
"13.44600","-3.40232","9.91687"
"13.46400","-3.40689","9.92561"
"13.48200","-3.41147","9.94984"
"13.50000","-3.41610","9.96708"
"13.51800","-3.42070","10.00054"
"13.53600","-3.42523","10.03821"
"13.55400","-3.42973","10.06468"
"13.57200","-3.43428","10.08519"
"13.59000","-3.43887","10.09490"
"13.60800","-3.44343","10.12065"
"13.62600","-3.44800","10.14512"
"13.64400","-3.45265","10.17648"
"13.66200","-3.45733","10.22469"
"13.68000","-3.46193","10.25893"
"13.69800","-3.46648","10.29067"
"13.71600","-3.47103","10.31547"
"13.73400","-3.47558","10.33585"
"13.75200","-3.48012","10.34632"
"13.77000","-3.48463","10.36311"
"13.78800","-3.48919","10.40061"
"13.80600","-3.49383","10.44048"
"13.82400","-3.49847","10.49057"
"13.84200","-3.50304","10.52051"
"13.86000","-3.50758","10.53305"
"13.87800","-3.51214","10.55144"
"13.89600","-3.51669","10.56831"
"13.91400","-3.52116","10.59752"
"13.93200","-3.52566","10.62926"
"13.95000","-3.53024","10.67691"
"13.96800","-3.53486","10.70286"
"13.98600","-3.53946","10.71628"
"14.00400","-3.54407","10.73307"
"14.02200","-3.54873","10.74926"
"14.04000","-3.55340","10.78629"
"14.05800","-3.55797","10.81759"
"14.07600","-3.56246","10.85188"
"14.09400","-3.56697","10.88638"
"14.11200","-3.57154","10.91751"
"14.13000","-3.57609","10.95398"
"14.14800","-3.58062","10.98564"
"14.16600","-3.58523","11.02106"
"14.18400","-3.58991","11.03902"
"14.20200","-3.59456","11.04488"
"14.22000","-3.59910","11.06410"
"14.23800","-3.60361","11.09808"
"14.25600","-3.60812","11.14534"
"14.27400","-3.61265","11.17453"
"14.29200","-3.61714","11.20030"
"14.31000","-3.62164","11.23249"
"14.32800","-3.62622","11.25507"
"14.34600","-3.63089","11.28601"
"14.36400","-3.63555","11.30447"
"14.38200","-3.64017","11.33689"
"14.40000","-3.64479","11.36326"
"14.41800","-3.64937","11.39010"
"14.43600","-3.65388","11.43613"
"14.45400","-3.65838","11.47035"
"14.47200","-3.66293","11.50438"
"14.49000","-3.66753","11.52379"
"14.50800","-3.67215","11.55329"
"14.52600","-3.67676","11.58349"
"14.54400","-3.68137","11.61129"
"14.56200","-3.68598","11.65527"
"14.58000","-3.69054","11.68564"
"14.59800","-3.69503","11.71739"
"14.61600","-3.69952","11.75100"
"14.63400","-3.70406","11.77878"
"14.65200","-3.70861","11.80968"
"14.67000","-3.71313","11.83010"
"14.68800","-3.71770","11.85947"
"14.70600","-3.72234","11.89314"
"14.72400","-3.72697","11.92847"
"14.74200","-3.73157","11.96918"
"14.76000","-3.73615","11.99708"
"14.77800","-3.74072","12.03359"
"14.79600","-3.74529","12.05184"
"14.81400","-3.74981","12.07722"
"14.83200","-3.75434","12.10712"
"14.85000","-3.75894","12.13615"
"14.86800","-3.76360","12.18510"
"14.88600","-3.76824","12.22235"
"14.90400","-3.77283","12.27198"
"14.92200","-3.77742","12.30071"
"14.94000","-3.78199","12.31513"
"14.95800","-3.78650","12.33917"
"14.97600","-3.79098","12.36572"
"14.99400","-3.79551","12.40644"
"15.01200","-3.80009","12.44660"
"15.03000","-3.80469","12.49220"
"15.04800","-3.80925","12.51952"
"15.06600","-3.81384","12.54990"
"15.08400","-3.81847","12.58649"
"15.10200","-3.82307","12.61889"
"15.12000","-3.82758","12.65354"
"15.13800","-3.83209","12.68329"
"15.15600","-3.83666","12.72955"
"15.17400","-3.84125","12.78870"
"15.19200","-3.84579","12.82191"
"15.21000","-3.85033","12.85436"
"15.22800","-3.85499","12.88500"
"15.24600","-3.85968","12.92081"
"15.26400","-3.86430","12.95750"
"15.28200","-3.86886","13.00707"
"15.30000","-3.87341","13.04994"
"15.31800","-3.87794","13.07018"
"15.33600","-3.88245","13.09548"
"15.35400","-3.88693","13.12188"
"15.37200","-3.89150","13.15951"
"15.39000","-3.89614","13.21127"
"15.40800","-3.90079","13.24640"
"15.42600","-3.90536","13.28745"
"15.44400","-3.90993","13.31811"
"15.46200","-3.91451","13.36173"
"15.48000","-3.91905","13.40370"
"15.49800","-3.92352","13.43184"
"15.51600","-3.92802","13.46664"
"15.53400","-3.93260","13.49610"
"15.55200","-3.93722","13.53050"
"15.57000","-3.94182","13.56875"
"15.58800","-3.94643","13.60496"
"15.60600","-3.95108","13.65331"
"15.62400","-3.95574","13.68998"
"15.64200","-3.96030","13.72112"
"15.66000","-3.96478","13.74245"
"15.67800","-3.96931","13.77026"
"15.69600","-3.97388","13.81584"
"15.71400","-3.97842","13.85499"
"15.73200","-3.98296","13.90810"
"15.75000","-3.98757","13.95594"
"15.76800","-3.99224","14.01371"
"15.78600","-3.99687","14.05606"
"15.80400","-4.00140","14.09480"
"15.82200","-4.00592","14.14920"
"15.84000","-4.01046","14.18522"
"15.85800","-4.01499","14.23507"
"15.87600","-4.01948","14.26506"
"15.89400","-4.02400","14.29890"
"15.91200","-4.02861","14.34775"
"15.93000","-4.03328","14.38570"
"15.94800","-4.03792","14.42750"
"15.96600","-4.04252","14.46544"
"15.98400","-4.04713","14.51622"
"16.00200","-4.05170","14.56882"
"16.02000","-4.05622","14.61591"
"16.03800","-4.06073","14.64991"
"16.05600","-4.06528","14.68925"
"16.07400","-4.06988","14.73702"
"16.09200","-4.07449","14.78152"
"16.11000","-4.07908","14.82814"
"16.12800","-4.08369","14.87719"
"16.14600","-4.08830","14.92583"
"16.16400","-4.09288","14.99252"
"16.18200","-4.09739","15.03199"
"16.20000","-4.10188","15.07114"
"16.21800","-4.10641","15.10768"
"16.23600","-4.11095","15.14483"
"16.25400","-4.11548","15.19646"
"16.27200","-4.12006","15.23163"
"16.29000","-4.12468","15.28940"
"16.30800","-4.12930","15.33350"
"16.32600","-4.13387","15.37432"
"16.34400","-4.13845","15.42054"
"16.36200","-4.14303","15.45665"
"16.38000","-4.14759","15.51046"
"16.39800","-4.15211","15.55676"
"16.41600","-4.15664","15.60466"
"16.43400","-4.16125","15.65477"
"16.45200","-4.16591","15.69518"
"16.47000","-4.17055","15.74470"
"16.48800","-4.17514","15.78537"
"16.50600","-4.17973","15.84013"
"16.52400","-4.18433","15.89275"
"16.54200","-4.18885","15.94537"
"16.56000","-4.19334","16.00442"
"16.57800","-4.19788","16.05753"
"16.59600","-4.20246","16.11002"
"16.61400","-4.20704","16.15169"
"16.63200","-4.21159","16.19834"
"16.65000","-4.21618","16.24741"
"16.66800","-4.22080","16.29405"
"16.68600","-4.22538","16.35726"
"16.70400","-4.22988","16.40855"
"16.72200","-4.23438","16.46885"
"16.74000","-4.23896","16.52019"
"16.75800","-4.24356","16.57459"
"16.77600","-4.24811","16.62453"
"16.79400","-4.25269","16.66531"
"16.81200","-4.25736","16.73390"
"16.83000","-4.26205","16.79150"
"16.84800","-4.26665","16.84685"
"16.86600","-4.27119","16.90024"
"16.88400","-4.27573","16.94233"
"16.90200","-4.28028","16.98778"
"16.92000","-4.28479","17.02179"
"16.93800","-4.28928","17.06465"
"16.95600","-4.29384","17.11262"
"16.97400","-4.29849","17.16867"
"16.99200","-4.30313","17.24150"
"17.01000","-4.30769","17.29019"
"17.02800","-4.31226","17.35082"
"17.04600","-4.31684","17.40751"
"17.06400","-4.32137","17.45945"
"17.08200","-4.32584","17.52107"
"17.10000","-4.33036","17.57159"
"17.11800","-4.33496","17.63707"
"17.13600","-4.33958","17.69485"
"17.15400","-4.34416","17.75679"
"17.17200","-4.34876","17.79062"
"17.19000","-4.35341","17.80005"
"17.20800","-4.35808","17.84745"
"17.22600","-4.36265","17.90818"
"17.24400","-4.36715","17.99801"
"17.26200","-4.37169","18.06669"
"17.28000","-4.37624","18.12935"
"17.29800","-4.38077","18.18759"
"17.31600","-4.38531","18.21793"
"17.33400","-4.38993","18.26118"
"17.35200","-4.39461","18.29553"
"17.37000","-4.39921","18.35037"
"17.38800","-4.40374","18.42632"
"17.40600","-4.40827","18.51041"
"17.42400","-4.41282","18.59864"
"17.44200","-4.41733","18.66501"
"17.46000","-4.42184","18.72518"
"17.47800","-4.42636","18.76942"
"17.49600","-4.43098","18.82767"
"17.51400","-4.43565","18.89949"
"17.53200","-4.44026","18.96296"
"17.55000","-4.44485","19.04169"
"17.56800","-4.44945","19.12844"
"17.58600","-4.45404","19.21555"
"17.60400","-4.45857","19.27746"
"17.62200","-4.46310","19.30048"
"17.64000","-4.46766","19.32631"
"17.65800","-4.47225","19.33934"
"17.67600","-4.47683","19.38430"
"17.69400","-4.48142","19.45869"
"17.71200","-4.48602","19.55756"
"17.73000","-4.49061","19.65930"
"17.74800","-4.49517","19.74518"
"17.76600","-4.49969","19.83392"
"17.78400","-4.50422","19.87720"
"17.80200","-4.50877","19.92760"
"17.82000","-4.51330","20.00204"
"17.83800","-4.51782","20.08186"
"17.85600","-4.52239","20.15749"
"17.87400","-4.52701","20.23203"
"17.89200","-4.53164","20.32813"
"17.91000","-4.53623","20.40181"
"17.92800","-4.54081","20.45047"
"17.94600","-4.54539","20.50152"
"17.96400","-4.54994","20.55002"
"17.98200","-4.55443","20.64364"
"18.00000","-4.55896","20.74329"
"18.01800","-4.56359","20.82029"
"18.03600","-4.56828","20.89599"
"18.05400","-4.57292","20.96152"
"18.07200","-4.57751","21.03650"
"18.09000","-4.58210","21.06768"
"18.10800","-4.58667","21.08997"
"18.12600","-4.59118","21.13570"
"18.14400","-4.59566","21.19801"
"18.16200","-4.60019","21.28364"
"18.18000","-4.60476","21.37356"
"18.19800","-4.60933","21.48285"
"18.21600","-4.61389","21.56132"
"18.23400","-4.61850","21.63102"
"18.25200","-4.62313","21.69743"
"18.27000","-4.62772","21.77553"
"18.28800","-4.63224","21.88765"
"18.30600","-4.63677","21.98648"
"18.32400","-4.64135","22.06840"
"18.34200","-4.64592","22.14898"
"18.36000","-4.65043","22.24746"
"18.37800","-4.65500","22.34051"
"18.39600","-4.65966","22.41497"
"18.41400","-4.66433","22.52188"
"18.43200","-4.66892","22.64036"
"18.45000","-4.67350","22.72154"
"18.46800","-4.67807","22.78484"
"18.48600","-4.68262","22.83261"
"18.50400","-4.68712","22.92431"
"18.52200","-4.69161","23.03366"
"18.54000","-4.69617","23.15191"
"18.55800","-4.70082","23.22896"
"18.57600","-4.70545","23.28059"
"18.59400","-4.71003","23.36368"
"18.61200","-4.71461","23.43856"
"18.63000","-4.71920","23.51617"
"18.64800","-4.72373","23.58291"
"18.66600","-4.72819","23.67217"
"18.68400","-4.73271","23.78381"
"18.70200","-4.73730","23.88162"
"18.72000","-4.74191","23.95605"
"18.73800","-4.74648","23.99431"
"18.75600","-4.75107","24.05054"
"18.77400","-4.75571","24.10934"
"18.79200","-4.76035","24.16967"
"18.81000","-4.76490","24.27544"
"18.82800","-4.76941","24.40786"
"18.84600","-4.77397","24.56988"
"18.86400","-4.77855","24.70635"
"18.88200","-4.78308","24.80305"
"18.90000","-4.78763","24.86644"
"18.91800","-4.79226","24.88951"
"18.93600","-4.79691","24.96745"
"18.95400","-4.80149","25.06662"
"18.97200","-4.80601","25.23498"
"18.99000","-4.81054","25.40525"
"19.00800","-4.81511","25.51501"
"19.02600","-4.81965","25.60494"
"19.04400","-4.82415","25.65293"
"19.06200","-4.82870","25.75611"
"19.08000","-4.83333","25.86988"
"19.09800","-4.83799","25.97371"
"19.11600","-4.84259","26.08300"
"19.13400","-4.84717","26.18164"
"19.15200","-4.85178","26.29380"
"19.17000","-4.85638","26.37591"
"19.18800","-4.86093","26.43523"
"19.20600","-4.86546","26.48500"
"19.22400","-4.87001","26.56913"
"19.24200","-4.87460","26.71130"
"19.26000","-4.87919","26.86892"
"19.27800","-4.88376","27.01824"
"19.29600","-4.88835","27.10697"
"19.31400","-4.89294","27.17083"
"19.33200","-4.89750","27.23373"
"19.35000","-4.90203","27.31481"
"19.36800","-4.90657","27.46531"
"19.38600","-4.91113","27.60238"
"19.40400","-4.91566","27.72844"
"19.42200","-4.92019","27.86219"
"19.44000","-4.92476","27.97539"
"19.45800","-4.92935","28.09649"
"19.47600","-4.93395","28.18855"
"19.49400","-4.93852","28.29784"
"19.51200","-4.94311","28.43966"
"19.53000","-4.94771","28.58772"
"19.54800","-4.95229","28.71231"
"19.56600","-4.95682","28.80392"
"19.58400","-4.96137","28.90211"
"19.60200","-4.96600","28.97132"
"19.62000","-4.97066","29.06141"
"19.63800","-4.97525","29.17874"
"19.65600","-4.97982","29.29743"
"19.67400","-4.98440","29.42665"
"19.69200","-4.98897","29.50659"
"19.71000","-4.99350","29.59216"
"19.72800","-4.99802","29.69150"
"19.74600","-5.00258","29.83053"
"19.76400","-5.00715","29.98359"
"19.78200","-5.01170","30.09540"
"19.80000","-5.01625","30.19495"
"19.81800","-5.02082","30.28369"
"19.83600","-5.02543","30.42772"
"19.85400","-5.03001","30.60876"
"19.87200","-5.03454","30.71785"
"19.89000","-5.03909","30.81352"
"19.90800","-5.04368","30.91891"
"19.92600","-5.04826","31.06030"
"19.94400","-5.05279","31.22318"
"19.96200","-5.05738","31.35875"
"19.98000","-5.06205","31.50426"
"19.99800","-5.06670","31.61038"
"20.01600","-5.07126","31.76736"
"20.03400","-5.07581","31.90861"
"20.05200","-5.08037","32.04890"
"20.07000","-5.08494","32.16806"
"20.08800","-5.08945","32.21494"
"20.10600","-5.09394","32.29664"
"20.12400","-5.09852","32.40749"
"20.14200","-5.10317","32.55600"
"20.16000","-5.10777","32.73166"
"20.17800","-5.11233","32.90483"
"20.19600","-5.11690","33.06468"
"20.21400","-5.12148","33.16671"
"20.23200","-5.12601","33.28264"
"20.25000","-5.13050","33.39590"
"20.26800","-5.13505","33.52023"
"20.28600","-5.13965","33.65844"
"20.30400","-5.14426","33.81686"
"20.32200","-5.14884","34.00506"
"20.34000","-5.15344","34.16695"
"20.35800","-5.15809","34.32206"
"20.37600","-5.16273","34.44953"
"20.39400","-5.16728","34.54130"
"20.41200","-5.17180","34.63768"
"20.43000","-5.17637","34.73246"
"20.44800","-5.18094","34.91515"
"20.46600","-5.18546","35.10038"
"20.48400","-5.19000","35.26889"
"20.50200","-5.19462","35.41541"
"20.52000","-5.19927","35.45185"
"20.53800","-5.20383","35.45299"
"20.55600","-5.20834","35.45189"
"20.57400","-5.21287","35.57769"
"20.59200","-5.21741","35.80003"
"20.61000","-5.22193","36.04083"
"20.62800","-5.22643","36.27156"
"20.64600","-5.23100","36.41719"
"20.66400","-5.23565","36.51613"
"20.68200","-5.24031","36.58181"
"20.70000","-5.24491","36.69404"
"20.71800","-5.24949","36.83893"
"20.73600","-5.25409","36.98037"
"20.75400","-5.25868","37.16365"
"20.77200","-5.26323","37.38251"
"20.79000","-5.26775","37.61956"
"20.80800","-5.27230","37.76180"
"20.82600","-5.27691","37.80545"
"20.84400","-5.28152","37.90697"
"20.86200","-5.28611","38.01147"
"20.88000","-5.29071","38.12266"
"20.89800","-5.29531","38.27083"
"20.91600","-5.29985","38.48898"
"20.93400","-5.30436","38.68536"
"20.95200","-5.30889","38.83916"
"20.97000","-5.31345","38.95768"
"20.98800","-5.31798","38.98318"
"21.00600","-5.32251","39.02827"
"21.02400","-5.32707","39.13043"
"21.04200","-5.33167","39.34580"
"21.06000","-5.33628","39.65654"
"21.07800","-5.34086","39.80733"
"21.09600","-5.34546","39.84212"
"21.11400","-5.35005","39.87819"
"21.13200","-5.35461","39.94173"
"21.15000","-5.35912","40.09171"
"21.16800","-5.36367","40.30868"
"21.18600","-5.36830","40.57710"
"21.20400","-5.37295","40.78662"
"21.22200","-5.37756","40.94757"
"21.24000","-5.38213","41.15762"
"21.25800","-5.38673","41.34909"
"21.27600","-5.39131","41.52937"
"21.29400","-5.39582","41.62190"
"21.31200","-5.40032","41.64070"
"21.33000","-5.40488","41.69985"
"21.34800","-5.40946","41.84601"
"21.36600","-5.41402","42.08155"
"21.38400","-5.41857","42.34216"
"21.40200","-5.42317","42.52940"
"21.42000","-5.42779","42.64858"
"21.43800","-5.43236","42.82957"
"21.45600","-5.43687","43.04515"
"21.47400","-5.44140","43.19257"
"21.49200","-5.44599","43.36884"
"21.51000","-5.45055","43.56467"
"21.52800","-5.45510","43.74737"
"21.54600","-5.45972","43.90540"
"21.56400","-5.46440","44.07483"
"21.58200","-5.46904","44.27124"
"21.60000","-5.47359","44.45025"
"21.61800","-5.47814","44.60136"
"21.63600","-5.48271","44.69773"
"21.65400","-5.48727","44.85810"
"21.67200","-5.49178","45.04669"
"21.69000","-5.49630","45.14852"
"21.70800","-5.50090","45.31750"
"21.72600","-5.50555","45.57913"
"21.74400","-5.51013","45.73450"
"21.76200","-5.51467","45.77174"
"21.78000","-5.51923","45.80660"
"21.79800","-5.52381","45.89325"
"21.81600","-5.52834","46.03585"
"21.83400","-5.53283","46.30054"
"21.85200","-5.53739","46.60784"
"21.87000","-5.54201","46.89862"
"21.88800","-5.54663","47.14526"
"21.90600","-5.55120","47.23908"
"21.92400","-5.55581","47.26179"
"21.94200","-5.56046","47.32042"
"21.96000","-5.56509","47.51739"
"21.97800","-5.56961","47.80472"
"21.99600","-5.57413","48.07871"
"22.01400","-5.57869","48.30471"
"22.03200","-5.58326","48.41523"
"22.05000","-5.58778","48.50462"
"22.06800","-5.59235","48.65036"
"22.08600","-5.59699","48.80976"
"22.10400","-5.60163","48.93315"
"22.12200","-5.60619","48.97718"
"22.14000","-5.61071","49.11802"
"22.15800","-5.61527","49.32907"
"22.17600","-5.61983","49.50426"
"22.19400","-5.62434","49.58078"
"22.21200","-5.62883","49.65584"
"22.23000","-5.63339","49.76244"
"22.24800","-5.63804","49.86497"
"22.26600","-5.64269","50.04866"
"22.28400","-5.64727","50.33819"
"22.30200","-5.65185","50.70075"
"22.32000","-5.65645","50.96568"
"22.33800","-5.66101","51.06950"
"22.35600","-5.66552","51.21838"
"22.37400","-5.67005","51.38732"
"22.39200","-5.67461","51.54951"
"22.41000","-5.67922","51.75027"
"22.42800","-5.68382","51.95609"
"22.44600","-5.68842","52.11114"
"22.46400","-5.69304","52.22259"
"22.48200","-5.69763","52.39360"
"22.50000","-5.70217","52.63118"
"22.51800","-5.70668","52.82970"
"22.53600","-5.71121","52.91997"
"22.55400","-5.71577","52.96737"
"22.57200","-5.72030","53.00461"
"22.59000","-5.72486","53.10603"
"22.60800","-5.72944","53.35981"
"22.62600","-5.73406","53.58506"
"22.64400","-5.73865","53.64609"
"22.66200","-5.74323","53.69863"
"22.68000","-5.74783","53.78859"
"22.69800","-5.75243","53.93751"
"22.71600","-5.75697","54.16179"
"22.73400","-5.76148","54.43383"
"22.75200","-5.76604","54.70094"
"22.77000","-5.77067","54.94712"
"22.78800","-5.77531","55.18253"
"22.80600","-5.77990","55.28021"
"22.82400","-5.78448","55.28824"
"22.84200","-5.78909","55.31167"
"22.86000","-5.79366","55.47287"
"22.87800","-5.79815","55.81739"
"22.89600","-5.80265","56.13436"
"22.91400","-5.80720","56.37820"
"22.93200","-5.81180","56.45222"
"22.95000","-5.81635","56.50318"
"22.96800","-5.82091","56.60141"
"22.98600","-5.82550","56.73178"
"23.00400","-5.83011","56.93080"
"23.02200","-5.83466","57.15586"
"23.04000","-5.83918","57.40998"
"23.05800","-5.84373","57.62313"
"23.07600","-5.84833","57.72092"
"23.09400","-5.85290","57.75673"
"23.11200","-5.85744","57.79212"
"23.13000","-5.86205","58.04449"
"23.14800","-5.86672","58.32010"
"23.16600","-5.87136","58.57193"
"23.18400","-5.87593","58.89313"
"23.20200","-5.88050","59.06623"
"23.22000","-5.88507","59.15010"
"23.23800","-5.88962","59.24630"
"23.25600","-5.89411","59.42122"
"23.27400","-5.89862","59.54153"
"23.29200","-5.90322","59.66280"
"23.31000","-5.90786","59.90801"
"23.32800","-5.91244","60.17733"
"23.34600","-5.91700","60.39801"
"23.36400","-5.92158","60.52419"
"23.38200","-5.92617","60.62177"
"23.40000","-5.93067","60.77732"
"23.41800","-5.93514","60.94436"
"23.43600","-5.93970","61.16872"
"23.45400","-5.94432","61.40297"
"23.47200","-5.94893","61.66957"
"23.49000","-5.95351","61.89092"
"23.50800","-5.95813","61.98035"
"23.52600","-5.96279","61.94531"
"23.54400","-5.96742","62.04557"
"23.56200","-5.97195","62.27214"
"23.58000","-5.97647","62.50295"
"23.59800","-5.98103","62.69910"
"23.61600","-5.98559","62.86856"
"23.63400","-5.99012","62.96077"
"23.65200","-5.99468","63.08303"
"23.67000","-5.99931","63.26323"
"23.68800","-6.00394","63.54067"
"23.70600","-6.00850","63.80124"
"23.72400","-6.01303","63.96910"
"23.74200","-6.01758","64.16267"
"23.76000","-6.02214","64.34973"
"23.77800","-6.02664","64.40539"
"23.79600","-6.03113","64.42988"
"23.81400","-6.03570","64.64091"
"23.83200","-6.04036","64.99192"
"23.85000","-6.04501","65.30403"
"23.86800","-6.04960","65.51866"
"23.88600","-6.05420","65.63860"
"23.90400","-6.05880","65.69889"
"23.92200","-6.06336","65.73824"
"23.94000","-6.06787","65.94404"
"23.95800","-6.07240","66.29411"
"23.97600","-6.07697","66.52926"
"23.99400","-6.08156","66.64654"
"24.01200","-6.08615","66.81422"
"24.03000","-6.09076","67.00057"
"24.04800","-6.09536","67.15820"
"24.06600","-6.09995","67.31139"
"24.08400","-6.10448","67.51414"
"24.10200","-6.10899","67.67014"
"24.12000","-6.11353","67.83154"
"24.13800","-6.11811","68.01259"
"24.15600","-6.12265","68.20938"
"24.17400","-6.12719","68.46046"
"24.19200","-6.13177","68.59991"
"24.21000","-6.13638","68.79765"
"24.22800","-6.14095","69.02820"
"24.24600","-6.14552","69.13908"
"24.26400","-6.15011","69.22705"
"24.28200","-6.15471","69.38486"
"24.30000","-6.15925","69.62646"
"24.31800","-6.16378","69.85137"
"24.33600","-6.16837","70.06134"
"24.35400","-6.17304","70.25671"
"24.37200","-6.17769","70.48898"
"24.39000","-6.18228","70.78308"
"24.40800","-6.18685","71.05566"
"24.42600","-6.19144","71.34150"
"24.44400","-6.19598","71.54938"
"24.46200","-6.20046","71.63752"
"24.48000","-6.20497","71.70656"
"24.49800","-6.20954","71.77281"
"24.51600","-6.21413","71.98842"
"24.53400","-6.21868","72.31839"
"24.55200","-6.22324","72.67569"
"24.57000","-6.22784","72.95305"
"24.58800","-6.23245","73.07694"
"24.60600","-6.23700","73.21510"
"24.62400","-6.24152","73.33120"
"24.64200","-6.24608","73.34148"
"24.66000","-6.25068","72.91257"
"24.67800","-6.25524","72.15249"
"24.69600","-6.25980","71.41771"
"24.71400","-6.26444","70.59262"
"24.73200","-6.26911","69.66450"
"24.75000","-6.27373","68.67694"
"24.76800","-6.27828","67.64419"
"24.78600","-6.28283","66.43179"
"24.80400","-6.28740","65.01810"
"24.82200","-6.29195","63.62104"
"24.84000","-6.29644","62.07696"
"24.85800","-6.30097","60.16357"
"24.87600","-6.30557","57.90625"
"24.89400","-6.31021","55.35931"
"24.91200","-6.31478","52.51450"
"24.93000","-6.31932","49.39787"
"24.94800","-6.32388","46.01992"
"24.96600","-6.32844","42.41182"
"24.98400","-6.33293","38.66563"
"25.00200","-6.33743","34.74366"
"25.02000","-6.34200","30.76315"
"25.03800","-6.34664","26.87159"
"25.05600","-6.35126","23.09759"
"25.07400","-6.35585","19.36778"
"25.09200","-6.36048","15.62208"
"25.11000","-6.36514","11.93102"
"25.12800","-6.36974","8.34362"
"25.14600","-6.37424","4.89636"
"25.16400","-6.37876","1.81846"
"25.18200","-6.38333","0.15031"
"25.24900","-6.39762","-0.02302"
"27.04900","-6.39281","-0.00566"
"28.84900","-6.39281","-0.00484"
"30.64900","-6.39281","-0.00433"
"32.44900","-6.39281","-0.00422"
"34.24900","-6.39281","-0.00398"
"35.31500","-6.37981","1.78497"
"35.34000","-6.37300","7.87962"
"35.35800","-6.36764","13.55550"
"35.37600","-6.36243","19.20551"
"35.39400","-6.35746","24.57317"
"35.41200","-6.35265","29.72772"
"35.43000","-6.34795","34.74577"
"35.44800","-6.34339","39.62269"
"35.46600","-6.33885","44.46596"
"35.48400","-6.33429","49.34514"
"35.50200","-6.32973","54.25315"
"35.52000","-6.32524","59.14455"
"35.53800","-6.32072","63.86440"
"35.57200","-6.31202","71.48787"
"35.61900","-6.30003","77.09883"
"35.94000","-6.21850","78.76181"
"36.35100","-6.11418","74.13783"
"36.81000","-5.99752","69.53440"
"37.27900","-5.87839","64.91722"
"37.76500","-5.75478","60.32432"
"38.23300","-5.63599","55.72396"
"38.71000","-5.51494","51.13226"
"39.21200","-5.38739","46.54107"
"39.70000","-5.26333","41.92732"
"40.23100","-5.12850","37.36700"
"40.83900","-4.97409","32.79073"
"41.52000","-4.80120","28.22238"
"42.39600","-4.57870","23.67180"
"43.54700","-4.28624","19.21935"
"44.99000","-3.91972","15.38959"
"46.49200","-3.53816","12.44913"
"48.14200","-3.11907","9.95777"
"49.94200","-2.66197","8.19925"
"51.73300","-2.20713","6.82938"
"53.53300","-1.74970","5.88169"
"55.33300","-1.29262","4.97749"
"57.13300","-0.83540","4.30687"
"58.93300","-0.37827","3.64476"
"60.42200","0.00004","3.39692"