File: Specimen_RawData_1_SN19Z009675.csv
Time,Extension,Load
(s),(mm),(N)
"0.00000","0.00000","2.17544"
"0.01800","-0.00001","2.17306"
"0.03600","-0.00034","2.05894"
"0.05400","-0.00193","1.42721"
"0.07200","-0.00504","0.72853"
"0.09000","-0.00835","0.52472"
"0.10800","-0.01198","0.55922"
"0.12600","-0.01646","0.68478"
"0.14400","-0.02166","0.83098"
"0.16200","-0.02708","0.93986"
"0.18000","-0.03229","0.99609"
"0.19800","-0.03719","1.02306"
"0.21600","-0.04192","1.04471"
"0.23400","-0.04657","1.07600"
"0.25200","-0.05115","1.10714"
"0.27000","-0.05567","1.14041"
"0.28800","-0.06022","1.17159"
"0.30600","-0.06481","1.19254"
"0.32400","-0.06940","1.20799"
"0.34200","-0.07394","1.22486"
"0.36000","-0.07851","1.24896"
"0.37800","-0.08315","1.27185"
"0.39600","-0.08780","1.28999"
"0.41400","-0.09239","1.31370"
"0.43200","-0.09696","1.33014"
"0.45000","-0.10155","1.34297"
"0.46800","-0.10612","1.35067"
"0.48600","-0.11064","1.35138"
"0.50400","-0.11513","1.34523"
"0.52200","-0.11968","1.34277"
"0.54000","-0.12430","1.34730"
"0.55800","-0.12891","1.35620"
"0.57600","-0.13347","1.36358"
"0.59400","-0.13804","1.36811"
"0.61200","-0.14261","1.37413"
"0.63000","-0.14714","1.38723"
"0.64800","-0.15161","1.40243"
"0.66600","-0.15613","1.41973"
"0.68400","-0.16074","1.43891"
"0.70200","-0.16539","1.45825"
"0.72000","-0.17000","1.47569"
"0.73800","-0.17459","1.48865"
"0.75600","-0.17924","1.50400"
"0.77400","-0.18389","1.52132"
"0.79200","-0.18846","1.53816"
"0.81000","-0.19297","1.54772"
"0.82800","-0.19753","1.54936"
"0.84600","-0.20210","1.54611"
"0.86400","-0.20665","1.53901"
"0.88200","-0.21119","1.53341"
"0.90000","-0.21579","1.53650"
"0.91800","-0.22043","1.55011"
"0.93600","-0.22503","1.57117"
"0.95400","-0.22955","1.58740"
"0.97200","-0.23408","1.60323"
"0.99000","-0.23862","1.61578"
"1.00800","-0.24315","1.62497"
"1.02600","-0.24763","1.63520"
"1.04400","-0.25215","1.64544"
"1.06200","-0.25676","1.66144"
"1.08000","-0.26143","1.68103"
"1.09800","-0.26606","1.70513"
"1.11600","-0.27066","1.72202"
"1.13400","-0.27526","1.72872"
"1.15200","-0.27985","1.73142"
"1.17000","-0.28440","1.73214"
"1.18800","-0.28895","1.72986"
"1.20600","-0.29351","1.72373"
"1.22400","-0.29810","1.72563"
"1.24200","-0.30268","1.73140"
"1.26000","-0.30725","1.73976"
"1.27800","-0.31185","1.75310"
"1.29600","-0.31646","1.76489"
"1.31400","-0.32102","1.77583"
"1.33200","-0.32556","1.77999"
"1.35000","-0.33009","1.78407"
"1.36800","-0.33463","1.79793"
"1.38600","-0.33918","1.81985"
"1.40400","-0.34371","1.84497"
"1.42200","-0.34828","1.86724"
"1.44000","-0.35288","1.88291"
"1.45800","-0.35748","1.89615"
"1.47600","-0.36206","1.90446"
"1.49400","-0.36663","1.90999"
"1.51200","-0.37121","1.91173"
"1.53000","-0.37578","1.91626"
"1.54800","-0.38030","1.92336"
"1.56600","-0.38484","1.92686"
"1.58400","-0.38946","1.93806"
"1.60200","-0.39412","1.94940"
"1.62000","-0.39874","1.96483"
"1.63800","-0.40332","1.97842"
"1.65600","-0.40790","1.98929"
"1.67400","-0.41248","2.00057"
"1.69200","-0.41699","2.00757"
"1.71000","-0.42149","2.01365"
"1.72800","-0.42603","2.02141"
"1.74600","-0.43061","2.03409"
"1.76400","-0.43519","2.04828"
"1.78200","-0.43974","2.05666"
"1.80000","-0.44433","2.06178"
"1.81800","-0.44896","2.06150"
"1.83600","-0.45354","2.05950"
"1.85400","-0.45805","2.05526"
"1.87200","-0.46259","2.05323"
"1.89000","-0.46717","2.05358"
"1.90800","-0.47175","2.05789"
"1.92600","-0.47630","2.06772"
"1.94400","-0.48088","2.07494"
"1.96200","-0.48554","2.08316"
"1.98000","-0.49020","2.08850"
"1.99800","-0.49478","2.09078"
"2.01600","-0.49933","2.09397"
"2.03400","-0.50389","2.09761"
"2.05200","-0.50844","2.10718"
"2.07000","-0.51295","2.11797"
"2.08800","-0.51746","2.12469"
"2.10600","-0.52204","2.13010"
"2.12400","-0.52668","2.13440"
"2.14200","-0.53130","2.14411"
"2.16000","-0.53587","2.14921"
"2.17800","-0.54044","2.15644"
"2.19600","-0.54502","2.16586"
"2.21400","-0.54955","2.17636"
"2.23200","-0.55402","2.18331"
"2.25000","-0.55854","2.18426"
"2.26800","-0.56314","2.18894"
"2.28600","-0.56776","2.20069"
"2.30400","-0.57235","2.21450"
"2.32200","-0.57696","2.23042"
"2.34000","-0.58161","2.24100"
"2.35800","-0.58626","2.25026"
"2.37600","-0.59081","2.25979"
"2.39400","-0.59531","2.26860"
"2.41200","-0.59985","2.27947"
"2.43000","-0.60442","2.28632"
"2.44800","-0.60896","2.29088"
"2.46600","-0.61352","2.29266"
"2.48400","-0.61814","2.29590"
"2.50200","-0.62279","2.30273"
"2.52000","-0.62738","2.31557"
"2.53800","-0.63191","2.33072"
"2.55600","-0.63644","2.34175"
"2.57400","-0.64097","2.35188"
"2.59200","-0.64549","2.35756"
"2.61000","-0.64997","2.36801"
"2.62800","-0.65450","2.37961"
"2.64600","-0.65913","2.38987"
"2.66400","-0.66380","2.40464"
"2.68200","-0.66843","2.41703"
"2.70000","-0.67302","2.42954"
"2.71800","-0.67762","2.44316"
"2.73600","-0.68219","2.45823"
"2.75400","-0.68670","2.47308"
"2.77200","-0.69123","2.48257"
"2.79000","-0.69579","2.48999"
"2.80800","-0.70038","2.49491"
"2.82600","-0.70498","2.50260"
"2.84400","-0.70957","2.50751"
"2.86200","-0.71418","2.51129"
"2.88000","-0.71880","2.51835"
"2.89800","-0.72338","2.52736"
"2.91600","-0.72789","2.53480"
"2.93400","-0.73241","2.53463"
"2.95200","-0.73694","2.53370"
"2.97000","-0.74147","2.53915"
"2.98800","-0.74599","2.54544"
"3.00600","-0.75058","2.55277"
"3.02400","-0.75520","2.55603"
"3.04200","-0.75981","2.55925"
"3.06000","-0.76439","2.56461"
"3.07800","-0.76897","2.56933"
"3.09600","-0.77354","2.57541"
"3.11400","-0.77810","2.58084"
"3.13200","-0.78262","2.58607"
"3.15000","-0.78717","2.58831"
"3.16800","-0.79181","2.58975"
"3.18600","-0.79647","2.59313"
"3.20400","-0.80107","2.59868"
"3.22200","-0.80565","2.60222"
"3.24000","-0.81024","2.60528"
"3.25800","-0.81482","2.61472"
"3.27600","-0.81932","2.62241"
"3.29400","-0.82382","2.62212"
"3.31200","-0.82837","2.62229"
"3.33000","-0.83296","2.62748"
"3.34800","-0.83754","2.63032"
"3.36600","-0.84208","2.62473"
"3.38400","-0.84666","2.62122"
"3.40200","-0.85127","2.62669"
"3.42000","-0.85584","2.63555"
"3.43800","-0.86034","2.65008"
"3.45600","-0.86488","2.65833"
"3.47400","-0.86949","2.65834"
"3.49200","-0.87410","2.66075"
"3.51000","-0.87865","2.66544"
"3.52800","-0.88323","2.67502"
"3.54600","-0.88787","2.68251"
"3.56400","-0.89251","2.69259"
"3.58200","-0.89709","2.69929"
"3.60000","-0.90167","2.69738"
"3.61800","-0.90625","2.69707"
"3.63600","-0.91080","2.70156"
"3.65400","-0.91530","2.71023"
"3.67200","-0.91980","2.71373"
"3.69000","-0.92439","2.71764"
"3.70800","-0.92903","2.72772"
"3.72600","-0.93363","2.73439"
"3.74400","-0.93819","2.73844"
"3.76200","-0.94277","2.73948"
"3.78000","-0.94736","2.74063"
"3.79800","-0.95189","2.75109"
"3.81600","-0.95636","2.75858"
"3.83400","-0.96089","2.76582"
"3.85200","-0.96549","2.77146"
"3.87000","-0.97010","2.78111"
"3.88800","-0.97468","2.78829"
"3.90600","-0.97929","2.79205"
"3.92400","-0.98394","2.79620"
"3.94200","-0.98858","2.79320"
"3.96000","-0.99313","2.79260"
"3.97800","-0.99766","2.79577"
"3.99600","-1.00223","2.80169"
"4.01400","-1.00680","2.80865"
"4.03200","-1.01131","2.81619"
"4.05000","-1.01585","2.82409"
"4.06800","-1.02046","2.82848"
"4.08600","-1.02510","2.84210"
"4.10400","-1.02969","2.85677"
"4.12200","-1.03422","2.86440"
"4.14000","-1.03878","2.86915"
"4.15800","-1.04333","2.87135"
"4.17600","-1.04784","2.87657"
"4.19400","-1.05233","2.87948"
"4.21200","-1.05687","2.87946"
"4.23000","-1.06149","2.87803"
"4.24800","-1.06614","2.87836"
"4.26600","-1.07075","2.87921"
"4.28400","-1.07534","2.87837"
"4.30200","-1.07993","2.88482"
"4.32000","-1.08450","2.89607"
"4.33800","-1.08903","2.90713"
"4.35600","-1.09357","2.91383"
"4.37400","-1.09814","2.91919"
"4.39200","-1.10275","2.93127"
"4.41000","-1.10733","2.93903"
"4.42800","-1.11192","2.94056"
"4.44600","-1.11651","2.94293"
"4.46400","-1.12111","2.94381"
"4.48200","-1.12566","2.95135"
"4.50000","-1.13019","2.95328"
"4.51800","-1.13472","2.95423"
"4.53600","-1.13928","2.95437"
"4.55400","-1.14382","2.95877"
"4.57200","-1.14836","2.96880"
"4.59000","-1.15293","2.97809"
"4.60800","-1.15755","2.98349"
"4.62600","-1.16215","2.98744"
"4.64400","-1.16671","2.99486"
"4.66200","-1.17129","3.00527"
"4.68000","-1.17585","3.01377"
"4.69800","-1.18038","3.02454"
"4.71600","-1.18488","3.03227"
"4.73400","-1.18943","3.03762"
"4.75200","-1.19405","3.04256"
"4.77000","-1.19872","3.04668"
"4.78800","-1.20335","3.05664"
"4.80600","-1.20796","3.06318"
"4.82400","-1.21258","3.07415"
"4.84200","-1.21718","3.08367"
"4.86000","-1.22168","3.08446"
"4.87800","-1.22617","3.08411"
"4.89600","-1.23071","3.08725"
"4.91400","-1.23528","3.09551"
"4.93200","-1.23983","3.09696"
"4.95000","-1.24440","3.09981"
"4.96800","-1.24902","3.10664"
"4.98600","-1.25364","3.11449"
"5.00400","-1.25818","3.12316"
"5.02200","-1.26268","3.13015"
"5.04000","-1.26722","3.14209"
"5.05800","-1.27182","3.15238"
"5.07600","-1.27641","3.16040"
"5.09400","-1.28097","3.16798"
"5.11200","-1.28558","3.17306"
"5.13000","-1.29025","3.17948"
"5.14800","-1.29488","3.18492"
"5.16600","-1.29943","3.18117"
"5.18400","-1.30399","3.17630"
"5.20200","-1.30855","3.18268"
"5.22000","-1.31310","3.19540"
"5.23800","-1.31761","3.20173"
"5.25600","-1.32212","3.20513"
"5.27400","-1.32672","3.21516"
"5.29200","-1.33137","3.22660"
"5.31000","-1.33596","3.23718"
"5.32800","-1.34052","3.24383"
"5.34600","-1.34511","3.25085"
"5.36400","-1.34969","3.25350"
"5.38200","-1.35421","3.25537"
"5.40000","-1.35869","3.25759"
"5.41800","-1.36323","3.26022"
"5.43600","-1.36782","3.26757"
"5.45400","-1.37243","3.27455"
"5.47200","-1.37703","3.28128"
"5.49000","-1.38167","3.28822"
"5.50800","-1.38633","3.29198"
"5.52600","-1.39096","3.30031"
"5.54400","-1.39546","3.30619"
"5.56200","-1.39996","3.30494"
"5.58000","-1.40451","3.30194"
"5.59800","-1.40908","3.31380"
"5.61600","-1.41362","3.32792"
"5.63400","-1.41819","3.33446"
"5.65200","-1.42284","3.33937"
"5.67000","-1.42750","3.34543"
"5.68800","-1.43206","3.35455"
"5.70600","-1.43657","3.36557"
"5.72400","-1.44110","3.37409"
"5.74200","-1.44562","3.38322"
"5.76000","-1.45012","3.38861"
"5.77800","-1.45462","3.39499"
"5.79600","-1.45919","3.39837"
"5.81400","-1.46385","3.40232"
"5.83200","-1.46852","3.40797"
"5.85000","-1.47312","3.41074"
"5.86800","-1.47771","3.41934"
"5.88600","-1.48231","3.42356"
"5.90400","-1.48687","3.42995"
"5.92200","-1.49138","3.43796"
"5.94000","-1.49588","3.44730"
"5.95800","-1.50045","3.45480"
"5.97600","-1.50507","3.45940"
"5.99400","-1.50969","3.46854"
"6.01200","-1.51429","3.47557"
"6.03000","-1.51888","3.48313"
"6.04800","-1.52347","3.49370"
"6.06600","-1.52800","3.50086"
"6.08400","-1.53253","3.50609"
"6.10200","-1.53706","3.50721"
"6.12000","-1.54161","3.51163"
"6.13800","-1.54614","3.51893"
"6.15600","-1.55068","3.52329"
"6.17400","-1.55528","3.52809"
"6.19200","-1.55991","3.53215"
"6.21000","-1.56452","3.54360"
"6.22800","-1.56910","3.55015"
"6.24600","-1.57369","3.55523"
"6.26400","-1.57827","3.55917"
"6.28200","-1.58282","3.55911"
"6.30000","-1.58734","3.56726"
"6.31800","-1.59191","3.57619"
"6.33600","-1.59655","3.58514"
"6.35400","-1.60118","3.59595"
"6.37200","-1.60576","3.61004"
"6.39000","-1.61034","3.62080"
"6.40800","-1.61493","3.62119"
"6.42600","-1.61950","3.62667"
"6.44400","-1.62399","3.63080"
"6.46200","-1.62849","3.63284"
"6.48000","-1.63304","3.63796"
"6.49800","-1.63763","3.64426"
"6.51600","-1.64220","3.65129"
"6.53400","-1.64676","3.65311"
"6.55200","-1.65136","3.65608"
"6.57000","-1.65597","3.66483"
"6.58800","-1.66051","3.67563"
"6.60600","-1.66502","3.68199"
"6.62400","-1.66958","3.68341"
"6.64200","-1.67418","3.69025"
"6.66000","-1.67876","3.70174"
"6.67800","-1.68331","3.71184"
"6.69600","-1.68793","3.72548"
"6.71400","-1.69260","3.73696"
"6.73200","-1.69722","3.74802"
"6.75000","-1.70177","3.75123"
"6.76800","-1.70633","3.75427"
"6.78600","-1.71091","3.75697"
"6.80400","-1.71546","3.75932"
"6.82200","-1.71996","3.76965"
"6.84000","-1.72447","3.77926"
"6.85800","-1.72907","3.78535"
"6.87600","-1.73370","3.78907"
"6.89400","-1.73829","3.79578"
"6.91200","-1.74284","3.80298"
"6.93000","-1.74742","3.81047"
"6.94800","-1.75201","3.81897"
"6.96600","-1.75652","3.82670"
"6.98400","-1.76100","3.83495"
"7.00200","-1.76556","3.84282"
"7.02000","-1.77019","3.85099"
"7.03800","-1.77480","3.86185"
"7.05600","-1.77937","3.86968"
"7.07400","-1.78398","3.87826"
"7.09200","-1.78861","3.88360"
"7.11000","-1.79321","3.88887"
"7.12800","-1.79774","3.89620"
"7.14600","-1.80227","3.89762"
"7.16400","-1.80685","3.90365"
"7.18200","-1.81142","3.91248"
"7.20000","-1.81596","3.91713"
"7.21800","-1.82053","3.91476"
"7.23600","-1.82516","3.92538"
"7.25400","-1.82978","3.94357"
"7.27200","-1.83432","3.95080"
"7.29000","-1.83884","3.95819"
"7.30800","-1.84339","3.96155"
"7.32600","-1.84794","3.96405"
"7.34400","-1.85246","3.97062"
"7.36200","-1.85696","3.97952"
"7.38000","-1.86152","3.99376"
"7.39800","-1.86617","4.00193"
"7.41600","-1.87082","4.00895"
"7.43400","-1.87542","4.01919"
"7.45200","-1.88003","4.02619"
"7.47000","-1.88464","4.03704"
"7.48800","-1.88920","4.04861"
"7.50600","-1.89373","4.05863"
"7.52400","-1.89826","4.06529"
"7.54200","-1.90282","4.07514"
"7.56000","-1.90740","4.08749"
"7.57800","-1.91198","4.09319"
"7.59600","-1.91658","4.10446"
"7.61400","-1.92118","4.11370"
"7.63200","-1.92576","4.12319"
"7.65000","-1.93027","4.14020"
"7.66800","-1.93476","4.14968"
"7.68600","-1.93929","4.16123"
"7.70400","-1.94386","4.16520"
"7.72200","-1.94841","4.17172"
"7.74000","-1.95298","4.17959"
"7.75800","-1.95759","4.18527"
"7.77600","-1.96222","4.19203"
"7.79400","-1.96682","4.18962"
"7.81200","-1.97139","4.20679"
"7.83000","-1.97597","4.22518"
"7.84800","-1.98054","4.23655"
"7.86600","-1.98509","4.24256"
"7.88400","-1.98962","4.24249"
"7.90200","-1.99421","4.24998"
"7.92000","-1.99887","4.25788"
"7.93800","-2.00352","4.26670"
"7.95600","-2.00811","4.27245"
"7.97400","-2.01269","4.27740"
"7.99200","-2.01727","4.29345"
"8.01000","-2.02181","4.30576"
"8.02800","-2.02630","4.31597"
"8.04600","-2.03081","4.32137"
"8.06400","-2.03539","4.32303"
"8.08200","-2.03997","4.33268"
"8.10000","-2.04453","4.34140"
"8.11800","-2.04911","4.35425"
"8.13600","-2.05373","4.36250"
"8.15400","-2.05834","4.37522"
"8.17200","-2.06287","4.38747"
"8.19000","-2.06737","4.39768"
"8.20800","-2.07193","4.41005"
"8.22600","-2.07653","4.41751"
"8.24400","-2.08109","4.42994"
"8.26200","-2.08563","4.43818"
"8.28000","-2.09026","4.44782"
"8.29800","-2.09494","4.46208"
"8.31600","-2.09956","4.47822"
"8.33400","-2.10410","4.49602"
"8.35200","-2.10866","4.50552"
"8.37000","-2.11323","4.51972"
"8.38800","-2.11777","4.52256"
"8.40600","-2.12226","4.52070"
"8.42400","-2.12680","4.52692"
"8.44200","-2.13142","4.54003"
"8.46000","-2.13606","4.55455"
"8.47800","-2.14064","4.56319"
"8.49600","-2.14519","4.56833"
"8.51400","-2.14977","4.57980"
"8.53200","-2.15434","4.58812"
"8.55000","-2.15883","4.61657"
"8.56800","-2.16332","4.65709"
"8.58600","-2.16789","4.68385"
"8.60400","-2.17253","4.70117"
"8.62200","-2.17715","4.71334"
"8.64000","-2.18174","4.72392"
"8.65800","-2.18637","4.72829"
"8.67600","-2.19102","4.74161"
"8.69400","-2.19561","4.76020"
"8.71200","-2.20009","4.77269"
"8.73000","-2.20459","4.78274"
"8.74800","-2.20914","4.79298"
"8.76600","-2.21370","4.80689"
"8.78400","-2.21823","4.80970"
"8.80200","-2.22283","4.81092"
"8.82000","-2.22750","4.81838"
"8.83800","-2.23215","4.82966"
"8.85600","-2.23671","4.84422"
"8.87400","-2.24123","4.85360"
"8.89200","-2.24575","4.86675"
"8.91000","-2.25026","4.87563"
"8.92800","-2.25476","4.88425"
"8.94600","-2.25928","4.89872"
"8.96400","-2.26387","4.90650"
"8.98200","-2.26855","4.91086"
"9.00000","-2.27322","4.91540"
"9.01800","-2.27782","4.92430"
"9.03600","-2.28240","4.93666"
"9.05400","-2.28698","4.93909"
"9.07200","-2.29151","4.94421"
"9.09000","-2.29602","4.94555"
"9.10800","-2.30056","4.94010"
"9.12600","-2.30514","4.93342"
"9.14400","-2.30976","4.92941"
"9.16200","-2.31436","4.93561"
"9.18000","-2.31896","4.94357"
"9.19800","-2.32357","4.95760"
"9.21600","-2.32815","4.97411"
"9.23400","-2.33267","4.99316"
"9.25200","-2.33718","5.01145"
"9.27000","-2.34171","5.02554"
"9.28800","-2.34626","5.03629"
"9.30600","-2.35077","5.04214"
"9.32400","-2.35533","5.05219"
"9.34200","-2.35995","5.06570"
"9.36000","-2.36458","5.08467"
"9.37800","-2.36917","5.10428"
"9.39600","-2.37373","5.11806"
"9.41400","-2.37829","5.12879"
"9.43200","-2.38284","5.13575"
"9.45000","-2.38735","5.14455"
"9.46800","-2.39187","5.16203"
"9.48600","-2.39647","5.18035"
"9.50400","-2.40114","5.20251"
"9.52200","-2.40582","5.22541"
"9.54000","-2.41043","5.24812"
"9.55800","-2.41503","5.26363"
"9.57600","-2.41962","5.26748"
"9.59400","-2.42415","5.27923"
"9.61200","-2.42862","5.29027"
"9.63000","-2.43313","5.30519"
"9.64800","-2.43771","5.31688"
"9.66600","-2.44231","5.32718"
"9.68400","-2.44688","5.34089"
"9.70200","-2.45145","5.35555"
"9.72000","-2.45605","5.37221"
"9.73800","-2.46065","5.38285"
"9.75600","-2.46519","5.39703"
"9.77400","-2.46971","5.40961"
"9.79200","-2.47427","5.42038"
"9.81000","-2.47887","5.43470"
"9.82800","-2.48342","5.44789"
"9.84600","-2.48797","5.45936"
"9.86400","-2.49261","5.46910"
"9.88200","-2.49729","5.47802"
"9.90000","-2.50191","5.49029"
"9.91800","-2.50646","5.50151"
"9.93600","-2.51099","5.51565"
"9.95400","-2.51553","5.52517"
"9.97200","-2.52006","5.53425"
"9.99000","-2.52457","5.54307"
"10.00800","-2.52915","5.55461"
"10.02600","-2.53380","5.56885"
"10.04400","-2.53844","5.57860"
"10.06200","-2.54300","5.59205"
"10.08000","-2.54755","5.60617"
"10.09800","-2.55212","5.62487"
"10.11600","-2.55666","5.64409"
"10.13400","-2.56114","5.66155"
"10.15200","-2.56562","5.68079"
"10.17000","-2.57020","5.69548"
"10.18800","-2.57484","5.70623"
"10.20600","-2.57946","5.71725"
"10.22400","-2.58406","5.72978"
"10.24200","-2.58870","5.74895"
"10.26000","-2.59336","5.76396"
"10.27800","-2.59795","5.78302"
"10.29600","-2.60244","5.79634"
"10.31400","-2.60695","5.80858"
"10.33200","-2.61152","5.82192"
"10.35000","-2.61608","5.83176"
"10.36800","-2.62062","5.84359"
"10.38600","-2.62522","5.85602"
"10.40400","-2.62989","5.86964"
"10.42200","-2.63452","5.88895"
"10.44000","-2.63906","5.90616"
"10.45800","-2.64358","5.92441"
"10.47600","-2.64808","5.94064"
"10.49400","-2.65259","5.95144"
"10.51200","-2.65708","5.96346"
"10.53000","-2.66160","5.97294"
"10.54800","-2.66621","5.98706"
"10.56600","-2.67088","5.99943"
"10.58400","-2.67553","6.01747"
"10.60200","-2.68014","6.03469"
"10.62000","-2.68474","6.04910"
"10.63800","-2.68932","6.06419"
"10.65600","-2.69385","6.07652"
"10.67400","-2.69836","6.08718"
"10.69200","-2.70291","6.09503"
"10.71000","-2.70751","6.11114"
"10.72800","-2.71212","6.12715"
"10.74600","-2.71671","6.14384"
"10.76400","-2.72131","6.16639"
"10.78200","-2.72590","6.18380"
"10.80000","-2.73047","6.20085"
"10.81800","-2.73498","6.20868"
"10.83600","-2.73948","6.22107"
"10.85400","-2.74401","6.23155"
"10.87200","-2.74857","6.24399"
"10.89000","-2.75313","6.25896"
"10.90800","-2.75771","6.26986"
"10.92600","-2.76233","6.28764"
"10.94400","-2.76694","6.30588"
"10.96200","-2.77151","6.31374"
"10.98000","-2.77607","6.32294"
"10.99800","-2.78064","6.33443"
"11.01600","-2.78520","6.35203"
"11.03400","-2.78973","6.36844"
"11.05200","-2.79426","6.39229"
"11.07000","-2.79887","6.41770"
"11.08800","-2.80354","6.43448"
"11.10600","-2.80818","6.45324"
"11.12400","-2.81276","6.46242"
"11.14200","-2.81735","6.46831"
"11.16000","-2.82194","6.47381"
"11.17800","-2.82647","6.48941"
"11.19600","-2.83094","6.51107"
"11.21400","-2.83546","6.52372"
"11.23200","-2.84004","6.53986"
"11.25000","-2.84463","6.56273"
"11.26800","-2.84921","6.58155"
"11.28600","-2.85379","6.59933"
"11.30400","-2.85841","6.61300"
"11.32200","-2.86302","6.63165"
"11.34000","-2.86754","6.64390"
"11.35800","-2.87204","6.65448"
"11.37600","-2.87660","6.67172"
"11.39400","-2.88119","6.68717"
"11.41200","-2.88575","6.70424"
"11.43000","-2.89032","6.71624"
"11.44800","-2.89498","6.73485"
"11.46600","-2.89966","6.75351"
"11.48400","-2.90426","6.77007"
"11.50200","-2.90879","6.78939"
"11.52000","-2.91334","6.79455"
"11.53800","-2.91789","6.82557"
"11.55600","-2.92242","6.85207"
"11.57400","-2.92693","6.86392"
"11.59200","-2.93149","6.87149"
"11.61000","-2.93613","6.88287"
"11.62800","-2.94075","6.90312"
"11.64600","-2.94530","6.91888"
"11.66400","-2.94986","6.93431"
"11.68200","-2.95443","6.94458"
"11.70000","-2.95899","6.95787"
"11.71800","-2.96347","6.97653"
"11.73600","-2.96798","6.99128"
"11.75400","-2.97257","7.01243"
"11.77200","-2.97720","7.02812"
"11.79000","-2.98180","7.04607"
"11.80800","-2.98639","7.06573"
"11.82600","-2.99103","7.08416"
"11.84400","-2.99569","7.10270"
"11.86200","-3.00027","7.11653"
"11.88000","-3.00478","7.13016"
"11.89800","-3.00931","7.14795"
"11.91600","-3.01388","7.16358"
"11.93400","-3.01843","7.18259"
"11.95200","-3.02296","7.18903"
"11.97000","-3.02756","7.20020"
"11.98800","-3.03221","7.21305"
"12.00600","-3.03682","7.22403"
"12.02400","-3.04133","7.23732"
"12.04200","-3.04585","7.25184"
"12.06000","-3.05037","7.27186"
"12.07800","-3.05489","7.28503"
"12.09600","-3.05939","7.30356"
"12.11400","-3.06392","7.32405"
"12.13200","-3.06854","7.33875"
"12.15000","-3.07324","7.35565"
"12.16800","-3.07789","7.36770"
"12.18600","-3.08249","7.38957"
"12.20400","-3.08707","7.41119"
"12.22200","-3.09164","7.42877"
"12.24000","-3.09616","7.44551"
"12.25800","-3.10068","7.45091"
"12.27600","-3.10522","7.46560"
"12.29400","-3.10981","7.48117"
"12.31200","-3.11444","7.50371"
"12.33000","-3.11905","7.52761"
"12.34800","-3.12364","7.54475"
"12.36600","-3.12824","7.56626"
"12.38400","-3.13281","7.58071"
"12.40200","-3.13732","7.59894"
"12.42000","-3.14184","7.61344"
"12.43800","-3.14637","7.63342"
"12.45600","-3.15093","7.65931"
"12.47400","-3.15546","7.68102"
"12.49200","-3.16003","7.70570"
"12.51000","-3.16465","7.72749"
"12.52800","-3.16925","7.75643"
"12.54600","-3.17381","7.77858"
"12.56400","-3.17837","7.78692"
"12.58200","-3.18295","7.79849"
"12.60000","-3.18752","7.81314"
"12.61800","-3.19206","7.83126"
"12.63600","-3.19661","7.85211"
"12.65400","-3.20122","7.87612"
"12.67200","-3.20589","7.90236"
"12.69000","-3.21052","7.91969"
"12.70800","-3.21511","7.93898"
"12.72600","-3.21969","7.95688"
"12.74400","-3.22427","7.97568"
"12.76200","-3.22879","7.99605"
"12.78000","-3.23329","8.01145"
"12.79800","-3.23783","8.03624"
"12.81600","-3.24241","8.05701"
"12.83400","-3.24699","8.07760"
"12.85200","-3.25154","8.09718"
"12.87000","-3.25611","8.12169"
"12.88800","-3.26072","8.15054"
"12.90600","-3.26531","8.16465"
"12.92400","-3.26982","8.18373"
"12.94200","-3.27435","8.20088"
"12.96000","-3.27892","8.21783"
"12.97800","-3.28351","8.23843"
"12.99600","-3.28806","8.25695"
"13.01400","-3.29264","8.27783"
"13.03200","-3.29731","8.29175"
"13.05000","-3.30198","8.31602"
"13.06800","-3.30657","8.33833"
"13.08600","-3.31111","8.35673"
"13.10400","-3.31566","8.37985"
"13.12200","-3.32022","8.40028"
"13.14000","-3.32475","8.42835"
"13.15800","-3.32925","8.44833"
"13.17600","-3.33381","8.46351"
"13.19400","-3.33845","8.48901"
"13.21200","-3.34309","8.50646"
"13.23000","-3.34764","8.52823"
"13.24800","-3.35220","8.55265"
"13.26600","-3.35679","8.57091"
"13.28400","-3.36134","8.59004"
"13.30200","-3.36581","8.61359"
"13.32000","-3.37032","8.63891"
"13.33800","-3.37491","8.65923"
"13.35600","-3.37955","8.68038"
"13.37400","-3.38415","8.69790"
"13.39200","-3.38874","8.71580"
"13.41000","-3.39338","8.73961"
"13.42800","-3.39804","8.75941"
"13.44600","-3.40261","8.78284"
"13.46400","-3.40711","8.80357"
"13.48200","-3.41164","8.82984"
"13.50000","-3.41621","8.85757"
"13.51800","-3.42076","8.88644"
"13.53600","-3.42531","8.91077"
"13.55400","-3.42993","8.92435"
"13.57200","-3.43458","8.94569"
"13.59000","-3.43918","8.96888"
"13.60800","-3.44369","8.98426"
"13.62600","-3.44821","9.00267"
"13.64400","-3.45275","9.02746"
"13.66200","-3.45727","9.05478"
"13.68000","-3.46177","9.07141"
"13.69800","-3.46630","9.08737"
"13.71600","-3.47091","9.10978"
"13.73400","-3.47558","9.13465"
"13.75200","-3.48021","9.16895"
"13.77000","-3.48480","9.19893"
"13.78800","-3.48939","9.22761"
"13.80600","-3.49398","9.24550"
"13.82400","-3.49851","9.26304"
"13.84200","-3.50303","9.28748"
"13.86000","-3.50759","9.31026"
"13.87800","-3.51217","9.33601"
"13.89600","-3.51677","9.35704"
"13.91400","-3.52135","9.38823"
"13.93200","-3.52596","9.41703"
"13.95000","-3.53058","9.43425"
"13.96800","-3.53515","9.45731"
"13.98600","-3.53967","9.48003"
"14.00400","-3.54418","9.50856"
"14.02200","-3.54872","9.53378"
"14.04000","-3.55324","9.56206"
"14.05800","-3.55775","9.59046"
"14.07600","-3.56230","9.61465"
"14.09400","-3.56692","9.64360"
"14.11200","-3.57153","9.66892"
"14.13000","-3.57611","9.69737"
"14.14800","-3.58070","9.72976"
"14.16600","-3.58529","9.75655"
"14.18400","-3.58985","9.79465"
"14.20200","-3.59437","9.81809"
"14.22000","-3.59891","9.84193"
"14.23800","-3.60352","9.86853"
"14.25600","-3.60819","9.89188"
"14.27400","-3.61283","9.92212"
"14.29200","-3.61742","9.94813"
"14.31000","-3.62202","9.97646"
"14.32800","-3.62662","10.00192"
"14.34600","-3.63113","10.02984"
"14.36400","-3.63561","10.05218"
"14.38200","-3.64014","10.07855"
"14.40000","-3.64472","10.10946"
"14.41800","-3.64929","10.12875"
"14.43600","-3.65386","10.15728"
"14.45400","-3.65845","10.19275"
"14.47200","-3.66306","10.21976"
"14.49000","-3.66764","10.24859"
"14.50800","-3.67215","10.27458"
"14.52600","-3.67669","10.30227"
"14.54400","-3.68127","10.32484"
"14.56200","-3.68586","10.35589"
"14.58000","-3.69041","10.38880"
"14.59800","-3.69499","10.41476"
"14.61600","-3.69965","10.44441"
"14.63400","-3.70431","10.47342"
"14.65200","-3.70891","10.51025"
"14.67000","-3.71347","10.54679"
"14.68800","-3.71803","10.56989"
"14.70600","-3.72257","10.59043"
"14.72400","-3.72708","10.60845"
"14.74200","-3.73157","10.64224"
"14.76000","-3.73613","10.67162"
"14.77800","-3.74078","10.70462"
"14.79600","-3.74541","10.73953"
"14.81400","-3.74998","10.77002"
"14.83200","-3.75456","10.80653"
"14.85000","-3.75915","10.82762"
"14.86800","-3.76368","10.85253"
"14.88600","-3.76815","10.87452"
"14.90400","-3.77267","10.90322"
"14.92200","-3.77727","10.94627"
"14.94000","-3.78189","10.97855"
"14.95800","-3.78647","11.01147"
"14.97600","-3.79107","11.04157"
"14.99400","-3.79570","11.07052"
"15.01200","-3.80035","11.09883"
"15.03000","-3.80491","11.12521"
"15.04800","-3.80942","11.15920"
"15.06600","-3.81396","11.18537"
"15.08400","-3.81854","11.21590"
"15.10200","-3.82308","11.25155"
"15.12000","-3.82762","11.29013"
"15.13800","-3.83225","11.33226"
"15.15600","-3.83691","11.36542"
"15.17400","-3.84152","11.39952"
"15.19200","-3.84603","11.42671"
"15.21000","-3.85057","11.45071"
"15.22800","-3.85510","11.48066"
"15.24600","-3.85961","11.50884"
"15.26400","-3.86410","11.54743"
"15.28200","-3.86863","11.58154"
"15.30000","-3.87325","11.61847"
"15.31800","-3.87792","11.65422"
"15.33600","-3.88255","11.68498"
"15.35400","-3.88715","11.71773"
"15.37200","-3.89176","11.74327"
"15.39000","-3.89633","11.77701"
"15.40800","-3.90084","11.80897"
"15.42600","-3.90536","11.83890"
"15.44400","-3.90990","11.87330"
"15.46200","-3.91449","11.90670"
"15.48000","-3.91909","11.94736"
"15.49800","-3.92368","11.98386"
"15.51600","-3.92829","12.02200"
"15.53400","-3.93292","12.05192"
"15.55200","-3.93749","12.07570"
"15.57000","-3.94201","12.10984"
"15.58800","-3.94653","12.14230"
"15.60600","-3.95107","12.18661"
"15.62400","-3.95560","12.22243"
"15.64200","-3.96012","12.25042"
"15.66000","-3.96470","12.28794"
"15.67800","-3.96932","12.32674"
"15.69600","-3.97394","12.37729"
"15.71400","-3.97852","12.41154"
"15.73200","-3.98312","12.44287"
"15.75000","-3.98770","12.47558"
"15.76800","-3.99225","12.51007"
"15.78600","-3.99676","12.55228"
"15.80400","-4.00130","12.58494"
"15.82200","-4.00590","12.62717"
"15.84000","-4.01056","12.65896"
"15.85800","-4.01518","12.68895"
"15.87600","-4.01977","12.72363"
"15.89400","-4.02436","12.76855"
"15.91200","-4.02895","12.81723"
"15.93000","-4.03346","12.85491"
"15.94800","-4.03795","12.89447"
"15.96600","-4.04249","12.93478"
"15.98400","-4.04707","12.96541"
"16.00200","-4.05164","13.00153"
"16.02000","-4.05620","13.02921"
"16.03800","-4.06081","13.06849"
"16.05600","-4.06543","13.11102"
"16.07400","-4.07001","13.15170"
"16.09200","-4.07453","13.19626"
"16.11000","-4.07907","13.23795"
"16.12800","-4.08365","13.28815"
"16.14600","-4.08822","13.33005"
"16.16400","-4.09273","13.37486"
"16.18200","-4.09731","13.41516"
"16.20000","-4.10198","13.44041"
"16.21800","-4.10665","13.47620"
"16.23600","-4.11123","13.50990"
"16.25400","-4.11578","13.55522"
"16.27200","-4.12034","13.59580"
"16.29000","-4.12491","13.63899"
"16.30800","-4.12941","13.68000"
"16.32600","-4.13390","13.71035"
"16.34400","-4.13848","13.74428"
"16.36200","-4.14312","13.78292"
"16.38000","-4.14774","13.83535"
"16.39800","-4.15229","13.88877"
"16.41600","-4.15685","13.92891"
"16.43400","-4.16143","13.97864"
"16.45200","-4.16596","14.01751"
"16.47000","-4.17043","14.05399"
"16.48800","-4.17498","14.09257"
"16.50600","-4.17960","14.13107"
"16.52400","-4.18423","14.18698"
"16.54200","-4.18882","14.23204"
"16.56000","-4.19342","14.27793"
"16.57800","-4.19807","14.32129"
"16.59600","-4.20271","14.36875"
"16.61400","-4.20725","14.41343"
"16.63200","-4.21175","14.44939"
"16.65000","-4.21629","14.49474"
"16.66800","-4.22085","14.53613"
"16.68600","-4.22537","14.57718"
"16.70400","-4.22993","14.61656"
"16.72200","-4.23457","14.66362"
"16.74000","-4.23923","14.71751"
"16.75800","-4.24382","14.76396"
"16.77600","-4.24835","14.81885"
"16.79400","-4.25288","14.86419"
"16.81200","-4.25741","14.91091"
"16.83000","-4.26193","14.96244"
"16.84800","-4.26643","15.00850"
"16.86600","-4.27098","15.06076"
"16.88400","-4.27562","15.10656"
"16.90200","-4.28029","15.15268"
"16.92000","-4.28490","15.19704"
"16.93800","-4.28949","15.24499"
"16.95600","-4.29408","15.29565"
"16.97400","-4.29865","15.33838"
"16.99200","-4.30317","15.39862"
"17.01000","-4.30770","15.44498"
"17.02800","-4.31224","15.48777"
"17.04600","-4.31683","15.54706"
"17.06400","-4.32144","15.59337"
"17.08200","-4.32605","15.65391"
"17.10000","-4.33067","15.70041"
"17.11800","-4.33527","15.74173"
"17.13600","-4.33983","15.79469"
"17.15400","-4.34434","15.84407"
"17.17200","-4.34884","15.89625"
"17.19000","-4.35337","15.94468"
"17.20800","-4.35790","16.00369"
"17.22600","-4.36243","16.04912"
"17.24400","-4.36703","16.09759"
"17.26200","-4.37167","16.15876"
"17.28000","-4.37629","16.20746"
"17.29800","-4.38088","16.25559"
"17.31600","-4.38547","16.30112"
"17.33400","-4.39005","16.35338"
"17.35200","-4.39460","16.41171"
"17.37000","-4.39909","16.46932"
"17.38800","-4.40363","16.53302"
"17.40600","-4.40825","16.58560"
"17.42400","-4.41291","16.64509"
"17.44200","-4.41753","16.70427"
"17.46000","-4.42213","16.75683"
"17.47800","-4.42673","16.81157"
"17.49600","-4.43131","16.85415"
"17.51400","-4.43582","16.90031"
"17.53200","-4.44030","16.94839"
"17.55000","-4.44484","17.01137"
"17.56800","-4.44941","17.07301"
"17.58600","-4.45396","17.12914"
"17.60400","-4.45852","17.18853"
"17.62200","-4.46313","17.24128"
"17.64000","-4.46776","17.30280"
"17.65800","-4.47233","17.37076"
"17.67600","-4.47684","17.43417"
"17.69400","-4.48137","17.49775"
"17.71200","-4.48595","17.54630"
"17.73000","-4.49054","17.60487"
"17.74800","-4.49508","17.66285"
"17.76600","-4.49968","17.71448"
"17.78400","-4.50435","17.77309"
"17.80200","-4.50900","17.82371"
"17.82000","-4.51357","17.88166"
"17.83800","-4.51813","17.93735"
"17.85600","-4.52269","17.99649"
"17.87400","-4.52724","18.05589"
"17.89200","-4.53173","18.11470"
"17.91000","-4.53623","18.17892"
"17.92800","-4.54081","18.21768"
"17.94600","-4.54546","18.28842"
"17.96400","-4.55008","18.37135"
"17.98200","-4.55467","18.44353"
"18.00000","-4.55926","18.50348"
"18.01800","-4.56384","18.54958"
"18.03600","-4.56835","18.61296"
"18.05400","-4.57279","18.67059"
"18.07200","-4.57731","18.73678"
"18.09000","-4.58192","18.80211"
"18.10800","-4.58655","18.85074"
"18.12600","-4.59115","18.91044"
"18.14400","-4.59578","18.97070"
"18.16200","-4.60044","19.04064"
"18.18000","-4.60506","19.11778"
"18.19800","-4.60958","19.20234"
"18.21600","-4.61408","19.28364"
"18.23400","-4.61861","19.35476"
"18.25200","-4.62316","19.43529"
"18.27000","-4.62769","19.49574"
"18.28800","-4.63225","19.55106"
"18.30600","-4.63689","19.60121"
"18.32400","-4.64156","19.65696"
"18.34200","-4.64614","19.74209"
"18.36000","-4.65069","19.81305"
"18.37800","-4.65524","19.87718"
"18.39600","-4.65976","19.94802"
"18.41400","-4.66426","20.02047"
"18.43200","-4.66873","20.09242"
"18.45000","-4.67327","20.16068"
"18.46800","-4.67790","20.24991"
"18.48600","-4.68258","20.32740"
"18.50400","-4.68719","20.41857"
"18.52200","-4.69179","20.49506"
"18.54000","-4.69641","20.57467"
"18.55800","-4.70099","20.66374"
"18.57600","-4.70551","20.73672"
"18.59400","-4.71003","20.80777"
"18.61200","-4.71458","20.86498"
"18.63000","-4.71916","20.93779"
"18.64800","-4.72373","21.01448"
"18.66600","-4.72833","21.07121"
"18.68400","-4.73295","21.15019"
"18.70200","-4.73757","21.22058"
"18.72000","-4.74212","21.28937"
"18.73800","-4.74665","21.35993"
"18.75600","-4.75117","21.44130"
"18.77400","-4.75572","21.53799"
"18.79200","-4.76023","21.62187"
"18.81000","-4.76476","21.70485"
"18.82800","-4.76935","21.77680"
"18.84600","-4.77398","21.84554"
"18.86400","-4.77860","21.94101"
"18.88200","-4.78319","22.02485"
"18.90000","-4.78779","22.12010"
"18.91800","-4.79236","22.19991"
"18.93600","-4.79690","22.28210"
"18.95400","-4.80140","22.35323"
"18.97200","-4.80596","22.41524"
"18.99000","-4.81059","22.50450"
"19.00800","-4.81525","22.58875"
"19.02600","-4.81986","22.67739"
"19.04400","-4.82445","22.75829"
"19.06200","-4.82906","22.83231"
"19.08000","-4.83363","22.92625"
"19.09800","-4.83812","23.00651"
"19.11600","-4.84262","23.09091"
"19.13400","-4.84716","23.18007"
"19.15200","-4.85174","23.26840"
"19.17000","-4.85629","23.36650"
"19.18800","-4.86084","23.45780"
"19.20600","-4.86546","23.54815"
"19.22400","-4.87009","23.62182"
"19.24200","-4.87466","23.70044"
"19.26000","-4.87918","23.78198"
"19.27800","-4.88372","23.85507"
"19.29600","-4.88829","23.94042"
"19.31400","-4.89285","24.02299"
"19.33200","-4.89737","24.12112"
"19.35000","-4.90197","24.19393"
"19.36800","-4.90665","24.30428"
"19.38600","-4.91130","24.41982"
"19.40400","-4.91589","24.49282"
"19.42200","-4.92047","24.57500"
"19.44000","-4.92505","24.66868"
"19.45800","-4.92959","24.78674"
"19.47600","-4.93408","24.88501"
"19.49400","-4.93858","24.96502"
"19.51200","-4.94316","25.05712"
"19.53000","-4.94780","25.14350"
"19.54800","-4.95239","25.24622"
"19.56600","-4.95696","25.34211"
"19.58400","-4.96156","25.43494"
"19.60200","-4.96615","25.53142"
"19.62000","-4.97066","25.61922"
"19.63800","-4.97514","25.71592"
"19.65600","-4.97968","25.80499"
"19.67400","-4.98429","25.90709"
"19.69200","-4.98889","26.01770"
"19.71000","-4.99346","26.10532"
"19.72800","-4.99807","26.20554"
"19.74600","-5.00273","26.30900"
"19.76400","-5.00736","26.41527"
"19.78200","-5.01189","26.52132"
"19.80000","-5.01642","26.63504"
"19.81800","-5.02099","26.75288"
"19.83600","-5.02554","26.84254"
"19.85400","-5.03006","26.95173"
"19.87200","-5.03463","27.04110"
"19.89000","-5.03927","27.12967"
"19.90800","-5.04392","27.21945"
"19.92600","-5.04849","27.30108"
"19.94400","-5.05302","27.44983"
"19.96200","-5.05757","27.56963"
"19.98000","-5.06210","27.67514"
"19.99800","-5.06661","27.75685"
"20.01600","-5.07110","27.83989"
"20.03400","-5.07567","27.95142"
"20.05200","-5.08032","28.05128"
"20.07000","-5.08497","28.16765"
"20.08800","-5.08958","28.27253"
"20.10600","-5.09417","28.38073"
"20.12400","-5.09877","28.49961"
"20.14200","-5.10333","28.60952"
"20.16000","-5.10784","28.73162"
"20.17800","-5.11236","28.84099"
"20.19600","-5.11691","28.95465"
"20.21400","-5.12150","29.06042"
"20.23200","-5.12608","29.15882"
"20.25000","-5.13068","29.27466"
"20.26800","-5.13530","29.38442"
"20.28600","-5.13992","29.50690"
"20.30400","-5.14447","29.61473"
"20.32200","-5.14899","29.72205"
"20.34000","-5.15351","29.83260"
"20.35800","-5.15806","29.94430"
"20.37600","-5.16258","30.05913"
"20.39400","-5.16712","30.16378"
"20.41200","-5.17172","30.27232"
"20.43000","-5.17633","30.37071"
"20.44800","-5.18093","30.48306"
"20.46600","-5.18551","30.57757"
"20.48400","-5.19011","30.70372"
"20.50200","-5.19470","30.86929"
"20.52000","-5.19924","30.97737"
"20.53800","-5.20375","31.05702"
"20.55600","-5.20833","31.14615"
"20.57400","-5.21297","31.24614"
"20.59200","-5.21761","31.37008"
"20.61000","-5.22220","31.49427"
"20.62800","-5.22678","31.62164"
"20.64600","-5.23138","31.73625"
"20.66400","-5.23595","31.84570"
"20.68200","-5.24045","31.96484"
"20.70000","-5.24497","32.07366"
"20.71800","-5.24952","32.19905"
"20.73600","-5.25409","32.32072"
"20.75400","-5.25863","32.42944"
"20.77200","-5.26318","32.55276"
"20.79000","-5.26780","32.66817"
"20.80800","-5.27242","32.77963"
"20.82600","-5.27697","32.88113"
"20.84400","-5.28150","32.99469"
"20.86200","-5.28606","33.11659"
"20.88000","-5.29066","33.23355"
"20.89800","-5.29522","33.35666"
"20.91600","-5.29976","33.46384"
"20.93400","-5.30437","33.58862"
"20.95200","-5.30903","33.71067"
"20.97000","-5.31365","33.83509"
"20.98800","-5.31821","33.96025"
"21.00600","-5.32276","34.07787"
"21.02400","-5.32734","34.20752"
"21.04200","-5.33191","34.32390"
"21.06000","-5.33642","34.43713"
"21.07800","-5.34095","34.55478"
"21.09600","-5.34554","34.68534"
"21.11400","-5.35017","34.81957"
"21.13200","-5.35474","34.93151"
"21.15000","-5.35929","35.03887"
"21.16800","-5.36387","35.14455"
"21.18600","-5.36845","35.25739"
"21.20400","-5.37295","35.39192"
"21.22200","-5.37744","35.50142"
"21.24000","-5.38201","35.63596"
"21.25800","-5.38665","35.75475"
"21.27600","-5.39126","35.88792"
"21.29400","-5.39582","36.01305"
"21.31200","-5.40042","36.12803"
"21.33000","-5.40508","36.26124"
"21.34800","-5.40970","36.39030"
"21.36600","-5.41423","36.51219"
"21.38400","-5.41877","36.62495"
"21.40200","-5.42334","36.74907"
"21.42000","-5.42789","36.86155"
"21.43800","-5.43240","36.97794"
"21.45600","-5.43697","37.09933"
"21.47400","-5.44160","37.19542"
"21.49200","-5.44623","37.32244"
"21.51000","-5.45078","37.44977"
"21.52800","-5.45532","37.56449"
"21.54600","-5.45987","37.69698"
"21.56400","-5.46442","37.82482"
"21.58200","-5.46893","37.94968"
"21.60000","-5.47344","38.07551"
"21.61800","-5.47801","38.20868"
"21.63600","-5.48266","38.34943"
"21.65400","-5.48730","38.49776"
"21.67200","-5.49189","38.65383"
"21.69000","-5.49649","38.76975"
"21.70800","-5.50109","38.88181"
"21.72600","-5.50564","38.99677"
"21.74400","-5.51016","39.10643"
"21.76200","-5.51471","39.22833"
"21.78000","-5.51928","39.32721"
"21.79800","-5.52389","39.45752"
"21.81600","-5.52848","39.58832"
"21.83400","-5.53306","39.71993"
"21.85200","-5.53765","39.84006"
"21.87000","-5.54224","39.95536"
"21.88800","-5.54677","40.08675"
"21.90600","-5.55129","40.21708"
"21.92400","-5.55582","40.35784"
"21.94200","-5.56037","40.49707"
"21.96000","-5.56491","40.62078"
"21.97800","-5.56946","40.75801"
"21.99600","-5.57406","40.88798"
"22.01400","-5.57868","41.02074"
"22.03200","-5.58326","41.13499"
"22.05000","-5.58784","41.24623"
"22.06800","-5.59244","41.37506"
"22.08600","-5.59702","41.48895"
"22.10400","-5.60156","41.60837"
"22.12200","-5.60608","41.72673"
"22.14000","-5.61066","41.84837"
"22.15800","-5.61530","41.97304"
"22.17600","-5.61993","42.09149"
"22.19400","-5.62452","42.21914"
"22.21200","-5.62912","42.33647"
"22.23000","-5.63373","42.46736"
"22.24800","-5.63829","42.59903"
"22.26600","-5.64277","42.73817"
"22.28400","-5.64728","42.89026"
"22.30200","-5.65184","43.02965"
"22.32000","-5.65642","43.18278"
"22.33800","-5.66096","43.31047"
"22.35600","-5.66552","43.43283"
"22.37400","-5.67013","43.54700"
"22.39200","-5.67475","43.65477"
"22.41000","-5.67928","43.78065"
"22.42800","-5.68380","43.89654"
"22.44600","-5.68836","44.01582"
"22.46400","-5.69296","44.12171"
"22.48200","-5.69754","44.24237"
"22.50000","-5.70209","44.37518"
"22.51800","-5.70672","44.48240"
"22.53600","-5.71140","44.59223"
"22.55400","-5.71602","44.72564"
"22.57200","-5.72058","44.87170"
"22.59000","-5.72514","45.03440"
"22.60800","-5.72970","45.17696"
"22.62600","-5.73424","45.33247"
"22.64400","-5.73873","45.46456"
"22.66200","-5.74326","45.57647"
"22.68000","-5.74787","45.68731"
"22.69800","-5.75251","45.80533"
"22.71600","-5.75709","45.92496"
"22.73400","-5.76166","46.03936"
"22.75200","-5.76625","46.17530"
"22.77000","-5.77081","46.30745"
"22.78800","-5.77530","46.45898"
"22.80600","-5.77978","46.59962"
"22.82400","-5.78434","46.71077"
"22.84200","-5.78896","46.82205"
"22.86000","-5.79357","46.93630"
"22.87800","-5.79816","47.07061"
"22.89600","-5.80278","47.21857"
"22.91400","-5.80744","47.34478"
"22.93200","-5.81204","47.46867"
"22.95000","-5.81655","47.59142"
"22.96800","-5.82108","47.72818"
"22.98600","-5.82565","47.85146"
"23.00400","-5.83022","47.96387"
"23.02200","-5.83474","48.09805"
"23.04000","-5.83932","48.21900"
"23.05800","-5.84396","48.35181"
"23.07600","-5.84859","48.45086"
"23.09400","-5.85314","48.57122"
"23.11200","-5.85768","48.72642"
"23.13000","-5.86223","48.86357"
"23.14800","-5.86676","48.99995"
"23.16600","-5.87125","49.10520"
"23.18400","-5.87575","49.20312"
"23.20200","-5.88032","49.31409"
"23.22000","-5.88497","49.45235"
"23.23800","-5.88962","49.59488"
"23.25600","-5.89423","49.72781"
"23.27400","-5.89885","49.85446"
"23.29200","-5.90344","49.96626"
"23.31000","-5.90798","50.10034"
"23.32800","-5.91249","50.21422"
"23.34600","-5.91702","50.32562"
"23.36400","-5.92161","50.45025"
"23.38200","-5.92622","50.56958"
"23.40000","-5.93080","50.69491"
"23.41800","-5.93538","50.81395"
"23.43600","-5.93997","50.93049"
"23.45400","-5.94454","51.06661"
"23.47200","-5.94905","51.18402"
"23.49000","-5.95356","51.31353"
"23.50800","-5.95810","51.43047"
"23.52600","-5.96265","51.55493"
"23.54400","-5.96721","51.68287"
"23.56200","-5.97178","51.80159"
"23.58000","-5.97639","51.92794"
"23.59800","-5.98100","52.04411"
"23.61600","-5.98558","52.17978"
"23.63400","-5.99016","52.31505"
"23.65200","-5.99475","52.44113"
"23.67000","-5.99933","52.55529"
"23.68800","-6.00386","52.66583"
"23.70600","-6.00838","52.78362"
"23.72400","-6.01297","52.89552"
"23.74200","-6.01763","53.02330"
"23.76000","-6.02228","53.15401"
"23.77800","-6.02686","53.26962"
"23.79600","-6.03145","53.40018"
"23.81400","-6.03605","53.52176"
"23.83200","-6.04060","53.64330"
"23.85000","-6.04509","53.76008"
"23.86800","-6.04961","53.88190"
"23.88600","-6.05418","54.02150"
"23.90400","-6.05876","54.14172"
"23.92200","-6.06331","54.25702"
"23.94000","-6.06788","54.37339"
"23.95800","-6.07249","54.49485"
"23.97600","-6.07709","54.61430"
"23.99400","-6.08161","54.72100"
"24.01200","-6.08614","54.83069"
"24.03000","-6.09073","54.92009"
"24.04800","-6.09533","55.02947"
"24.06600","-6.09989","55.15194"
"24.08400","-6.10445","55.28318"
"24.10200","-6.10907","55.43072"
"24.12000","-6.11372","55.57446"
"24.13800","-6.11832","55.72097"
"24.15600","-6.12289","55.84093"
"24.17400","-6.12746","55.95437"
"24.19200","-6.13203","56.06411"
"24.21000","-6.13657","56.17217"
"24.22800","-6.14106","56.29413"
"24.24600","-6.14562","56.41683"
"24.26400","-6.15025","56.54427"
"24.28200","-6.15488","56.63839"
"24.30000","-6.15943","56.72887"
"24.31800","-6.16399","56.84450"
"24.33600","-6.16857","56.97598"
"24.35400","-6.17312","57.10720"
"24.37200","-6.17760","57.20447"
"24.39000","-6.18211","57.29950"
"24.40800","-6.18671","57.40980"
"24.42600","-6.19135","57.53900"
"24.44400","-6.19594","57.69954"
"24.46200","-6.20051","57.84404"
"24.48000","-6.20514","57.97805"
"24.49800","-6.20979","58.08433"
"24.51600","-6.21437","58.19511"
"24.53400","-6.21887","58.32555"
"24.55200","-6.22340","58.43266"
"24.57000","-6.22798","58.55141"
"24.58800","-6.23253","58.67057"
"24.60600","-6.23707","58.78900"
"24.62400","-6.24167","58.89871"
"24.64200","-6.24632","58.99960"
"24.66000","-6.25095","59.12947"
"24.67800","-6.25548","59.24828"
"24.69600","-6.26001","59.36879"
"24.71400","-6.26454","59.48197"
"24.73200","-6.26906","59.59314"
"24.75000","-6.27355","59.70625"
"24.76800","-6.27809","59.82817"
"24.78600","-6.28271","59.97895"
"24.80400","-6.28739","60.11152"
"24.82200","-6.29201","60.22190"
"24.84000","-6.29659","60.32985"
"24.85800","-6.30117","60.43201"
"24.87600","-6.30573","60.54954"
"24.89400","-6.31026","60.66265"
"24.91200","-6.31478","60.79217"
"24.93000","-6.31934","60.93364"
"24.94800","-6.32394","61.07194"
"24.96600","-6.32856","61.20642"
"24.98400","-6.33316","61.33232"
"25.00200","-6.33777","61.47116"
"25.02000","-6.34237","61.57209"
"25.03800","-6.34694","61.64635"
"25.05600","-6.35145","61.73456"
"25.07400","-6.35596","61.86045"
"25.09200","-6.36050","62.02765"
"25.11000","-6.36505","62.18682"
"25.12800","-6.36958","62.32183"
"25.14600","-6.37415","62.42892"
"25.16400","-6.37874","62.53414"
"25.18200","-6.38336","62.63881"
"25.20000","-6.38794","62.72137"
"25.21800","-6.39252","62.78382"
"25.23600","-6.39710","62.83530"
"25.25400","-6.40168","62.88427"
"25.27200","-6.40620","62.94780"
"25.29000","-6.41073","63.04560"
"25.30800","-6.41533","63.13754"
"25.32600","-6.41999","63.15759"
"25.34400","-6.42463","63.15630"
"25.36200","-6.42922","63.23375"
"25.38000","-6.43381","63.30431"
"25.39800","-6.43840","63.30496"
"25.41600","-6.44292","63.13816"
"25.43400","-6.44740","62.72826"
"25.45200","-6.45192","62.03380"
"25.47000","-6.45650","61.04575"
"25.48800","-6.46107","59.81744"
"25.50600","-6.46563","58.44359"
"25.52400","-6.47022","57.04870"
"25.54200","-6.47485","55.73894"
"25.56000","-6.47945","54.51995"
"25.57800","-6.48397","53.30257"
"25.59600","-6.48848","52.05374"
"25.61400","-6.49305","50.76964"
"25.63200","-6.49764","49.51971"
"25.65000","-6.50218","48.47543"
"25.66800","-6.50674","47.51506"
"25.68600","-6.51139","46.45589"
"25.70400","-6.51607","45.27753"
"25.72200","-6.52067","44.10104"
"25.74000","-6.52524","42.96668"
"25.75800","-6.52979","41.35573"
"25.77600","-6.53435","38.76648"
"25.79400","-6.53886","35.48273"
"25.81200","-6.54336","31.92357"
"25.83000","-6.54792","28.28150"
"25.84800","-6.55255","24.65683"
"25.86600","-6.55718","20.93367"
"25.88400","-6.56175","17.21249"
"25.90200","-6.56632","13.52836"
"25.92000","-6.57089","10.02274"
"25.93800","-6.57543","7.08057"
"25.95600","-6.57990","4.69595"
"25.97400","-6.58442","2.59693"
"25.99200","-6.58903","0.87585"
"26.01000","-6.59367","0.02181"
"26.52300","-6.60214","-0.00712"
"28.32300","-6.60219","-0.00585"
"30.12300","-6.60219","-0.00458"
"31.92300","-6.60219","-0.00459"
"33.72300","-6.60219","-0.00397"
"35.52300","-6.60219","-0.00353"
"36.15100","-6.58503","3.29387"
"36.18700","-6.57447","9.52832"
"36.22300","-6.56470","17.99406"
"36.24100","-6.56003","22.51872"
"36.26200","-6.55462","27.78084"
"36.29800","-6.54538","36.75168"
"36.33400","-6.53612","45.65753"
"36.37000","-6.52704","54.16021"
"36.40600","-6.51781","62.00621"
"36.44600","-6.50762","67.86010"
"36.91600","-6.38834","68.06394"
"37.74500","-6.17772","63.58138"
"38.35700","-6.02226","59.00257"
"38.93100","-5.87646","54.42418"
"39.53300","-5.72363","49.84390"
"40.12700","-5.57268","45.27816"
"40.75600","-5.41295","40.70665"
"41.40100","-5.24912","36.14130"
"42.09100","-5.07381","31.57259"
"42.84600","-4.88209","27.02456"
"43.76700","-4.64831","22.48440"
"44.96100","-4.34493","17.94920"
"46.61600","-3.92452","13.62178"
"48.41600","-3.46728","10.55222"
"50.21600","-3.01003","8.47871"
"52.01600","-2.55296","6.93225"
"53.81600","-2.09569","5.63955"
"55.61600","-1.63847","4.74352"
"57.41600","-1.18118","4.22042"
"59.21600","-0.72420","3.83079"
"61.01600","-0.26691","3.87714"
"62.02000","-0.01194","6.16734"
"62.06700","0.00002","8.55482"